https://github.com/canonical/cloud-init/commit/36ddf1ebed3f264fa86ef4f657dce29244c2e068

=== Begin SRU Template ===
[Impact]
sudoers file now prefers '@' instead of '#' for includedir. Ensure we don't
break the sudoers file by adding an additional #includedir when
@includedir already exists.

[Test Case]
There is an upstream test for this bug:
https://github.com/canonical/cloud-init/blob/master/tests/integration_tests/modules/test_users_groups.py::test_sudoers_includedir

=== Xenial ===
n/a

=== Bionic ===
n/a

=== Focal ===
n/a

=== Groovy ===
============================= test session starts ==============================
platform linux -- Python 3.5.9, pytest-5.4.2, py-1.8.1, pluggy-0.13.1
rootdir: /home/james/cloud-init-tests, inifile: tox.ini
plugins: cov-2.9.0
collected 1 item

tests/integration_tests/modules/test_users_groups.py::test_sudoers_includedir Detected image: image_id=groovy os=ubuntu release=groovy

-------------------------------- live log setup --------------------------------
2021-03-25 20:54:10 INFO      integration_testing:clouds.py:87 Detected image: image_id=groovy os=ubuntu release=groovy
Detected image: image_id=groovy os=ubuntu release=groovy
2021-03-25 20:54:10 INFO      integration_testing:clouds.py:87 Detected image: image_id=groovy os=ubuntu release=groovy
Settings:
CLOUD_INIT_SOURCE=PROPOSED
COLLECT_LOGS=NEVER
EXISTING_INSTANCE_ID=None
INSTANCE_TYPE=None
KEEP_IMAGE=False
KEEP_INSTANCE=False
KEYPAIR_NAME=None
LOCAL_LOG_PATH=/tmp/cloud_init_test_logs
OPENSTACK_NETWORK=falcojr_admin_net
OS_IMAGE=groovy
PLATFORM=lxd_vm
PUBLIC_SSH_KEY=None
RUN_UNSTABLE=False
2021-03-25 20:54:27 INFO      integration_testing:clouds.py:128 Settings:
CLOUD_INIT_SOURCE=PROPOSED
COLLECT_LOGS=NEVER
EXISTING_INSTANCE_ID=None
INSTANCE_TYPE=None
KEEP_IMAGE=False
KEEP_INSTANCE=False
KEYPAIR_NAME=None
LOCAL_LOG_PATH=/tmp/cloud_init_test_logs
OPENSTACK_NETWORK=falcojr_admin_net
OS_IMAGE=groovy
PLATFORM=lxd_vm
PUBLIC_SSH_KEY=None
RUN_UNSTABLE=False
Setting up environment for lxd_vm
2021-03-25 20:54:27 INFO      integration_testing:conftest.py:156 Setting up environment for lxd_vm
Launching instance with launch_kwargs:
user_data=None
image_id=ubuntu:08c31b98a026f237c3d991c70acf7fc64bbc9b4e4ecaca2b8083f11eddef48ec
2021-03-25 20:54:27 INFO      integration_testing:clouds.py:167 Launching instance with launch_kwargs:
user_data=None
image_id=ubuntu:08c31b98a026f237c3d991c70acf7fc64bbc9b4e4ecaca2b8083f11eddef48ec
The profile named pycloudlib-vm-groovy-v2 already exists
['lxc', 'init', 'ubuntu:08c31b98a026f237c3d991c70acf7fc64bbc9b4e4ecaca2b8083f11eddef48ec', '--profile', 'pycloudlib-vm-groovy-v2', '--config', 'user.meta-data=public-keys: ssh-rsa AAAAB3NzaC1yc2EAAAADAQABAAABgQDJMS8gdKw0kA1PDwAVkURrxgjbAgWVeiBq+VSOI1jFLafONDwkc0ZVriZofmCZ1BVjixCA6kqVQsmA88Av7eeI3jGvy4fwX+TKhDQk28rRC9mNz8nBLfB+gp3wfcgFJrVeekhjV+fgxiyq1wJC4WcJZfXKdXvsNTBzhd2RNZAsyKyRKBRahv57/KJjXozS94p83l0qq/gi6pYYBTTkLz65SiyVCUpkddgXDPfxEXqjsx6ha3VCdoKBdRgh3p2toADzcYafyqxDMPtfLJE+BofSA4Gi9YQAMhshdk4tzI+KYcq07cd8AtreXpVyZLC3r7cfe4m2IK7UvVSbTItYoUItN255P1M09eLQNlbbrJwnxuX3IUwxBkYZhVUIaEOQreWTnc+tg20ZK3olUzNWcJBurpeT5i6Hg/QoRrQSanVLFx8hff4l1V9Yxb23txlv9e2Pzh0i/0YVmrVlQxuen/5YyWNm553D1EfH8fEon3xVAqrbC8NS63GaP0QhGo7rlYs= james@newt\n', '--vm']
2021-03-25 20:54:58 INFO      pycloudlib.instance:instance.py:165 executing: sh -c whoami
2021-03-25 20:55:20 INFO      pycloudlib.instance:instance.py:343 [Errno None] Unable to connect to port 22 on 10.37.179.10
Retrying SSH connection to ubuntu@10.37.179.10:22 (578s left)
2021-03-25 20:55:21 INFO      pycloudlib.instance:instance.py:343 [Errno None] Unable to connect to port 22 on 10.37.179.10
Retrying SSH connection to ubuntu@10.37.179.10:22 (577s left)
2021-03-25 20:55:22 INFO      pycloudlib.instance:instance.py:343 [Errno None] Unable to connect to port 22 on 10.37.179.10
Retrying SSH connection to ubuntu@10.37.179.10:22 (575s left)
2021-03-25 20:55:24 INFO      pycloudlib.instance:instance.py:343 [Errno None] Unable to connect to port 22 on 10.37.179.10
Retrying SSH connection to ubuntu@10.37.179.10:22 (574s left)
2021-03-25 20:55:25 INFO      paramiko.transport:transport.py:1819 Connected (version 2.0, client OpenSSH_8.3p1)
2021-03-25 20:55:25 INFO      paramiko.transport:transport.py:1819 Authentication (publickey) successful!
2021-03-25 20:55:27 INFO      pycloudlib.instance:instance.py:165 executing: sh -c 'cloud-init status --help'
2021-03-25 20:55:28 INFO      pycloudlib.instance:instance.py:165 executing: cloud-init status --wait --long
Launched instance: LXDInstance(name=engaged-shad)
2021-03-25 20:55:33 INFO      integration_testing:clouds.py:171 Launched instance: LXDInstance(name=engaged-shad)
2021-03-25 20:55:33 INFO      pycloudlib.instance:instance.py:165 executing: sudo -- sh -c 'cloud-init --version'
cloud-init version: /usr/bin/cloud-init 20.4.1-0ubuntu1~20.10.1
2021-03-25 20:55:33 INFO      integration_testing:clouds.py:177 cloud-init version: /usr/bin/cloud-init 20.4.1-0ubuntu1~20.10.1
2021-03-25 20:55:33 INFO      pycloudlib.instance:instance.py:165 executing: sudo -- sh -c 'grep serial /etc/cloud/build.info'
image serial: 20210323
2021-03-25 20:55:33 INFO      integration_testing:clouds.py:181 image serial: 20210323
Installing proposed image
2021-03-25 20:55:33 INFO      integration_testing:instances.py:144 Installing proposed image
2021-03-25 20:55:33 INFO      pycloudlib.instance:instance.py:165 executing: sudo -- sh -c 'echo deb "http://archive.ubuntu.com/ubuntu $(lsb_release -sc)-proposed main" | tee /etc/apt/sources.list.d/proposed.list
apt-get update -q
apt-get install -qy cloud-init'
2021-03-25 20:56:02 INFO      pycloudlib.instance:instance.py:165 executing: sudo -- sh -c 'cloud-init -v'
Installed cloud-init version: 21.1-19-gbad84ad4-0ubuntu1~20.10.1
2021-03-25 20:56:02 INFO      integration_testing:instances.py:136 Installed cloud-init version: 21.1-19-gbad84ad4-0ubuntu1~20.10.1
2021-03-25 20:56:02 INFO      pycloudlib.instance:instance.py:165 executing: sh -c 'sudo cloud-init clean --logs'
2021-03-25 20:56:02 INFO      pycloudlib.instance:instance.py:165 executing: sh -c 'sudo rm -rf /var/log/syslog'
2021-03-25 20:56:03 INFO      pycloudlib.instance:instance.py:165 executing: sh -c 'sudo cloud-init clean --logs'
2021-03-25 20:56:03 INFO      pycloudlib.instance:instance.py:165 executing: sh -c 'sudo rm -rf /var/log/syslog'
2021-03-25 20:56:03 INFO      pycloudlib.instance:instance.py:165 executing: sh -c 'sudo cloud-init clean --logs'
2021-03-25 20:56:03 INFO      pycloudlib.instance:instance.py:165 executing: sh -c 'sudo rm -rf /var/log/syslog'
Created new image: local:engaged-shad-snapshot
2021-03-25 20:57:27 INFO      integration_testing:instances.py:113 Created new image: local:engaged-shad-snapshot
Done with environment setup
2021-03-25 20:57:27 INFO      integration_testing:conftest.py:162 Done with environment setup
Launching instance with launch_kwargs:
user_data=#cloud-config
# Add groups to the system
groups:
  - secret: [root]
  - cloud-users

# Add users to the system. Users are added after groups are added.
users:
  - default
  - name: foobar
    gecos: Foo B. Bar
    primary_group: foobar
    groups: users
    expiredate: 2038-01-19
    lock_passwd: false
    passwd: $6$j212wezy$7H/1LT4f9/N3wpgNunhsIqtMj62OKiS3nyNwuizouQc3u7MbYCarYeAHWYPYb2FT.lbioDm2RrkJPb9BZMN1O/
  - name: barfoo
    gecos: Bar B. Foo
    sudo: ALL=(ALL) NOPASSWD:ALL
    groups: [cloud-users, secret]
    lock_passwd: true
  - name: cloudy
    gecos: Magic Cloud App Daemon User
    inactive: true
    system: true

image_id=local:engaged-shad-snapshot
2021-03-25 20:57:27 INFO      integration_testing:clouds.py:167 Launching instance with launch_kwargs:
user_data=#cloud-config
# Add groups to the system
groups:
  - secret: [root]
  - cloud-users

# Add users to the system. Users are added after groups are added.
users:
  - default
  - name: foobar
    gecos: Foo B. Bar
    primary_group: foobar
    groups: users
    expiredate: 2038-01-19
    lock_passwd: false
    passwd: $6$j212wezy$7H/1LT4f9/N3wpgNunhsIqtMj62OKiS3nyNwuizouQc3u7MbYCarYeAHWYPYb2FT.lbioDm2RrkJPb9BZMN1O/
  - name: barfoo
    gecos: Bar B. Foo
    sudo: ALL=(ALL) NOPASSWD:ALL
    groups: [cloud-users, secret]
    lock_passwd: true
  - name: cloudy
    gecos: Magic Cloud App Daemon User
    inactive: true
    system: true

image_id=local:engaged-shad-snapshot
['lxc', 'init', 'local:engaged-shad-snapshot', '--profile', 'pycloudlib-vm-groovy-v2', '--config', 'user.meta-data=public-keys: ssh-rsa AAAAB3NzaC1yc2EAAAADAQABAAABgQDJMS8gdKw0kA1PDwAVkURrxgjbAgWVeiBq+VSOI1jFLafONDwkc0ZVriZofmCZ1BVjixCA6kqVQsmA88Av7eeI3jGvy4fwX+TKhDQk28rRC9mNz8nBLfB+gp3wfcgFJrVeekhjV+fgxiyq1wJC4WcJZfXKdXvsNTBzhd2RNZAsyKyRKBRahv57/KJjXozS94p83l0qq/gi6pYYBTTkLz65SiyVCUpkddgXDPfxEXqjsx6ha3VCdoKBdRgh3p2toADzcYafyqxDMPtfLJE+BofSA4Gi9YQAMhshdk4tzI+KYcq07cd8AtreXpVyZLC3r7cfe4m2IK7UvVSbTItYoUItN255P1M09eLQNlbbrJwnxuX3IUwxBkYZhVUIaEOQreWTnc+tg20ZK3olUzNWcJBurpeT5i6Hg/QoRrQSanVLFx8hff4l1V9Yxb23txlv9e2Pzh0i/0YVmrVlQxuen/5YyWNm553D1EfH8fEon3xVAqrbC8NS63GaP0QhGo7rlYs= james@newt\n', '--config', 'user.user-data=#cloud-config\n# Add groups to the system\ngroups:\n  - secret: [root]\n  - cloud-users\n\n# Add users to the system. Users are added after groups are added.\nusers:\n  - default\n  - name: foobar\n    gecos: Foo B. Bar\n    primary_group: foobar\n    groups: users\n    expiredate: 2038-01-19\n    lock_passwd: false\n    passwd: $6$j212wezy$7H/1LT4f9/N3wpgNunhsIqtMj62OKiS3nyNwuizouQc3u7MbYCarYeAHWYPYb2FT.lbioDm2RrkJPb9BZMN1O/\n  - name: barfoo\n    gecos: Bar B. Foo\n    sudo: ALL=(ALL) NOPASSWD:ALL\n    groups: [cloud-users, secret]\n    lock_passwd: true\n  - name: cloudy\n    gecos: Magic Cloud App Daemon User\n    inactive: true\n    system: true\n', '--vm']
2021-03-25 20:58:34 INFO      pycloudlib.instance:instance.py:165 executing: sh -c whoami
2021-03-25 20:58:55 INFO      pycloudlib.instance:instance.py:343 [Errno None] Unable to connect to port 22 on 10.37.179.89
Retrying SSH connection to ubuntu@10.37.179.89:22 (578s left)
2021-03-25 20:58:57 INFO      pycloudlib.instance:instance.py:343 [Errno None] Unable to connect to port 22 on 10.37.179.89
Retrying SSH connection to ubuntu@10.37.179.89:22 (576s left)
2021-03-25 20:58:58 INFO      pycloudlib.instance:instance.py:343 [Errno None] Unable to connect to port 22 on 10.37.179.89
Retrying SSH connection to ubuntu@10.37.179.89:22 (575s left)
2021-03-25 20:59:00 INFO      paramiko.transport:transport.py:1819 Connected (version 2.0, client OpenSSH_8.3p1)
2021-03-25 20:59:00 INFO      paramiko.transport:transport.py:1819 Authentication (publickey) successful!
2021-03-25 20:59:02 INFO      pycloudlib.instance:instance.py:165 executing: sh -c 'cloud-init status --help'
2021-03-25 20:59:03 INFO      pycloudlib.instance:instance.py:165 executing: cloud-init status --wait --long
Launched instance: LXDInstance(name=internal-jackal)
2021-03-25 20:59:06 INFO      integration_testing:clouds.py:171 Launched instance: LXDInstance(name=internal-jackal)
2021-03-25 20:59:06 INFO      pycloudlib.instance:instance.py:165 executing: sudo -- sh -c 'cloud-init --version'
cloud-init version: /usr/bin/cloud-init 21.1-19-gbad84ad4-0ubuntu1~20.10.1
2021-03-25 20:59:07 INFO      integration_testing:clouds.py:177 cloud-init version: /usr/bin/cloud-init 21.1-19-gbad84ad4-0ubuntu1~20.10.1
2021-03-25 20:59:07 INFO      pycloudlib.instance:instance.py:165 executing: sudo -- sh -c 'grep serial /etc/cloud/build.info'
image serial: 20210323
2021-03-25 20:59:07 INFO      integration_testing:clouds.py:181 image serial: 20210323
Detected image: image_id=groovy os=ubuntu release=groovy
-------------------------------- live log call ---------------------------------
2021-03-25 20:59:07 INFO      integration_testing:clouds.py:87 Detected image: image_id=groovy os=ubuntu release=groovy
2021-03-25 20:59:07 INFO      pycloudlib.instance:instance.py:165 executing: sudo -- sh -c 'sed -i '"'"'s/#include/@include/g'"'"' /etc/sudoers'
2021-03-25 20:59:07 INFO      pycloudlib.instance:instance.py:165 executing: sudo -- sh -c 'cat /etc/sudoers'
2021-03-25 20:59:07 INFO      pycloudlib.instance:instance.py:165 executing: sh -c 'sudo cloud-init clean --logs'
2021-03-25 20:59:07 INFO      pycloudlib.instance:instance.py:165 executing: sh -c 'sudo rm -rf /var/log/syslog'
Restarting instance and waiting for boot
2021-03-25 20:59:07 INFO      integration_testing:instances.py:65 Restarting instance and waiting for boot
2021-03-25 20:59:09 INFO      pycloudlib.instance:instance.py:165 executing: sh -c whoami
2021-03-25 20:59:25 INFO      paramiko.transport:transport.py:1819 Connected (version 2.0, client OpenSSH_8.3p1)
2021-03-25 20:59:25 INFO      paramiko.transport:transport.py:1819 Authentication (publickey) successful!
2021-03-25 20:59:26 INFO      pycloudlib.instance:instance.py:165 executing: sh -c 'cloud-init status --help'
2021-03-25 20:59:26 INFO      pycloudlib.instance:instance.py:165 executing: cloud-init status --wait --long
2021-03-25 20:59:28 INFO      pycloudlib.instance:instance.py:165 executing: sudo -- sh -c 'cat /etc/sudoers'
PASSEDDeleting snapshot image created for this testrun: local:engaged-shad-snapshot

------------------------------ live log teardown -------------------------------
2021-03-25 20:59:29 INFO      integration_testing:clouds.py:202 Deleting snapshot image created for this testrun: local:engaged-shad-snapshot


======================== 1 passed in 319.34s (0:05:19) =========================



[Regression Potential]
None
