https://bugs.launchpad.net/ubuntu/+source/cloud-init/+bug/1897099
http://pad.lv/1897099

=== Begin SRU Template ===
[Impact]

cloud-init attempts to determine the correct method of swapfile creation based
on the filesystem in use.  If fallocate could work, then we attempt it.  If
fallocate fails, we should fallback to dd (which is slower, but works in
more/all cases).

This fallback was found to be broken, so if fallocate failed then the swapfile
would not be created.  (This became particularly painful when a kernel was
released which broke the use of fallocate on ext4.)

[Test Case]

There is an upstream integration test for this bug:
https://github.com/canonical/cloud-init/blob/master/tests/integration_tests/bugs/test_lp1897099.py

xenial:

```
=========================================================== test session starts ===========================================================
platform linux -- Python 3.8.6, pytest-6.1.2, py-1.9.0, pluggy-0.13.1
rootdir: /home/powersj/Work/cloud-init, configfile: tox.ini
plugins: cov-2.10.1
collected 1 item

tests/integration_tests/bugs/test_lp1897099.py::test_fallocate_fallback
------------------------------------------------------------- live log setup --------------------------------------------------------------
2020-12-10 18:47:58 INFO      integration_testing:clouds.py:73 Detected image: image_id=xenial os=ubuntu release=xenial
2020-12-10 18:47:58 INFO      integration_testing:clouds.py:73 Detected image: image_id=xenial os=ubuntu release=xenial
2020-12-10 18:47:58 INFO      integration_testing:clouds.py:104 Settings:
CLOUD_INIT_SOURCE=PROPOSED
COLLECT_LOGS=ON_ERROR
EXISTING_INSTANCE_ID=None
GCE_PROJECT=None
GCE_REGION=us-central1
GCE_ZONE=a
INSTANCE_TYPE=None
KEEP_IMAGE=False
KEEP_INSTANCE=False
LOCAL_LOG_PATH=/tmp/cloud_init_test_logs
OCI_COMPARTMENT_ID=None
OS_IMAGE=xenial
PLATFORM=lxd_vm
RUN_UNSTABLE=False
2020-12-10 18:47:58 INFO      integration_testing:conftest.py:140 Setting up environment for lxd_vm
2020-12-10 18:47:58 INFO      integration_testing:clouds.py:150 Launching instance with launch_kwargs:
image_id=images:ubuntu/16.04/cloud
user_data=None
wait=False
2020-12-10 18:49:27 INFO      pycloudlib.instance:instance.py:166 executing: sh -c whoami
2020-12-10 18:49:37 INFO      pycloudlib.instance:instance.py:166 executing: sh -c whoami
2020-12-10 18:49:47 INFO      pycloudlib.instance:instance.py:166 executing: sh -c whoami
2020-12-10 18:49:57 INFO      pycloudlib.instance:instance.py:166 executing: sh -c whoami
2020-12-10 18:50:18 INFO      pycloudlib.instance:instance.py:166 executing: sh -c 'cloud-init status --help'
2020-12-10 18:50:29 INFO      pycloudlib.instance:instance.py:166 executing: cloud-init status --wait --long
2020-12-10 18:50:39 INFO      integration_testing:clouds.py:159 Launched instance: LXDInstance(name=delicate-hyena)
2020-12-10 18:50:39 INFO      integration_testing:instances.py:144 Installing proposed image
2020-12-10 18:50:39 INFO      pycloudlib.instance:instance.py:166 executing: sudo -- sh -c 'echo deb "http://archive.ubuntu.com/ubuntu $(lsb_release -sc)-proposed main" | tee /etc/apt/sources.list.d/proposed.list
apt-get update -q
apt-get install -qy cloud-init'
2020-12-10 18:50:54 INFO      pycloudlib.instance:instance.py:166 executing: sudo -- sh -c 'cloud-init -v'
2020-12-10 18:51:05 INFO      integration_testing:instances.py:137 Installed cloud-init version: 20.4-0ubuntu1~16.04.1
2020-12-10 18:51:05 INFO      pycloudlib.instance:instance.py:166 executing: sh -c 'sudo cloud-init clean --logs'
2020-12-10 18:51:16 INFO      pycloudlib.instance:instance.py:166 executing: sh -c 'sudo rm -rf /var/log/syslog'
2020-12-10 18:51:26 INFO      pycloudlib.instance:instance.py:166 executing: sh -c 'sudo cloud-init clean --logs'
2020-12-10 18:51:37 INFO      pycloudlib.instance:instance.py:166 executing: sh -c 'sudo rm -rf /var/log/syslog'
2020-12-10 18:51:47 INFO      pycloudlib.instance:instance.py:166 executing: sh -c 'sudo cloud-init clean --logs'
2020-12-10 18:51:58 INFO      pycloudlib.instance:instance.py:166 executing: sh -c 'sudo rm -rf /var/log/syslog'
2020-12-10 18:53:20 INFO      integration_testing:instances.py:117 Created new image: local:delicate-hyena-snapshot
2020-12-10 18:53:20 INFO      integration_testing:conftest.py:146 Done with environment setup
2020-12-10 18:53:20 INFO      integration_testing:clouds.py:150 Launching instance with launch_kwargs:
image_id=local:delicate-hyena-snapshot
user_data=#cloud-config
bootcmd:
- echo 'whoops' > /usr/bin/fallocate
swap:
filename: /swap.img
size: 10000000
maxsize: 10000000

wait=False
2020-12-10 18:54:36 INFO      pycloudlib.instance:instance.py:166 executing: sh -c whoami
2020-12-10 18:54:46 INFO      pycloudlib.instance:instance.py:166 executing: sh -c whoami
2020-12-10 18:54:56 INFO      pycloudlib.instance:instance.py:166 executing: sh -c whoami
2020-12-10 18:55:06 INFO      pycloudlib.instance:instance.py:166 executing: sh -c whoami
2020-12-10 18:55:26 INFO      pycloudlib.instance:instance.py:166 executing: sh -c 'cloud-init status --help'
2020-12-10 18:55:37 INFO      pycloudlib.instance:instance.py:166 executing: cloud-init status --wait --long
2020-12-10 18:55:48 INFO      integration_testing:clouds.py:159 Launched instance: LXDInstance(name=able-badger)
-------------------------------------------------------------- live log call --------------------------------------------------------------
2020-12-10 18:55:48 INFO      pycloudlib.instance:instance.py:166 executing: sudo -- sh -c 'cat /var/log/cloud-init.log'
2020-12-10 18:55:58 INFO      pycloudlib.instance:instance.py:166 executing: sudo -- sh -c 'cat /proc/swaps'
2020-12-10 18:56:08 INFO      pycloudlib.instance:instance.py:166 executing: sudo -- sh -c 'cat /etc/fstab'
PASSED                                                                                                                              [100%]
------------------------------------------------------------ live log teardown ------------------------------------------------------------
2020-12-10 18:56:20 INFO      integration_testing:clouds.py:178 Deleting snapshot image created for this testrun: local:delicate-hyena-snapshot


====================================================== 1 passed in 502.24s (0:08:22) ======================================================
```

bionic:

```
GLOB sdist-make: /home/daniel/dev/cloud-init/setup.py
bionic inst-nodeps: /tmp/integration-tests-tox/.tmp/package/1/cloud-init-20.4.zip
bionic installed: adal==1.2.5,applicationinsights==0.11.9,argcomplete==1.12.2,attrs==20.3.0,azure-cli-core==2.16.0,azure-cli-telemetry==1.0.6,azure-common==1.1.26,azure-core==1.9.0,azure-mgmt-compute==14.0.0,azure-mgmt-core==1.2.1,azure-mgmt-network==13.0.0,azure-mgmt-resource==12.0.0,bcrypt==3.2.0,boto3==1.16.33,botocore==1.19.33,cachetools==4.1.1,certifi==2020.12.5,cffi==1.14.4,chardet==3.0.4,cloud-init @ file:///tmp/integration-tests-tox/.tmp/package/1/cloud-init-20.4.zip,colorama==0.4.4,configobj==5.0.6,configparser==4.0.2,coverage==5.3,cryptography==3.2.1,google-api-core==1.23.0,google-api-python-client==1.12.8,google-auth==1.23.0,google-auth-httplib2==0.0.4,googleapis-common-protos==1.52.0,httplib2==0.18.1,httpretty==1.0.3,humanfriendly==8.2,idna==2.10,iniconfig==1.1.1,isodate==0.6.0,Jinja2==2.11.2,jmespath==0.10.0,jsonpatch==1.28,jsonpointer==2.0,jsonschema==3.2.0,knack==0.7.2,MarkupSafe==1.1.1,msal==1.0.0,msal-extensions==0.1.3,msrest==0.6.19,msrestazure==0.6.4,oauthlib==3.1.0,oci==2.25.1,packaging==20.7,paramiko==2.7.2,pkginfo==1.6.1,pluggy==0.13.1,portalocker==1.7.1,protobuf==3.14.0,py==1.9.0,pyasn1==0.4.8,pyasn1-modules==0.2.8,pycloudlib @ git+https://github.com/canonical/pycloudlib.git@324763289c9a38fc9ac7ec524acb9eb11c7d6c13,pycparser==2.20,Pygments==2.7.3,PyJWT==1.7.1,PyNaCl==1.4.0,pyOpenSSL==19.1.0,pyparsing==2.4.7,pyrsistent==0.17.3,pytest==6.1.2,pytest-cov==2.10.1,python-dateutil==2.8.1,python-simplestreams @ git+https://git.launchpad.net/simplestreams@21c5bba2a5413c51e6b9131fc450e96f6b46090d,pytz==2020.4,PyYAML==5.3.1,requests==2.25.0,requests-oauthlib==1.3.0,rsa==4.6,s3transfer==0.3.3,six==1.15.0,tabulate==0.8.7,toml==0.10.2,uritemplate==3.0.1,urllib3==1.26.2
bionic run-test-pre: PYTHONHASHSEED='3828862569'
bionic run-test: commands[0] | /tmp/integration-tests-tox/bionic/bin/python -m pytest --log-cli-level=INFO bugs/test_lp1897099.py
======================================= test session starts ========================================
platform linux -- Python 3.8.6, pytest-6.1.2, py-1.9.0, pluggy-0.13.1
cachedir: /tmp/integration-tests-tox/bionic/.pytest_cache
rootdir: /home/daniel/dev/cloud-init, configfile: tox.ini
plugins: cov-2.10.1
collected 1 item

bugs/test_lp1897099.py::test_fallocate_fallback
------------------------------------------ live log setup ------------------------------------------
2020-12-10 20:17:25 INFO      integration_testing:clouds.py:73 Detected image: image_id=bionic os=ubuntu release=bionic
2020-12-10 20:17:25 INFO      integration_testing:clouds.py:73 Detected image: image_id=bionic os=ubuntu release=bionic
2020-12-10 20:17:39 INFO      integration_testing:clouds.py:104 Settings:
CLOUD_INIT_SOURCE=PROPOSED
COLLECT_LOGS=ON_ERROR
EXISTING_INSTANCE_ID=None
GCE_PROJECT=ubuntu-oddbloke
GCE_REGION=us-central1
GCE_ZONE=a
INSTANCE_TYPE=None
KEEP_IMAGE=true
KEEP_INSTANCE=False
LOCAL_LOG_PATH=/tmp/cloud_init_test_logs
OCI_COMPARTMENT_ID=None
OS_IMAGE=bionic
PLATFORM=lxd_vm
RUN_UNSTABLE=False
2020-12-10 20:17:39 INFO      integration_testing:conftest.py:140 Setting up environment for lxd_vm
2020-12-10 20:17:39 INFO      integration_testing:clouds.py:150 Launching instance with launch_kwargs:
image_id=ubuntu:e5819f74feb47ee275f907caf346e8a619c1f06f439d2a8eb83c7b960d5918e9
user_data=None
wait=False
2020-12-10 20:18:55 INFO      pycloudlib.instance:instance.py:166 executing: sh -c whoami
2020-12-10 20:18:57 INFO      pycloudlib.instance:instance.py:166 executing: sh -c whoami
2020-12-10 20:19:16 INFO      pycloudlib.instance:instance.py:166 executing: sh -c whoami
2020-12-10 20:19:28 INFO      pycloudlib.instance:instance.py:166 executing: sh -c whoami
2020-12-10 20:19:38 INFO      pycloudlib.instance:instance.py:166 executing: sh -c whoami
2020-12-10 20:19:50 INFO      pycloudlib.instance:instance.py:166 executing: sh -c whoami
2020-12-10 20:20:02 INFO      pycloudlib.instance:instance.py:166 executing: sh -c whoami
2020-12-10 20:20:04 INFO      pycloudlib.instance:instance.py:166 executing: sh -c 'cloud-init status --help'
2020-12-10 20:20:05 INFO      pycloudlib.instance:instance.py:166 executing: cloud-init status --wait --long
2020-12-10 20:20:09 INFO      integration_testing:clouds.py:159 Launched instance: LXDInstance(name=awaited-humpback)
2020-12-10 20:20:09 INFO      integration_testing:instances.py:144 Installing proposed image
2020-12-10 20:20:09 INFO      pycloudlib.instance:instance.py:166 executing: sudo -- sh -c 'echo deb "http://archive.ubuntu.com/ubuntu $(lsb_release -sc)-proposed main" | tee /etc/apt/sources.list.d/proposed.list
apt-get update -q
apt-get install -qy cloud-init'
2020-12-10 20:20:25 INFO      pycloudlib.instance:instance.py:166 executing: sudo -- sh -c 'cloud-init -v'
2020-12-10 20:20:26 INFO      integration_testing:instances.py:137 Installed cloud-init version: 20.4-0ubuntu1~18.04.1
2020-12-10 20:20:26 INFO      pycloudlib.instance:instance.py:166 executing: sh -c 'sudo cloud-init clean --logs'
2020-12-10 20:20:27 INFO      pycloudlib.instance:instance.py:166 executing: sh -c 'sudo rm -rf /var/log/syslog'
2020-12-10 20:20:28 INFO      pycloudlib.instance:instance.py:166 executing: sh -c 'sudo cloud-init clean --logs'
2020-12-10 20:20:29 INFO      pycloudlib.instance:instance.py:166 executing: sh -c 'sudo rm -rf /var/log/syslog'
2020-12-10 20:20:30 INFO      pycloudlib.instance:instance.py:166 executing: sh -c 'sudo cloud-init clean --logs'
2020-12-10 20:20:31 INFO      pycloudlib.instance:instance.py:166 executing: sh -c 'sudo rm -rf /var/log/syslog'
2020-12-10 20:24:09 INFO      integration_testing:instances.py:117 Created new image: local:awaited-humpback-snapshot
2020-12-10 20:24:10 INFO      integration_testing:conftest.py:146 Done with environment setup
2020-12-10 20:24:10 INFO      integration_testing:clouds.py:150 Launching instance with launch_kwargs:
image_id=local:awaited-humpback-snapshot
user_data=#cloud-config
bootcmd:
  - echo 'whoops' > /usr/bin/fallocate
swap:
  filename: /swap.img
  size: 10000000
  maxsize: 10000000

wait=False
2020-12-10 20:26:06 INFO      pycloudlib.instance:instance.py:166 executing: sh -c whoami
2020-12-10 20:26:08 INFO      pycloudlib.instance:instance.py:166 executing: sh -c whoami
2020-12-10 20:26:20 INFO      pycloudlib.instance:instance.py:166 executing: sh -c whoami
2020-12-10 20:26:33 INFO      pycloudlib.instance:instance.py:166 executing: sh -c whoami
2020-12-10 20:26:45 INFO      pycloudlib.instance:instance.py:166 executing: sh -c whoami
2020-12-10 20:26:57 INFO      pycloudlib.instance:instance.py:166 executing: sh -c whoami
2020-12-10 20:26:58 INFO      pycloudlib.instance:instance.py:166 executing: sh -c 'cloud-init status --help'
2020-12-10 20:26:59 INFO      pycloudlib.instance:instance.py:166 executing: cloud-init status --wait --long
2020-12-10 20:27:01 INFO      integration_testing:clouds.py:159 Launched instance: LXDInstance(name=winning-roughy)
------------------------------------------ live log call -------------------------------------------
2020-12-10 20:27:01 INFO      pycloudlib.instance:instance.py:166 executing: sudo -- sh -c 'cat /var/log/cloud-init.log'
2020-12-10 20:27:02 INFO      pycloudlib.instance:instance.py:166 executing: sudo -- sh -c 'cat /proc/swaps'
2020-12-10 20:27:03 INFO      pycloudlib.instance:instance.py:166 executing: sudo -- sh -c 'cat /etc/fstab'
PASSED                                                                                       [100%]
---------------------------------------- live log teardown -----------------------------------------
2020-12-10 20:27:04 INFO      integration_testing:clouds.py:174 NOT deleting snapshot image created for this testrun because KEEP_IMAGE is True: local:awaited-humpback-snapshot


========================================= warnings summary =========================================
tests/integration_tests/bugs/test_lp1897099.py::test_fallocate_fallback
tests/integration_tests/bugs/test_lp1897099.py::test_fallocate_fallback
tests/integration_tests/bugs/test_lp1897099.py::test_fallocate_fallback
  /tmp/integration-tests-tox/bionic/lib/python3.8/site-packages/simplestreams/mirrors/__init__.py:206: DeprecationWarning: The 'warn' method is deprecated, use 'warning' instead
    LOG.warn("got ENOENT for (%s, %s), trying with trailing /",

-- Docs: https://docs.pytest.org/en/stable/warnings.html
============================ 1 passed, 3 warnings in 579.05s (0:09:39) =============================
```

focal:

```
GLOB sdist-make: /home/daniel/dev/cloud-init/setup.py
focal inst-nodeps: /tmp/integration-tests-tox/.tmp/package/2/cloud-init-20.4.zip
focal installed: adal==1.2.5,applicationinsights==0.11.9,argcomplete==1.12.2,attrs==20.3.0,azure-cli-core==2.16.0,azure-cli-telemetry==1.0.6,azure-common==1.1.26,azure-core==1.9.0,azure-mgmt-compute==14.0.0,azure-mgmt-core==1.2.1,azure-mgmt-network==13.0.0,azure-mgmt-resource==12.0.0,bcrypt==3.2.0,boto3==1.16.33,botocore==1.19.33,cachetools==4.1.1,certifi==2020.12.5,cffi==1.14.4,chardet==3.0.4,cloud-init @ file:///tmp/integration-tests-tox/.tmp/package/2/cloud-init-20.4.zip,colorama==0.4.4,configobj==5.0.6,configparser==4.0.2,coverage==5.3,cryptography==3.2.1,google-api-core==1.23.0,google-api-python-client==1.12.8,google-auth==1.23.0,google-auth-httplib2==0.0.4,googleapis-common-protos==1.52.0,httplib2==0.18.1,httpretty==1.0.3,humanfriendly==8.2,idna==2.10,iniconfig==1.1.1,isodate==0.6.0,Jinja2==2.11.2,jmespath==0.10.0,jsonpatch==1.28,jsonpointer==2.0,jsonschema==3.2.0,knack==0.7.2,MarkupSafe==1.1.1,msal==1.0.0,msal-extensions==0.1.3,msrest==0.6.19,msrestazure==0.6.4,oauthlib==3.1.0,oci==2.25.1,packaging==20.7,paramiko==2.7.2,pkginfo==1.6.1,pluggy==0.13.1,portalocker==1.7.1,protobuf==3.14.0,py==1.9.0,pyasn1==0.4.8,pyasn1-modules==0.2.8,pycloudlib @ git+https://github.com/canonical/pycloudlib.git@324763289c9a38fc9ac7ec524acb9eb11c7d6c13,pycparser==2.20,Pygments==2.7.3,PyJWT==1.7.1,PyNaCl==1.4.0,pyOpenSSL==19.1.0,pyparsing==2.4.7,pyrsistent==0.17.3,pytest==6.1.2,pytest-cov==2.10.1,python-dateutil==2.8.1,python-simplestreams @ git+https://git.launchpad.net/simplestreams@21c5bba2a5413c51e6b9131fc450e96f6b46090d,pytz==2020.4,PyYAML==5.3.1,requests==2.25.0,requests-oauthlib==1.3.0,rsa==4.6,s3transfer==0.3.3,six==1.15.0,tabulate==0.8.7,toml==0.10.2,uritemplate==3.0.1,urllib3==1.26.2
focal run-test-pre: PYTHONHASHSEED='2138496199'
focal run-test: commands[0] | /tmp/integration-tests-tox/focal/bin/python -m pytest --log-cli-level=INFO bugs/test_lp1897099.py
======================================= test session starts ========================================
platform linux -- Python 3.8.6, pytest-6.1.2, py-1.9.0, pluggy-0.13.1
cachedir: /tmp/integration-tests-tox/focal/.pytest_cache
rootdir: /home/daniel/dev/cloud-init, configfile: tox.ini
plugins: cov-2.10.1
collected 1 item

bugs/test_lp1897099.py::test_fallocate_fallback
------------------------------------------ live log setup ------------------------------------------
2020-12-10 20:17:39 INFO      integration_testing:clouds.py:73 Detected image: image_id=focal os=ubuntu release=focal
2020-12-10 20:17:39 INFO      integration_testing:clouds.py:73 Detected image: image_id=focal os=ubuntu release=focal
2020-12-10 20:17:50 INFO      integration_testing:clouds.py:104 Settings:
CLOUD_INIT_SOURCE=PROPOSED
COLLECT_LOGS=ON_ERROR
EXISTING_INSTANCE_ID=None
GCE_PROJECT=ubuntu-oddbloke
GCE_REGION=us-central1
GCE_ZONE=a
INSTANCE_TYPE=None
KEEP_IMAGE=true
KEEP_INSTANCE=False
LOCAL_LOG_PATH=/tmp/cloud_init_test_logs
OCI_COMPARTMENT_ID=None
OS_IMAGE=focal
PLATFORM=lxd_vm
RUN_UNSTABLE=False
2020-12-10 20:17:50 INFO      integration_testing:conftest.py:140 Setting up environment for lxd_vm
2020-12-10 20:17:50 INFO      integration_testing:clouds.py:150 Launching instance with launch_kwargs:
image_id=ubuntu:324a6f70e0af79c7d10006de001a7f4e551db8ff4cf42d27da27b845c04da926
user_data=None
wait=False
2020-12-10 20:19:07 INFO      pycloudlib.instance:instance.py:166 executing: sh -c whoami
2020-12-10 20:19:09 INFO      pycloudlib.instance:instance.py:166 executing: sh -c whoami
2020-12-10 20:19:21 INFO      pycloudlib.instance:instance.py:166 executing: sh -c whoami
2020-12-10 20:19:34 INFO      pycloudlib.instance:instance.py:166 executing: sh -c whoami
2020-12-10 20:19:36 INFO      pycloudlib.instance:instance.py:166 executing: sh -c 'cloud-init status --help'
2020-12-10 20:19:38 INFO      pycloudlib.instance:instance.py:166 executing: cloud-init status --wait --long
2020-12-10 20:19:52 INFO      integration_testing:clouds.py:159 Launched instance: LXDInstance(name=meet-toucan)
2020-12-10 20:19:52 INFO      integration_testing:instances.py:144 Installing proposed image
2020-12-10 20:19:52 INFO      pycloudlib.instance:instance.py:166 executing: sudo -- sh -c 'echo deb "http://archive.ubuntu.com/ubuntu $(lsb_release -sc)-proposed main" | tee /etc/apt/sources.list.d/proposed.list
apt-get update -q
apt-get install -qy cloud-init'
2020-12-10 20:20:10 INFO      pycloudlib.instance:instance.py:166 executing: sudo -- sh -c 'cloud-init -v'
2020-12-10 20:20:11 INFO      integration_testing:instances.py:137 Installed cloud-init version: 20.4-0ubuntu1~20.04.1
2020-12-10 20:20:11 INFO      pycloudlib.instance:instance.py:166 executing: sh -c 'sudo cloud-init clean --logs'
2020-12-10 20:20:12 INFO      pycloudlib.instance:instance.py:166 executing: sh -c 'sudo rm -rf /var/log/syslog'
2020-12-10 20:20:13 INFO      pycloudlib.instance:instance.py:166 executing: sh -c 'sudo cloud-init clean --logs'
2020-12-10 20:20:14 INFO      pycloudlib.instance:instance.py:166 executing: sh -c 'sudo rm -rf /var/log/syslog'
2020-12-10 20:20:15 INFO      pycloudlib.instance:instance.py:166 executing: sh -c 'sudo cloud-init clean --logs'
2020-12-10 20:20:16 INFO      pycloudlib.instance:instance.py:166 executing: sh -c 'sudo rm -rf /var/log/syslog'
2020-12-10 20:21:48 INFO      integration_testing:instances.py:117 Created new image: local:meet-toucan-snapshot
2020-12-10 20:21:49 INFO      integration_testing:conftest.py:146 Done with environment setup
2020-12-10 20:21:49 INFO      integration_testing:clouds.py:150 Launching instance with launch_kwargs:
image_id=local:meet-toucan-snapshot
user_data=#cloud-config
bootcmd:
  - echo 'whoops' > /usr/bin/fallocate
swap:
  filename: /swap.img
  size: 10000000
  maxsize: 10000000

wait=False
2020-12-10 20:24:04 INFO      pycloudlib.instance:instance.py:166 executing: sh -c whoami
2020-12-10 20:24:06 INFO      pycloudlib.instance:instance.py:166 executing: sh -c whoami
2020-12-10 20:24:19 INFO      pycloudlib.instance:instance.py:166 executing: sh -c whoami
2020-12-10 20:24:30 INFO      pycloudlib.instance:instance.py:166 executing: sh -c whoami
2020-12-10 20:24:44 INFO      pycloudlib.instance:instance.py:166 executing: sh -c whoami
2020-12-10 20:24:45 INFO      pycloudlib.instance:instance.py:166 executing: sh -c 'cloud-init status --help'
2020-12-10 20:24:46 INFO      pycloudlib.instance:instance.py:166 executing: cloud-init status --wait --long
2020-12-10 20:24:47 INFO      integration_testing:clouds.py:159 Launched instance: LXDInstance(name=logical-marmoset)
------------------------------------------ live log call -------------------------------------------
2020-12-10 20:24:47 INFO      pycloudlib.instance:instance.py:166 executing: sudo -- sh -c 'cat /var/log/cloud-init.log'
2020-12-10 20:24:48 INFO      pycloudlib.instance:instance.py:166 executing: sudo -- sh -c 'cat /proc/swaps'
2020-12-10 20:24:53 INFO      pycloudlib.instance:instance.py:166 executing: sudo -- sh -c 'cat /etc/fstab'
PASSED                                                                                       [100%]
---------------------------------------- live log teardown -----------------------------------------
2020-12-10 20:24:55 INFO      integration_testing:clouds.py:174 NOT deleting snapshot image created for this testrun because KEEP_IMAGE is True: local:meet-toucan-snapshot


========================================= warnings summary =========================================
tests/integration_tests/bugs/test_lp1897099.py::test_fallocate_fallback
tests/integration_tests/bugs/test_lp1897099.py::test_fallocate_fallback
  /tmp/integration-tests-tox/focal/lib/python3.8/site-packages/simplestreams/mirrors/__init__.py:206: DeprecationWarning: The 'warn' method is deprecated, use 'warning' instead
    LOG.warn("got ENOENT for (%s, %s), trying with trailing /",

-- Docs: https://docs.pytest.org/en/stable/warnings.html
============================ 1 passed, 2 warnings in 435.68s (0:07:15) =============================
```

groovy:

```
GLOB sdist-make: /home/daniel/dev/cloud-init/setup.py
groovy recreate: /tmp/integration-tests-tox/groovy
groovy installdeps: -r/home/daniel/dev/cloud-init/tests/integration_tests/../../integration-requirements.txt, -r/home/daniel/dev/cloud-init/tests/integration_tests/../../test-requirements.txt
groovy inst: /tmp/integration-tests-tox/.tmp/package/3/cloud-init-20.4.zip
groovy installed: adal==1.2.5,applicationinsights==0.11.9,argcomplete==1.12.2,attrs==20.3.0,azure-cli-core==2.16.0,azure-cli-telemetry==1.0.6,azure-common==1.1.26,azure-core==1.9.0,azure-mgmt-compute==14.0.0,azure-mgmt-core==1.2.1,azure-mgmt-network==13.0.0,azure-mgmt-resource==12.0.0,bcrypt==3.2.0,boto3==1.16.33,botocore==1.19.33,cachetools==4.1.1,certifi==2020.12.5,cffi==1.14.4,chardet==3.0.4,cloud-init @ file:///tmp/integration-tests-tox/.tmp/package/3/cloud-init-20.4.zip,colorama==0.4.4,configobj==5.0.6,configparser==4.0.2,coverage==5.3,cryptography==3.2.1,google-api-core==1.23.0,google-api-python-client==1.12.8,google-auth==1.23.0,google-auth-httplib2==0.0.4,googleapis-common-protos==1.52.0,httplib2==0.18.1,httpretty==1.0.3,humanfriendly==8.2,idna==2.10,iniconfig==1.1.1,isodate==0.6.0,Jinja2==2.11.2,jmespath==0.10.0,jsonpatch==1.28,jsonpointer==2.0,jsonschema==3.2.0,knack==0.7.2,MarkupSafe==1.1.1,msal==1.0.0,msal-extensions==0.1.3,msrest==0.6.19,msrestazure==0.6.4,oauthlib==3.1.0,oci==2.25.1,packaging==20.7,paramiko==2.7.2,pkginfo==1.6.1,pluggy==0.13.1,portalocker==1.7.1,protobuf==3.14.0,py==1.9.0,pyasn1==0.4.8,pyasn1-modules==0.2.8,pycloudlib @ git+https://github.com/canonical/pycloudlib.git@d1c63026c76ed3ef02dc21982f9f7eeea2606f2a,pycparser==2.20,Pygments==2.7.3,PyJWT==1.7.1,PyNaCl==1.4.0,pyOpenSSL==20.0.0,pyparsing==2.4.7,pyrsistent==0.17.3,pytest==6.1.2,pytest-cov==2.10.1,python-dateutil==2.8.1,python-simplestreams @ git+https://git.launchpad.net/simplestreams@21c5bba2a5413c51e6b9131fc450e96f6b46090d,pytz==2020.4,PyYAML==5.3.1,requests==2.25.0,requests-oauthlib==1.3.0,rsa==4.6,s3transfer==0.3.3,six==1.15.0,tabulate==0.8.7,toml==0.10.2,uritemplate==3.0.1,urllib3==1.26.2
groovy run-test-pre: PYTHONHASHSEED='3385205031'
groovy run-test: commands[0] | /tmp/integration-tests-tox/groovy/bin/python -m pytest --log-cli-level=INFO bugs/test_lp1897099.py
======================================= test session starts ========================================
platform linux -- Python 3.8.6, pytest-6.1.2, py-1.9.0, pluggy-0.13.1
cachedir: /tmp/integration-tests-tox/groovy/.pytest_cache
rootdir: /home/daniel/dev/cloud-init, configfile: tox.ini
plugins: cov-2.10.1
collected 1 item

bugs/test_lp1897099.py::test_fallocate_fallback
------------------------------------------ live log setup ------------------------------------------
2020-12-10 20:22:06 INFO      integration_testing:clouds.py:73 Detected image: image_id=groovy os=ubuntu release=groovy
2020-12-10 20:22:06 INFO      integration_testing:clouds.py:73 Detected image: image_id=groovy os=ubuntu release=groovy
2020-12-10 20:22:16 INFO      integration_testing:clouds.py:104 Settings:
CLOUD_INIT_SOURCE=PROPOSED
COLLECT_LOGS=ON_ERROR
EXISTING_INSTANCE_ID=None
GCE_PROJECT=ubuntu-oddbloke
GCE_REGION=us-central1
GCE_ZONE=a
INSTANCE_TYPE=None
KEEP_IMAGE=true
KEEP_INSTANCE=False
LOCAL_LOG_PATH=/tmp/cloud_init_test_logs
OCI_COMPARTMENT_ID=None
OS_IMAGE=groovy
PLATFORM=lxd_vm
RUN_UNSTABLE=False
2020-12-10 20:22:16 INFO      integration_testing:conftest.py:140 Setting up environment for lxd_vm
2020-12-10 20:22:16 INFO      integration_testing:clouds.py:150 Launching instance with launch_kwargs:
image_id=ubuntu:b43f7b486a7c27a833c644b51e4995d7de4c9c398d3fa930229b0b271da4ef0f
user_data=None
wait=False
2020-12-10 20:25:06 INFO      pycloudlib.instance:instance.py:166 executing: sh -c whoami
2020-12-10 20:25:08 INFO      pycloudlib.instance:instance.py:166 executing: sh -c whoami
2020-12-10 20:25:20 INFO      pycloudlib.instance:instance.py:166 executing: sh -c whoami
2020-12-10 20:25:35 INFO      pycloudlib.instance:instance.py:166 executing: sh -c whoami
2020-12-10 20:25:46 INFO      pycloudlib.instance:instance.py:166 executing: sh -c whoami
2020-12-10 20:26:03 INFO      pycloudlib.instance:instance.py:166 executing: sh -c whoami
2020-12-10 20:26:16 INFO      pycloudlib.instance:instance.py:166 executing: sh -c whoami
2020-12-10 20:26:18 INFO      pycloudlib.instance:instance.py:166 executing: sh -c 'cloud-init status --help'
2020-12-10 20:26:20 INFO      pycloudlib.instance:instance.py:166 executing: cloud-init status --wait --long
2020-12-10 20:26:23 INFO      integration_testing:clouds.py:159 Launched instance: LXDInstance(name=civil-monarch)
2020-12-10 20:26:23 INFO      integration_testing:instances.py:144 Installing proposed image
2020-12-10 20:26:23 INFO      pycloudlib.instance:instance.py:166 executing: sudo -- sh -c 'echo deb "http://archive.ubuntu.com/ubuntu $(lsb_release -sc)-proposed main" | tee /etc/apt/sources.list.d/proposed.list
apt-get update -q
apt-get install -qy cloud-init'
2020-12-10 20:26:40 INFO      pycloudlib.instance:instance.py:166 executing: sudo -- sh -c 'cloud-init -v'
2020-12-10 20:26:41 INFO      integration_testing:instances.py:137 Installed cloud-init version: 20.4-0ubuntu1~20.10.1
2020-12-10 20:26:41 INFO      pycloudlib.instance:instance.py:166 executing: sh -c 'sudo cloud-init clean --logs'
2020-12-10 20:26:42 INFO      pycloudlib.instance:instance.py:166 executing: sh -c 'sudo rm -rf /var/log/syslog'
2020-12-10 20:26:43 INFO      pycloudlib.instance:instance.py:166 executing: sh -c 'sudo cloud-init clean --logs'
2020-12-10 20:26:44 INFO      pycloudlib.instance:instance.py:166 executing: sh -c 'sudo rm -rf /var/log/syslog'
2020-12-10 20:26:45 INFO      pycloudlib.instance:instance.py:166 executing: sh -c 'sudo cloud-init clean --logs'
2020-12-10 20:26:46 INFO      pycloudlib.instance:instance.py:166 executing: sh -c 'sudo rm -rf /var/log/syslog'
2020-12-10 20:28:17 INFO      integration_testing:instances.py:117 Created new image: local:civil-monarch-snapshot
2020-12-10 20:28:17 INFO      integration_testing:conftest.py:146 Done with environment setup
2020-12-10 20:28:17 INFO      integration_testing:clouds.py:150 Launching instance with launch_kwargs:
image_id=local:civil-monarch-snapshot
user_data=#cloud-config
bootcmd:
  - echo 'whoops' > /usr/bin/fallocate
swap:
  filename: /swap.img
  size: 10000000
  maxsize: 10000000

wait=False
2020-12-10 20:29:49 INFO      pycloudlib.instance:instance.py:166 executing: sh -c whoami
2020-12-10 20:29:52 INFO      pycloudlib.instance:instance.py:166 executing: sh -c whoami
2020-12-10 20:30:04 INFO      pycloudlib.instance:instance.py:166 executing: sh -c whoami
2020-12-10 20:30:16 INFO      pycloudlib.instance:instance.py:166 executing: sh -c whoami
2020-12-10 20:30:19 INFO      pycloudlib.instance:instance.py:166 executing: sh -c 'cloud-init status --help'
2020-12-10 20:30:21 INFO      pycloudlib.instance:instance.py:166 executing: cloud-init status --wait --long
2020-12-10 20:30:22 INFO      integration_testing:clouds.py:159 Launched instance: LXDInstance(name=aware-ewe)
------------------------------------------ live log call -------------------------------------------
2020-12-10 20:30:22 INFO      pycloudlib.instance:instance.py:166 executing: sudo -- sh -c 'cat /var/log/cloud-init.log'
2020-12-10 20:30:23 INFO      pycloudlib.instance:instance.py:166 executing: sudo -- sh -c 'cat /proc/swaps'
2020-12-10 20:30:24 INFO      pycloudlib.instance:instance.py:166 executing: sudo -- sh -c 'cat /etc/fstab'
PASSED                                                                                       [100%]
---------------------------------------- live log teardown -----------------------------------------
2020-12-10 20:30:26 INFO      integration_testing:clouds.py:174 NOT deleting snapshot image created for this testrun because KEEP_IMAGE is True: local:civil-monarch-snapshot


========================================= warnings summary =========================================
tests/integration_tests/bugs/test_lp1897099.py::test_fallocate_fallback
tests/integration_tests/bugs/test_lp1897099.py::test_fallocate_fallback
  /tmp/integration-tests-tox/groovy/lib/python3.8/site-packages/simplestreams/mirrors/__init__.py:206: DeprecationWarning: The 'warn' method is deprecated, use 'warning' instead
    LOG.warn("got ENOENT for (%s, %s), trying with trailing /",

-- Docs: https://docs.pytest.org/en/stable/warnings.html
============================ 1 passed, 2 warnings in 499.96s (0:08:19) =============================
```

[Regression Potential]

This change only affects swap file creation, so most uses of cloud-init will
not even execute the modified code.  The commands executed are unchanged, the
only difference is we will now execute `dd` as well as `fallocate` if
`fallocate` fails, which does represent a change in behaviour.
