https://github.com/canonical/cloud-init/commit/66e2d42dd1b722dc8e59f4e5990cea54f81ccd2a

=== Begin SRU Template ===
[Impact]
cloud-init might incorrectly consider reboot as new-instance during kernel
upgrade or downgrade

[Test Case]
There is an upstream test for this bug:
https://github.com/canonical/cloud-init/blob/master/tests/integration_tests/bugs/test_lp1835584.py

=== Xenial ===
n/a

=== Bionic ===
============================= test session starts ==============================
platform linux -- Python 3.5.9, pytest-5.4.2, py-1.8.1, pluggy-0.13.1
rootdir: /home/james/cloud-init-tests, inifile: tox.ini
plugins: cov-2.9.0
collected 1 item

tests/integration_tests/bugs/test_lp1835584.py::test_azure_kernel_upgrade_case_insensitive_uuid Detected image: image_id=bionic os=ubuntu release=bionic

-------------------------------- live log setup --------------------------------
2021-03-29 14:05:16 INFO      integration_testing:clouds.py:87 Detected image: image_id=bionic os=ubuntu release=bionic
Detected image: image_id=bionic os=ubuntu release=bionic
2021-03-29 14:05:17 INFO      integration_testing:clouds.py:87 Detected image: image_id=bionic os=ubuntu release=bionic
Settings:
CLOUD_INIT_SOURCE=PROPOSED
COLLECT_LOGS=NEVER
EXISTING_INSTANCE_ID=None
INSTANCE_TYPE=None
KEEP_IMAGE=False
KEEP_INSTANCE=False
KEYPAIR_NAME=None
LOCAL_LOG_PATH=/tmp/cloud_init_test_logs
OPENSTACK_NETWORK=falcojr_admin_net
OS_IMAGE=bionic
PLATFORM=azure
PUBLIC_SSH_KEY=None
RUN_UNSTABLE=False
2021-03-29 14:05:17 INFO      integration_testing:clouds.py:128 Settings:
CLOUD_INIT_SOURCE=PROPOSED
COLLECT_LOGS=NEVER
EXISTING_INSTANCE_ID=None
INSTANCE_TYPE=None
KEEP_IMAGE=False
KEEP_INSTANCE=False
KEYPAIR_NAME=None
LOCAL_LOG_PATH=/tmp/cloud_init_test_logs
OPENSTACK_NETWORK=falcojr_admin_net
OS_IMAGE=bionic
PLATFORM=azure
PUBLIC_SSH_KEY=None
RUN_UNSTABLE=False
Detected image: image_id=bionic os=ubuntu release=bionic
-------------------------------- live log call ---------------------------------
2021-03-29 14:05:17 INFO      integration_testing:clouds.py:87 Detected image: image_id=bionic os=ubuntu release=bionic
Launching instance with launch_kwargs:
image_id=Canonical:0001-com-ubuntu-pro-bionic-fips:pro-fips-18_04:18.04.202010201
user_data=None
2021-03-29 14:05:17 INFO      integration_testing:clouds.py:167 Launching instance with launch_kwargs:
image_id=Canonical:0001-com-ubuntu-pro-bionic-fips:pro-fips-18_04:18.04.202010201
user_data=None
2021-03-29 14:07:54 INFO      pycloudlib.instance:instance.py:165 executing: sh -c whoami
2021-03-29 14:07:54 INFO      paramiko.transport:transport.py:1819 Connected (version 2.0, client OpenSSH_7.9p1)
2021-03-29 14:07:56 INFO      paramiko.transport:transport.py:1819 Authentication (publickey) successful!
2021-03-29 14:07:59 INFO      pycloudlib.instance:instance.py:165 executing: sh -c 'cloud-init status --help'
2021-03-29 14:08:01 INFO      pycloudlib.instance:instance.py:165 executing: cloud-init status --wait --long
Launched instance: <pycloudlib.azure.instance.AzureInstance object at 0x7fbc054b5b00>
2021-03-29 14:08:11 INFO      integration_testing:clouds.py:171 Launched instance: <pycloudlib.azure.instance.AzureInstance object at 0x7fbc054b5b00>
2021-03-29 14:08:11 INFO      pycloudlib.instance:instance.py:165 executing: sudo -- sh -c 'cloud-init --version'
cloud-init version: /usr/bin/cloud-init 20.3-2-g371b392c-0ubuntu1~18.04.1
2021-03-29 14:08:12 INFO      integration_testing:clouds.py:177 cloud-init version: /usr/bin/cloud-init 20.3-2-g371b392c-0ubuntu1~18.04.1
2021-03-29 14:08:12 INFO      pycloudlib.instance:instance.py:165 executing: sudo -- sh -c 'grep serial /etc/cloud/build.info'
image serial: 20201020.1
2021-03-29 14:08:12 INFO      integration_testing:clouds.py:181 image serial: 20201020.1
Installing proposed image
2021-03-29 14:08:12 INFO      integration_testing:instances.py:144 Installing proposed image
2021-03-29 14:08:12 INFO      pycloudlib.instance:instance.py:165 executing: sudo -- sh -c 'echo deb "http://archive.ubuntu.com/ubuntu $(lsb_release -sc)-proposed main" | tee /etc/apt/sources.list.d/proposed.list
apt-get update -q
apt-get install -qy cloud-init'
2021-03-29 14:08:34 INFO      pycloudlib.instance:instance.py:165 executing: sudo -- sh -c 'cloud-init -v'
Installed cloud-init version: 21.1-19-gbad84ad4-0ubuntu1~18.04.1
2021-03-29 14:08:35 INFO      integration_testing:instances.py:136 Installed cloud-init version: 21.1-19-gbad84ad4-0ubuntu1~18.04.1
2021-03-29 14:08:35 INFO      pycloudlib.instance:instance.py:165 executing: sudo -- sh -c 'cat /sys/class/dmi/id/product_uuid'
2021-03-29 14:08:35 INFO      pycloudlib.instance:instance.py:165 executing: sudo -- sh -c 'uname -r'
2021-03-29 14:08:35 INFO      pycloudlib.instance:instance.py:165 executing: sudo -- sh -c 'apt-get update'
2021-03-29 14:08:38 INFO      pycloudlib.instance:instance.py:165 executing: sudo -- sh -c 'apt-get install linux-azure --assume-yes'
Restarting instance and waiting for boot
2021-03-29 14:09:29 INFO      integration_testing:instances.py:65 Restarting instance and waiting for boot
2021-03-29 14:10:00 INFO      pycloudlib.instance:instance.py:165 executing: sh -c whoami
2021-03-29 14:10:00 INFO      pycloudlib.instance:instance.py:343 [Errno None] Unable to connect to port 22 on 13.89.140.213
Retrying SSH connection to ubuntu@13.89.140.213:22 (599s left)
2021-03-29 14:10:01 INFO      pycloudlib.instance:instance.py:343 [Errno None] Unable to connect to port 22 on 13.89.140.213
Retrying SSH connection to ubuntu@13.89.140.213:22 (598s left)
2021-03-29 14:10:02 INFO      pycloudlib.instance:instance.py:343 [Errno None] Unable to connect to port 22 on 13.89.140.213
Retrying SSH connection to ubuntu@13.89.140.213:22 (597s left)
2021-03-29 14:10:03 INFO      pycloudlib.instance:instance.py:343 [Errno None] Unable to connect to port 22 on 13.89.140.213
Retrying SSH connection to ubuntu@13.89.140.213:22 (596s left)
2021-03-29 14:10:04 INFO      paramiko.transport:transport.py:1819 Connected (version 2.0, client OpenSSH_7.9p1)
2021-03-29 14:10:04 INFO      paramiko.transport:transport.py:1819 Authentication (publickey) successful!
2021-03-29 14:10:07 INFO      pycloudlib.instance:instance.py:165 executing: sh -c 'cloud-init status --help'
2021-03-29 14:10:08 INFO      pycloudlib.instance:instance.py:165 executing: cloud-init status --wait --long
2021-03-29 14:10:10 INFO      pycloudlib.instance:instance.py:165 executing: sudo -- sh -c 'uname -r'
2021-03-29 14:10:10 INFO      pycloudlib.instance:instance.py:165 executing: sudo -- sh -c 'cat /sys/class/dmi/id/product_uuid'
2021-03-29 14:10:11 INFO      pycloudlib.instance:instance.py:165 executing: sudo -- sh -c 'cat /var/log/cloud-init.log'
PASSED

======================== 1 passed in 336.57s (0:05:36) =========================



=== Focal ===
n/a

=== Groovy ===
n/a

[Regression Potential]
New instances will no longer be created when they were incorrectly being
created before.
