Upstream test at:
https://github.com/canonical/cloud-init/blob/master/tests/integration_tests/test_upgrade.py

Logs from individual before/after runs in ec2-sru-21.2-3 subdirectory

==== Bionic ====
-------------------------------- live log setup --------------------------------
2021-05-17 23:55:42 INFO      integration_testing:clouds.py:88 Detected image: image_id=bionic os=ubuntu release=bionic
Detected image: image_id=bionic os=ubuntu release=bionic
-------------------------------- live log call ---------------------------------
2021-05-17 23:55:42 INFO      integration_testing:clouds.py:88 Detected image: image_id=bionic os=ubuntu release=bionic
Launching instance with launch_kwargs:
image_id=ami-0600b1bef20a0c212
user_data=#cloud-config
hostname: SRU-worked

2021-05-17 23:55:42 INFO      integration_testing:clouds.py:168 Launching instance with launch_kwargs:
image_id=ami-0600b1bef20a0c212
user_data=#cloud-config
hostname: SRU-worked

2021-05-17 23:55:43 INFO      paramiko.transport.sftp:sftp.py:158 [chan 8] sftp session closed.
2021-05-17 23:56:14 INFO      pycloudlib.instance:instance.py:165 executing: sh -c whoami
2021-05-17 23:56:15 INFO      pycloudlib.instance:instance.py:343 [Errno None] Unable to connect to port 22 on 3.14.1.108
Retrying SSH connection to ubuntu@3.14.1.108:22 (598s left)
2021-05-17 23:56:16 INFO      pycloudlib.instance:instance.py:343 [Errno None] Unable to connect to port 22 on 3.14.1.108
Retrying SSH connection to ubuntu@3.14.1.108:22 (597s left)
2021-05-17 23:56:18 INFO      pycloudlib.instance:instance.py:343 [Errno None] Unable to connect to port 22 on 3.14.1.108
Retrying SSH connection to ubuntu@3.14.1.108:22 (596s left)
2021-05-17 23:56:19 INFO      paramiko.transport:transport.py:1819 Connected (version 2.0, client OpenSSH_7.6p1)
2021-05-17 23:56:19 INFO      paramiko.transport:transport.py:1819 Authentication (publickey) successful!
2021-05-17 23:56:21 INFO      pycloudlib.instance:instance.py:165 executing: cloud-init status --wait --long
Launched instance: EC2Instance(key_pair=KeyPair(/home/james/.ssh/id_rsa, /home/james/.ssh/id_rsa.pub, name=james), client=<botocore.client.EC2 object at 0x7f635eddab70>, instance=ec2.Instance(id='i-0ee07d07d56452d90'))
2021-05-17 23:56:34 INFO      integration_testing:clouds.py:173 Launched instance: EC2Instance(key_pair=KeyPair(/home/james/.ssh/id_rsa, /home/james/.ssh/id_rsa.pub, name=james), client=<botocore.client.EC2 object at 0x7f635eddab70>, instance=ec2.Instance(id='i-0ee07d07d56452d90'))
2021-05-17 23:56:34 INFO      pycloudlib.instance:instance.py:165 executing: sudo -- sh -c 'cloud-init --version'
cloud-init version: /usr/bin/cloud-init 21.1-19-gbad84ad4-0ubuntu1~18.04.2
2021-05-17 23:56:35 INFO      integration_testing:clouds.py:179 cloud-init version: /usr/bin/cloud-init 21.1-19-gbad84ad4-0ubuntu1~18.04.2
2021-05-17 23:56:35 INFO      pycloudlib.instance:instance.py:165 executing: sudo -- sh -c 'grep serial /etc/cloud/build.info'
image serial: 20210514
2021-05-17 23:56:35 INFO      integration_testing:clouds.py:183 image serial: 20210514
2021-05-17 23:56:35 INFO      pycloudlib.instance:instance.py:165 executing: sudo -- sh -c hostname
2021-05-17 23:56:35 INFO      pycloudlib.instance:instance.py:165 executing: sudo -- sh -c 'dpkg-query --show cloud-init'
2021-05-17 23:56:36 INFO      pycloudlib.instance:instance.py:165 executing: sudo -- sh -c 'cat /run/cloud-init/result.json'
2021-05-17 23:56:36 INFO      pycloudlib.instance:instance.py:165 executing: sudo -- sh -c 'cloud-init init'
2021-05-17 23:56:37 INFO      pycloudlib.instance:instance.py:165 executing: sudo -- sh -c 'grep Trace /var/log/cloud-init.log'
2021-05-17 23:56:37 INFO      pycloudlib.instance:instance.py:165 executing: sudo -- sh -c cloud-id
2021-05-17 23:56:37 INFO      pycloudlib.instance:instance.py:165 executing: sudo -- sh -c 'cat /etc/netplan/50-cloud-init.yaml'
2021-05-17 23:56:38 INFO      pycloudlib.instance:instance.py:165 executing: sudo -- sh -c systemd-analyze
2021-05-17 23:56:38 INFO      pycloudlib.instance:instance.py:165 executing: sudo -- sh -c 'systemd-analyze blame'
2021-05-17 23:56:38 INFO      pycloudlib.instance:instance.py:165 executing: sudo -- sh -c 'cloud-init analyze show'
2021-05-17 23:56:39 INFO      pycloudlib.instance:instance.py:165 executing: sudo -- sh -c 'cloud-init analyze blame'
Installing proposed image
2021-05-17 23:56:39 INFO      integration_testing:instances.py:144 Installing proposed image
2021-05-17 23:56:39 INFO      pycloudlib.instance:instance.py:165 executing: sudo -- sh -c 'echo deb "http://archive.ubuntu.com/ubuntu $(lsb_release -sc)-proposed main" | tee /etc/apt/sources.list.d/proposed.list
apt-get update -q
apt-get install -qy cloud-init'
2021-05-17 23:56:54 INFO      pycloudlib.instance:instance.py:165 executing: sudo -- sh -c 'cloud-init -v'
Installed cloud-init version: 21.2-3-g899bfaa9-0ubuntu2~18.04.1
2021-05-17 23:56:54 INFO      integration_testing:instances.py:136 Installed cloud-init version: 21.2-3-g899bfaa9-0ubuntu2~18.04.1
2021-05-17 23:56:54 INFO      pycloudlib.instance:instance.py:165 executing: sh -c 'sudo cloud-init clean --logs'
2021-05-17 23:56:55 INFO      pycloudlib.instance:instance.py:165 executing: sh -c 'sudo rm -rf /var/log/syslog'
2021-05-17 23:56:55 INFO      pycloudlib.instance:instance.py:165 executing: sudo -- sh -c 'hostname something-else'
Restarting instance and waiting for boot
2021-05-17 23:56:55 INFO      integration_testing:instances.py:65 Restarting instance and waiting for boot
2021-05-17 23:56:55 INFO      pycloudlib.instance:instance.py:165 executing: sh -c 'cat /proc/sys/kernel/random/boot_id'
2021-05-17 23:57:01 INFO      pycloudlib.instance:instance.py:165 executing: sh -c 'cat /proc/sys/kernel/random/boot_id'
2021-05-17 23:57:01 INFO      pycloudlib.instance:instance.py:343 [Errno None] Unable to connect to port 22 on 3.14.1.108
Retrying SSH connection to ubuntu@3.14.1.108:22 (599s left)
2021-05-17 23:57:03 INFO      pycloudlib.instance:instance.py:343 [Errno None] Unable to connect to port 22 on 3.14.1.108
Retrying SSH connection to ubuntu@3.14.1.108:22 (598s left)
2021-05-17 23:57:04 INFO      pycloudlib.instance:instance.py:343 [Errno None] Unable to connect to port 22 on 3.14.1.108
Retrying SSH connection to ubuntu@3.14.1.108:22 (597s left)
2021-05-17 23:58:05 INFO      pycloudlib.instance:instance.py:343 timed out
Retrying SSH connection to ubuntu@3.14.1.108:22 (535s left)
2021-05-17 23:58:06 INFO      paramiko.transport:transport.py:1819 Connected (version 2.0, client OpenSSH_7.6p1)
2021-05-17 23:58:07 INFO      paramiko.transport:transport.py:1819 Authentication (publickey) successful!
2021-05-17 23:58:08 INFO      pycloudlib.instance:instance.py:165 executing: sh -c whoami
2021-05-17 23:58:08 INFO      pycloudlib.instance:instance.py:165 executing: cloud-init status --wait --long
2021-05-17 23:58:09 INFO      pycloudlib.instance:instance.py:165 executing: sh -c 'cat /proc/sys/kernel/random/boot_id'
2021-05-17 23:58:09 INFO      pycloudlib.instance:instance.py:165 executing: sudo -- sh -c 'cloud-init status --wait --long'
2021-05-17 23:58:09 INFO      pycloudlib.instance:instance.py:165 executing: sudo -- sh -c 'cloud-init status --wait --long'
2021-05-17 23:58:10 INFO      pycloudlib.instance:instance.py:165 executing: sudo -- sh -c hostname
2021-05-17 23:58:10 INFO      pycloudlib.instance:instance.py:165 executing: sudo -- sh -c 'dpkg-query --show cloud-init'
2021-05-17 23:58:10 INFO      pycloudlib.instance:instance.py:165 executing: sudo -- sh -c 'cat /run/cloud-init/result.json'
2021-05-17 23:58:10 INFO      pycloudlib.instance:instance.py:165 executing: sudo -- sh -c 'cloud-init init'
2021-05-17 23:58:11 INFO      pycloudlib.instance:instance.py:165 executing: sudo -- sh -c 'grep Trace /var/log/cloud-init.log'
2021-05-17 23:58:11 INFO      pycloudlib.instance:instance.py:165 executing: sudo -- sh -c cloud-id
2021-05-17 23:58:12 INFO      pycloudlib.instance:instance.py:165 executing: sudo -- sh -c 'cat /etc/netplan/50-cloud-init.yaml'
2021-05-17 23:58:12 INFO      pycloudlib.instance:instance.py:165 executing: sudo -- sh -c systemd-analyze
2021-05-17 23:58:12 INFO      pycloudlib.instance:instance.py:165 executing: sudo -- sh -c 'systemd-analyze blame'
2021-05-17 23:58:12 INFO      pycloudlib.instance:instance.py:165 executing: sudo -- sh -c 'cloud-init analyze show'
2021-05-17 23:58:13 INFO      pycloudlib.instance:instance.py:165 executing: sudo -- sh -c 'cloud-init analyze blame'
Wrote upgrade test logs to /home/james/tmp_home/cloud_init_test_logs/test_upgrade_ec2_bionic_before_210517185000.log and /home/james/tmp_home/cloud_init_test_logs/test_upgrade_ec2_bionic_after_210517185000.log
2021-05-17 23:58:44 INFO      integration_testing:test_upgrade.py:102 Wrote upgrade test logs to /home/james/tmp_home/cloud_init_test_logs/test_upgrade_ec2_bionic_before_210517185000.log and /home/james/tmp_home/cloud_init_test_logs/test_upgrade_ec2_bionic_after_210517185000.log
PASSED

==== Focal ====
-------------------------------- live log setup --------------------------------
2021-05-18 09:18:53 INFO      integration_testing:clouds.py:88 Detected image: image_id=focal os=ubuntu release=focal
Detected image: image_id=focal os=ubuntu release=focal
-------------------------------- live log call ---------------------------------
2021-05-18 09:18:53 INFO      integration_testing:clouds.py:88 Detected image: image_id=focal os=ubuntu release=focal
Launching instance with launch_kwargs:
image_id=ami-0f76aec439103b9fd
user_data=#cloud-config
hostname: SRU-worked

2021-05-18 09:18:53 INFO      integration_testing:clouds.py:168 Launching instance with launch_kwargs:
image_id=ami-0f76aec439103b9fd
user_data=#cloud-config
hostname: SRU-worked

2021-05-18 09:18:55 INFO      paramiko.transport.sftp:sftp.py:158 [chan 8] sftp session closed.
2021-05-18 09:19:25 INFO      pycloudlib.instance:instance.py:165 executing: sh -c whoami
2021-05-18 09:19:32 INFO      pycloudlib.instance:instance.py:343 [Errno None] Unable to connect to port 22 on 18.188.122.16
Retrying SSH connection to ubuntu@18.188.122.16:22 (592s left)
2021-05-18 09:19:34 INFO      pycloudlib.instance:instance.py:343 [Errno None] Unable to connect to port 22 on 18.188.122.16
Retrying SSH connection to ubuntu@18.188.122.16:22 (591s left)
2021-05-18 09:19:35 INFO      paramiko.transport:transport.py:1819 Connected (version 2.0, client OpenSSH_8.2p1)
2021-05-18 09:19:35 INFO      paramiko.transport:transport.py:1819 Authentication (publickey) successful!
2021-05-18 09:19:38 INFO      pycloudlib.instance:instance.py:165 executing: cloud-init status --wait --long
Launched instance: EC2Instance(key_pair=KeyPair(/home/james/.ssh/id_rsa, /home/james/.ssh/id_rsa.pub, name=james), client=<botocore.client.EC2 object at 0x7f5c1e129b38>, instance=ec2.Instance(id='i-05f70563ae6c12bdb'))
2021-05-18 09:19:46 INFO      integration_testing:clouds.py:173 Launched instance: EC2Instance(key_pair=KeyPair(/home/james/.ssh/id_rsa, /home/james/.ssh/id_rsa.pub, name=james), client=<botocore.client.EC2 object at 0x7f5c1e129b38>, instance=ec2.Instance(id='i-05f70563ae6c12bdb'))
2021-05-18 09:19:46 INFO      pycloudlib.instance:instance.py:165 executing: sudo -- sh -c 'cloud-init --version'
cloud-init version: /usr/bin/cloud-init 21.1-19-gbad84ad4-0ubuntu1~20.04.2
2021-05-18 09:19:47 INFO      integration_testing:clouds.py:179 cloud-init version: /usr/bin/cloud-init 21.1-19-gbad84ad4-0ubuntu1~20.04.2
2021-05-18 09:19:47 INFO      pycloudlib.instance:instance.py:165 executing: sudo -- sh -c 'grep serial /etc/cloud/build.info'
image serial: 20210511
2021-05-18 09:19:47 INFO      integration_testing:clouds.py:183 image serial: 20210511
2021-05-18 09:19:47 INFO      pycloudlib.instance:instance.py:165 executing: sudo -- sh -c hostname
2021-05-18 09:19:47 INFO      pycloudlib.instance:instance.py:165 executing: sudo -- sh -c 'dpkg-query --show cloud-init'
2021-05-18 09:19:47 INFO      pycloudlib.instance:instance.py:165 executing: sudo -- sh -c 'cat /run/cloud-init/result.json'
2021-05-18 09:19:47 INFO      pycloudlib.instance:instance.py:165 executing: sudo -- sh -c 'cloud-init init'
2021-05-18 09:19:48 INFO      pycloudlib.instance:instance.py:165 executing: sudo -- sh -c 'grep Trace /var/log/cloud-init.log'
2021-05-18 09:19:48 INFO      pycloudlib.instance:instance.py:165 executing: sudo -- sh -c cloud-id
2021-05-18 09:19:48 INFO      pycloudlib.instance:instance.py:165 executing: sudo -- sh -c 'cat /etc/netplan/50-cloud-init.yaml'
2021-05-18 09:19:48 INFO      pycloudlib.instance:instance.py:165 executing: sudo -- sh -c systemd-analyze
2021-05-18 09:19:49 INFO      pycloudlib.instance:instance.py:165 executing: sudo -- sh -c 'systemd-analyze blame'
2021-05-18 09:19:49 INFO      pycloudlib.instance:instance.py:165 executing: sudo -- sh -c 'cloud-init analyze show'
2021-05-18 09:19:50 INFO      pycloudlib.instance:instance.py:165 executing: sudo -- sh -c 'cloud-init analyze blame'
Installing proposed image
2021-05-18 09:19:50 INFO      integration_testing:instances.py:144 Installing proposed image
2021-05-18 09:19:50 INFO      pycloudlib.instance:instance.py:165 executing: sudo -- sh -c 'echo deb "http://archive.ubuntu.com/ubuntu $(lsb_release -sc)-proposed main" | tee /etc/apt/sources.list.d/proposed.list
apt-get update -q
apt-get install -qy cloud-init'
2021-05-18 09:20:10 INFO      pycloudlib.instance:instance.py:165 executing: sudo -- sh -c 'cloud-init -v'
Installed cloud-init version: 21.2-3-g899bfaa9-0ubuntu2~20.04.1
2021-05-18 09:20:11 INFO      integration_testing:instances.py:136 Installed cloud-init version: 21.2-3-g899bfaa9-0ubuntu2~20.04.1
2021-05-18 09:20:11 INFO      pycloudlib.instance:instance.py:165 executing: sh -c 'sudo cloud-init clean --logs'
2021-05-18 09:20:11 INFO      pycloudlib.instance:instance.py:165 executing: sh -c 'sudo rm -rf /var/log/syslog'
2021-05-18 09:20:11 INFO      pycloudlib.instance:instance.py:165 executing: sudo -- sh -c 'hostname something-else'
Restarting instance and waiting for boot
2021-05-18 09:20:11 INFO      integration_testing:instances.py:65 Restarting instance and waiting for boot
2021-05-18 09:20:11 INFO      pycloudlib.instance:instance.py:165 executing: sh -c 'cat /proc/sys/kernel/random/boot_id'
2021-05-18 09:20:17 INFO      pycloudlib.instance:instance.py:165 executing: sh -c 'cat /proc/sys/kernel/random/boot_id'
2021-05-18 09:20:17 INFO      pycloudlib.instance:instance.py:343 [Errno None] Unable to connect to port 22 on 18.188.122.16
Retrying SSH connection to ubuntu@18.188.122.16:22 (599s left)
2021-05-18 09:20:18 INFO      pycloudlib.instance:instance.py:343 [Errno None] Unable to connect to port 22 on 18.188.122.16
Retrying SSH connection to ubuntu@18.188.122.16:22 (598s left)
2021-05-18 09:20:19 INFO      pycloudlib.instance:instance.py:343 [Errno None] Unable to connect to port 22 on 18.188.122.16
Retrying SSH connection to ubuntu@18.188.122.16:22 (597s left)
2021-05-18 09:20:20 INFO      pycloudlib.instance:instance.py:343 [Errno None] Unable to connect to port 22 on 18.188.122.16
Retrying SSH connection to ubuntu@18.188.122.16:22 (596s left)
2021-05-18 09:21:22 INFO      pycloudlib.instance:instance.py:343 timed out
Retrying SSH connection to ubuntu@18.188.122.16:22 (535s left)
2021-05-18 09:21:23 INFO      paramiko.transport:transport.py:1819 Connected (version 2.0, client OpenSSH_8.2p1)
2021-05-18 09:21:23 INFO      paramiko.transport:transport.py:1819 Authentication (publickey) successful!
2021-05-18 09:21:24 INFO      pycloudlib.instance:instance.py:165 executing: sh -c whoami
2021-05-18 09:21:24 INFO      pycloudlib.instance:instance.py:165 executing: cloud-init status --wait --long
2021-05-18 09:21:24 INFO      pycloudlib.instance:instance.py:165 executing: sh -c 'cat /proc/sys/kernel/random/boot_id'
2021-05-18 09:21:24 INFO      pycloudlib.instance:instance.py:165 executing: sudo -- sh -c 'cloud-init status --wait --long'
2021-05-18 09:21:25 INFO      pycloudlib.instance:instance.py:165 executing: sudo -- sh -c 'cloud-init status --wait --long'
2021-05-18 09:21:25 INFO      pycloudlib.instance:instance.py:165 executing: sudo -- sh -c hostname
2021-05-18 09:21:25 INFO      pycloudlib.instance:instance.py:165 executing: sudo -- sh -c 'dpkg-query --show cloud-init'
2021-05-18 09:21:26 INFO      pycloudlib.instance:instance.py:165 executing: sudo -- sh -c 'cat /run/cloud-init/result.json'
2021-05-18 09:21:26 INFO      pycloudlib.instance:instance.py:165 executing: sudo -- sh -c 'cloud-init init'
2021-05-18 09:21:26 INFO      pycloudlib.instance:instance.py:165 executing: sudo -- sh -c 'grep Trace /var/log/cloud-init.log'
2021-05-18 09:21:26 INFO      pycloudlib.instance:instance.py:165 executing: sudo -- sh -c cloud-id
2021-05-18 09:21:27 INFO      pycloudlib.instance:instance.py:165 executing: sudo -- sh -c 'cat /etc/netplan/50-cloud-init.yaml'
2021-05-18 09:21:27 INFO      pycloudlib.instance:instance.py:165 executing: sudo -- sh -c systemd-analyze
2021-05-18 09:21:27 INFO      pycloudlib.instance:instance.py:165 executing: sudo -- sh -c 'systemd-analyze blame'
2021-05-18 09:21:28 INFO      pycloudlib.instance:instance.py:165 executing: sudo -- sh -c 'cloud-init analyze show'
2021-05-18 09:21:28 INFO      pycloudlib.instance:instance.py:165 executing: sudo -- sh -c 'cloud-init analyze blame'
Wrote upgrade test logs to /home/james/tmp_home/cloud_init_test_logs/test_upgrade_ec2_focal_before_210518041255.log and /home/james/tmp_home/cloud_init_test_logs/test_upgrade_ec2_focal_after_210518041255.log
2021-05-18 09:22:14 INFO      integration_testing:test_upgrade.py:102 Wrote upgrade test logs to /home/james/tmp_home/cloud_init_test_logs/test_upgrade_ec2_focal_before_210518041255.log and /home/james/tmp_home/cloud_init_test_logs/test_upgrade_ec2_focal_after_210518041255.log
PASSED


==== Groovy ====
-------------------------------- live log setup --------------------------------
2021-05-19 04:36:22 INFO      integration_testing:clouds.py:88 Detected image: image_id=groovy os=ubuntu release=groovy
Detected image: image_id=groovy os=ubuntu release=groovy
-------------------------------- live log call ---------------------------------
2021-05-19 04:36:22 INFO      integration_testing:clouds.py:88 Detected image: image_id=groovy os=ubuntu release=groovy
Launching instance with launch_kwargs:
user_data=#cloud-config
hostname: SRU-worked

image_id=ami-0dcb447bd4d93a513
2021-05-19 04:36:22 INFO      integration_testing:clouds.py:168 Launching instance with launch_kwargs:
user_data=#cloud-config
hostname: SRU-worked

image_id=ami-0dcb447bd4d93a513
2021-05-19 04:36:24 INFO      paramiko.transport.sftp:sftp.py:158 [chan 8] sftp session closed.
2021-05-19 04:36:54 INFO      pycloudlib.instance:instance.py:165 executing: sh -c whoami
2021-05-19 04:36:55 INFO      paramiko.transport:transport.py:1819 Connected (version 2.0, client OpenSSH_8.3p1)
2021-05-19 04:36:55 INFO      paramiko.transport:transport.py:1819 Authentication (publickey) successful!
2021-05-19 04:36:56 INFO      pycloudlib.instance:instance.py:165 executing: cloud-init status --wait --long
Launched instance: EC2Instance(key_pair=KeyPair(/home/james/.ssh/id_rsa, /home/james/.ssh/id_rsa.pub, name=james), client=<botocore.client.EC2 object at 0x7f56c994bbe0>, instance=ec2.Instance(id='i-0795e6400a33033a1'))
2021-05-19 04:37:01 INFO      integration_testing:clouds.py:173 Launched instance: EC2Instance(key_pair=KeyPair(/home/james/.ssh/id_rsa, /home/james/.ssh/id_rsa.pub, name=james), client=<botocore.client.EC2 object at 0x7f56c994bbe0>, instance=ec2.Instance(id='i-0795e6400a33033a1'))
2021-05-19 04:37:01 INFO      pycloudlib.instance:instance.py:165 executing: sudo -- sh -c 'cloud-init --version'
cloud-init version: /usr/bin/cloud-init 21.1-19-gbad84ad4-0ubuntu1~20.10.2
2021-05-19 04:37:01 INFO      integration_testing:clouds.py:179 cloud-init version: /usr/bin/cloud-init 21.1-19-gbad84ad4-0ubuntu1~20.10.2
2021-05-19 04:37:01 INFO      pycloudlib.instance:instance.py:165 executing: sudo -- sh -c 'grep serial /etc/cloud/build.info'
image serial: 20210517
2021-05-19 04:37:01 INFO      integration_testing:clouds.py:183 image serial: 20210517
2021-05-19 04:37:01 INFO      pycloudlib.instance:instance.py:165 executing: sudo -- sh -c hostname
2021-05-19 04:37:02 INFO      pycloudlib.instance:instance.py:165 executing: sudo -- sh -c 'dpkg-query --show cloud-init'
2021-05-19 04:37:02 INFO      pycloudlib.instance:instance.py:165 executing: sudo -- sh -c 'cat /run/cloud-init/result.json'
2021-05-19 04:37:02 INFO      pycloudlib.instance:instance.py:165 executing: sudo -- sh -c 'cloud-init init'
2021-05-19 04:37:02 INFO      pycloudlib.instance:instance.py:165 executing: sudo -- sh -c 'grep Trace /var/log/cloud-init.log'
2021-05-19 04:37:03 INFO      pycloudlib.instance:instance.py:165 executing: sudo -- sh -c cloud-id
2021-05-19 04:37:03 INFO      pycloudlib.instance:instance.py:165 executing: sudo -- sh -c 'cat /etc/netplan/50-cloud-init.yaml'
2021-05-19 04:37:03 INFO      pycloudlib.instance:instance.py:165 executing: sudo -- sh -c systemd-analyze
2021-05-19 04:37:03 INFO      pycloudlib.instance:instance.py:165 executing: sudo -- sh -c 'systemd-analyze blame'
2021-05-19 04:37:04 INFO      pycloudlib.instance:instance.py:165 executing: sudo -- sh -c 'cloud-init analyze show'
2021-05-19 04:37:05 INFO      pycloudlib.instance:instance.py:165 executing: sudo -- sh -c 'cloud-init analyze blame'
Installing proposed image
2021-05-19 04:37:05 INFO      integration_testing:instances.py:144 Installing proposed image
2021-05-19 04:37:05 INFO      pycloudlib.instance:instance.py:165 executing: sudo -- sh -c 'echo deb "http://archive.ubuntu.com/ubuntu $(lsb_release -sc)-proposed main" | tee /etc/apt/sources.list.d/proposed.list
apt-get update -q
apt-get install -qy cloud-init'
2021-05-19 04:37:25 INFO      pycloudlib.instance:instance.py:165 executing: sudo -- sh -c 'cloud-init -v'
Installed cloud-init version: 21.2-3-g899bfaa9-0ubuntu2~20.10.1
2021-05-19 04:37:25 INFO      integration_testing:instances.py:136 Installed cloud-init version: 21.2-3-g899bfaa9-0ubuntu2~20.10.1
2021-05-19 04:37:25 INFO      pycloudlib.instance:instance.py:165 executing: sh -c 'sudo cloud-init clean --logs'
2021-05-19 04:37:26 INFO      pycloudlib.instance:instance.py:165 executing: sh -c 'sudo rm -rf /var/log/syslog'
2021-05-19 04:37:26 INFO      pycloudlib.instance:instance.py:165 executing: sudo -- sh -c 'hostname something-else'
Restarting instance and waiting for boot
2021-05-19 04:37:26 INFO      integration_testing:instances.py:65 Restarting instance and waiting for boot
2021-05-19 04:37:26 INFO      pycloudlib.instance:instance.py:165 executing: sh -c 'cat /proc/sys/kernel/random/boot_id'
2021-05-19 04:37:31 INFO      pycloudlib.instance:instance.py:165 executing: sh -c 'cat /proc/sys/kernel/random/boot_id'
2021-05-19 04:37:31 INFO      pycloudlib.instance:instance.py:343 [Errno None] Unable to connect to port 22 on 18.191.211.121
Retrying SSH connection to ubuntu@18.191.211.121:22 (599s left)
2021-05-19 04:37:33 INFO      pycloudlib.instance:instance.py:343 [Errno None] Unable to connect to port 22 on 18.191.211.121
Retrying SSH connection to ubuntu@18.191.211.121:22 (598s left)
2021-05-19 04:37:34 INFO      pycloudlib.instance:instance.py:343 [Errno None] Unable to connect to port 22 on 18.191.211.121
Retrying SSH connection to ubuntu@18.191.211.121:22 (597s left)
2021-05-19 04:37:35 INFO      pycloudlib.instance:instance.py:343 [Errno None] Unable to connect to port 22 on 18.191.211.121
Retrying SSH connection to ubuntu@18.191.211.121:22 (596s left)
2021-05-19 04:38:08 INFO      pycloudlib.instance:instance.py:343 [Errno None] Unable to connect to port 22 on 18.191.211.121
Retrying SSH connection to ubuntu@18.191.211.121:22 (563s left)
2021-05-19 04:38:09 INFO      pycloudlib.instance:instance.py:343 [Errno None] Unable to connect to port 22 on 18.191.211.121
Retrying SSH connection to ubuntu@18.191.211.121:22 (562s left)
2021-05-19 04:38:10 INFO      pycloudlib.instance:instance.py:343 [Errno None] Unable to connect to port 22 on 18.191.211.121
Retrying SSH connection to ubuntu@18.191.211.121:22 (560s left)
2021-05-19 04:38:11 INFO      paramiko.transport:transport.py:1819 Connected (version 2.0, client OpenSSH_8.3p1)
2021-05-19 04:38:12 INFO      paramiko.transport:transport.py:1819 Authentication (publickey) successful!
2021-05-19 04:38:15 INFO      pycloudlib.instance:instance.py:165 executing: sh -c whoami
2021-05-19 04:38:15 INFO      pycloudlib.instance:instance.py:165 executing: cloud-init status --wait --long
2021-05-19 04:38:19 INFO      pycloudlib.instance:instance.py:165 executing: sh -c 'cat /proc/sys/kernel/random/boot_id'
2021-05-19 04:38:19 INFO      pycloudlib.instance:instance.py:165 executing: sudo -- sh -c 'cloud-init status --wait --long'
2021-05-19 04:38:20 INFO      pycloudlib.instance:instance.py:165 executing: sudo -- sh -c 'cloud-init status --wait --long'
2021-05-19 04:38:21 INFO      pycloudlib.instance:instance.py:165 executing: sudo -- sh -c hostname
2021-05-19 04:38:21 INFO      pycloudlib.instance:instance.py:165 executing: sudo -- sh -c 'dpkg-query --show cloud-init'
2021-05-19 04:38:21 INFO      pycloudlib.instance:instance.py:165 executing: sudo -- sh -c 'cat /run/cloud-init/result.json'
2021-05-19 04:38:21 INFO      pycloudlib.instance:instance.py:165 executing: sudo -- sh -c 'cloud-init init'
2021-05-19 04:38:22 INFO      pycloudlib.instance:instance.py:165 executing: sudo -- sh -c 'grep Trace /var/log/cloud-init.log'
2021-05-19 04:38:22 INFO      pycloudlib.instance:instance.py:165 executing: sudo -- sh -c cloud-id
2021-05-19 04:38:22 INFO      pycloudlib.instance:instance.py:165 executing: sudo -- sh -c 'cat /etc/netplan/50-cloud-init.yaml'
2021-05-19 04:38:22 INFO      pycloudlib.instance:instance.py:165 executing: sudo -- sh -c systemd-analyze
2021-05-19 04:38:22 INFO      pycloudlib.instance:instance.py:165 executing: sudo -- sh -c 'systemd-analyze blame'
2021-05-19 04:38:23 INFO      pycloudlib.instance:instance.py:165 executing: sudo -- sh -c 'cloud-init analyze show'
2021-05-19 04:38:23 INFO      pycloudlib.instance:instance.py:165 executing: sudo -- sh -c 'cloud-init analyze blame'
Wrote upgrade test logs to /home/james/tmp_home/cloud_init_test_logs/test_upgrade_ec2_groovy_before_210518233008.log and /home/james/tmp_home/cloud_init_test_logs/test_upgrade_ec2_groovy_after_210518233008.log
2021-05-19 04:39:09 INFO      integration_testing:test_upgrade.py:102 Wrote upgrade test logs to /home/james/tmp_home/cloud_init_test_logs/test_upgrade_ec2_groovy_before_210518233008.log and /home/james/tmp_home/cloud_init_test_logs/test_upgrade_ec2_groovy_after_210518233008.log
PASSED


==== Hirsute ====
-------------------------------- live log setup --------------------------------
2021-05-19 10:20:18 INFO      integration_testing:clouds.py:88 Detected image: image_id=hirsute os=ubuntu release=hirsute
Detected image: image_id=hirsute os=ubuntu release=hirsute
-------------------------------- live log call ---------------------------------
2021-05-19 10:20:18 INFO      integration_testing:clouds.py:88 Detected image: image_id=hirsute os=ubuntu release=hirsute
Launching instance with launch_kwargs:
user_data=#cloud-config
hostname: SRU-worked

image_id=ami-0226ca4ef0595249d
2021-05-19 10:20:18 INFO      integration_testing:clouds.py:168 Launching instance with launch_kwargs:
user_data=#cloud-config
hostname: SRU-worked

image_id=ami-0226ca4ef0595249d
2021-05-19 10:20:50 INFO      pycloudlib.instance:instance.py:165 executing: sh -c whoami
2021-05-19 10:21:05 INFO      pycloudlib.instance:instance.py:343 [Errno None] Unable to connect to port 22 on 13.59.164.154
Retrying SSH connection to ubuntu@13.59.164.154:22 (584s left)
2021-05-19 10:21:06 INFO      pycloudlib.instance:instance.py:343 [Errno None] Unable to connect to port 22 on 13.59.164.154
Retrying SSH connection to ubuntu@13.59.164.154:22 (583s left)
2021-05-19 10:21:07 INFO      paramiko.transport:transport.py:1819 Connected (version 2.0, client OpenSSH_8.4p1)
2021-05-19 10:21:08 INFO      paramiko.transport:transport.py:1819 Authentication (publickey) successful!
2021-05-19 10:21:10 INFO      pycloudlib.instance:instance.py:165 executing: cloud-init status --wait --long
Launched instance: EC2Instance(key_pair=KeyPair(/home/james/.ssh/id_rsa, /home/james/.ssh/id_rsa.pub, name=james), client=<botocore.client.EC2 object at 0x7f2b33f86b70>, instance=ec2.Instance(id='i-07286eef15112287e'))
2021-05-19 10:21:16 INFO      integration_testing:clouds.py:173 Launched instance: EC2Instance(key_pair=KeyPair(/home/james/.ssh/id_rsa, /home/james/.ssh/id_rsa.pub, name=james), client=<botocore.client.EC2 object at 0x7f2b33f86b70>, instance=ec2.Instance(id='i-07286eef15112287e'))
2021-05-19 10:21:16 INFO      pycloudlib.instance:instance.py:165 executing: sudo -- sh -c 'cloud-init --version'
cloud-init version: /usr/bin/cloud-init 21.1-19-gbad84ad4-0ubuntu3
2021-05-19 10:21:16 INFO      integration_testing:clouds.py:179 cloud-init version: /usr/bin/cloud-init 21.1-19-gbad84ad4-0ubuntu3
2021-05-19 10:21:16 INFO      pycloudlib.instance:instance.py:165 executing: sudo -- sh -c 'grep serial /etc/cloud/build.info'
image serial: 20210511.1
2021-05-19 10:21:17 INFO      integration_testing:clouds.py:183 image serial: 20210511.1
2021-05-19 10:21:17 INFO      pycloudlib.instance:instance.py:165 executing: sudo -- sh -c hostname
2021-05-19 10:21:17 INFO      pycloudlib.instance:instance.py:165 executing: sudo -- sh -c 'dpkg-query --show cloud-init'
2021-05-19 10:21:17 INFO      pycloudlib.instance:instance.py:165 executing: sudo -- sh -c 'cat /run/cloud-init/result.json'
2021-05-19 10:21:17 INFO      pycloudlib.instance:instance.py:165 executing: sudo -- sh -c 'cloud-init init'
2021-05-19 10:21:18 INFO      pycloudlib.instance:instance.py:165 executing: sudo -- sh -c 'grep Trace /var/log/cloud-init.log'
2021-05-19 10:21:18 INFO      pycloudlib.instance:instance.py:165 executing: sudo -- sh -c cloud-id
2021-05-19 10:21:18 INFO      pycloudlib.instance:instance.py:165 executing: sudo -- sh -c 'cat /etc/netplan/50-cloud-init.yaml'
2021-05-19 10:21:18 INFO      pycloudlib.instance:instance.py:165 executing: sudo -- sh -c systemd-analyze
2021-05-19 10:21:18 INFO      pycloudlib.instance:instance.py:165 executing: sudo -- sh -c 'systemd-analyze blame'
2021-05-19 10:21:19 INFO      pycloudlib.instance:instance.py:165 executing: sudo -- sh -c 'cloud-init analyze show'
2021-05-19 10:21:20 INFO      pycloudlib.instance:instance.py:165 executing: sudo -- sh -c 'cloud-init analyze blame'
Installing proposed image
2021-05-19 10:21:20 INFO      integration_testing:instances.py:144 Installing proposed image
2021-05-19 10:21:20 INFO      pycloudlib.instance:instance.py:165 executing: sudo -- sh -c 'echo deb "http://archive.ubuntu.com/ubuntu $(lsb_release -sc)-proposed main" | tee /etc/apt/sources.list.d/proposed.list
apt-get update -q
apt-get install -qy cloud-init'
2021-05-19 10:21:37 INFO      pycloudlib.instance:instance.py:165 executing: sudo -- sh -c 'cloud-init -v'
Installed cloud-init version: 21.2-3-g899bfaa9-0ubuntu2~21.04.1
2021-05-19 10:21:38 INFO      integration_testing:instances.py:136 Installed cloud-init version: 21.2-3-g899bfaa9-0ubuntu2~21.04.1
2021-05-19 10:21:38 INFO      pycloudlib.instance:instance.py:165 executing: sh -c 'sudo cloud-init clean --logs'
2021-05-19 10:21:38 INFO      pycloudlib.instance:instance.py:165 executing: sh -c 'sudo rm -rf /var/log/syslog'
2021-05-19 10:21:39 INFO      pycloudlib.instance:instance.py:165 executing: sudo -- sh -c 'hostname something-else'
Restarting instance and waiting for boot
2021-05-19 10:21:39 INFO      integration_testing:instances.py:65 Restarting instance and waiting for boot
2021-05-19 10:21:39 INFO      pycloudlib.instance:instance.py:165 executing: sh -c 'cat /proc/sys/kernel/random/boot_id'
2021-05-19 10:21:44 INFO      pycloudlib.instance:instance.py:165 executing: sh -c 'cat /proc/sys/kernel/random/boot_id'
2021-05-19 10:21:44 INFO      pycloudlib.instance:instance.py:343 [Errno None] Unable to connect to port 22 on 13.59.164.154
Retrying SSH connection to ubuntu@13.59.164.154:22 (599s left)
2021-05-19 10:21:45 INFO      pycloudlib.instance:instance.py:343 [Errno None] Unable to connect to port 22 on 13.59.164.154
Retrying SSH connection to ubuntu@13.59.164.154:22 (598s left)
2021-05-19 10:21:46 INFO      pycloudlib.instance:instance.py:343 [Errno None] Unable to connect to port 22 on 13.59.164.154
Retrying SSH connection to ubuntu@13.59.164.154:22 (597s left)
2021-05-19 10:22:48 INFO      pycloudlib.instance:instance.py:343 timed out
Retrying SSH connection to ubuntu@13.59.164.154:22 (536s left)
2021-05-19 10:22:49 INFO      paramiko.transport:transport.py:1819 Connected (version 2.0, client OpenSSH_8.4p1)
2021-05-19 10:22:49 INFO      paramiko.transport:transport.py:1819 Authentication (publickey) successful!
2021-05-19 10:22:50 INFO      pycloudlib.instance:instance.py:165 executing: sh -c whoami
2021-05-19 10:22:50 INFO      pycloudlib.instance:instance.py:165 executing: cloud-init status --wait --long
2021-05-19 10:22:51 INFO      pycloudlib.instance:instance.py:165 executing: sh -c 'cat /proc/sys/kernel/random/boot_id'
2021-05-19 10:22:51 INFO      pycloudlib.instance:instance.py:165 executing: sudo -- sh -c 'cloud-init status --wait --long'
2021-05-19 10:22:51 INFO      pycloudlib.instance:instance.py:165 executing: sudo -- sh -c 'cloud-init status --wait --long'
2021-05-19 10:22:52 INFO      pycloudlib.instance:instance.py:165 executing: sudo -- sh -c hostname
2021-05-19 10:22:52 INFO      pycloudlib.instance:instance.py:165 executing: sudo -- sh -c 'dpkg-query --show cloud-init'
2021-05-19 10:22:52 INFO      pycloudlib.instance:instance.py:165 executing: sudo -- sh -c 'cat /run/cloud-init/result.json'
2021-05-19 10:22:52 INFO      pycloudlib.instance:instance.py:165 executing: sudo -- sh -c 'cloud-init init'
2021-05-19 10:22:53 INFO      pycloudlib.instance:instance.py:165 executing: sudo -- sh -c 'grep Trace /var/log/cloud-init.log'
2021-05-19 10:22:53 INFO      pycloudlib.instance:instance.py:165 executing: sudo -- sh -c cloud-id
2021-05-19 10:22:53 INFO      pycloudlib.instance:instance.py:165 executing: sudo -- sh -c 'cat /etc/netplan/50-cloud-init.yaml'
2021-05-19 10:22:53 INFO      pycloudlib.instance:instance.py:165 executing: sudo -- sh -c systemd-analyze
2021-05-19 10:22:53 INFO      pycloudlib.instance:instance.py:165 executing: sudo -- sh -c 'systemd-analyze blame'
2021-05-19 10:22:54 INFO      pycloudlib.instance:instance.py:165 executing: sudo -- sh -c 'cloud-init analyze show'
2021-05-19 10:22:54 INFO      pycloudlib.instance:instance.py:165 executing: sudo -- sh -c 'cloud-init analyze blame'
Wrote upgrade test logs to /home/james/tmp_home/cloud_init_test_logs/test_upgrade_ec2_hirsute_before_210519051324.log and /home/james/tmp_home/cloud_init_test_logs/test_upgrade_ec2_hirsute_after_210519051324.log
2021-05-19 10:23:40 INFO      integration_testing:test_upgrade.py:102 Wrote upgrade test logs to /home/james/tmp_home/cloud_init_test_logs/test_upgrade_ec2_hirsute_before_210519051324.log and /home/james/tmp_home/cloud_init_test_logs/test_upgrade_ec2_hirsute_after_210519051324.log
PASSED
