Upstream test at:
https://github.com/canonical/cloud-init/blob/master/tests/integration_tests/test_upgrade.py

Logs from individual before/after runs in gce-sru-21.2-3 subdirectory

==== Bionic ====
-------------------------------- live log setup --------------------------------
2021-05-18 01:23:30 INFO      integration_testing:clouds.py:88 Detected image: image_id=bionic os=ubuntu release=bionic
Detected image: image_id=bionic os=ubuntu release=bionic
-------------------------------- live log call ---------------------------------
2021-05-18 01:23:30 INFO      integration_testing:clouds.py:88 Detected image: image_id=bionic os=ubuntu release=bionic
Launching instance with launch_kwargs:
user_data=#cloud-config
hostname: SRU-worked

image_id=projects/ubuntu-os-cloud-devel/global/images/daily-ubuntu-1804-bionic-v20210504
2021-05-18 01:23:30 INFO      integration_testing:clouds.py:168 Launching instance with launch_kwargs:
user_data=#cloud-config
hostname: SRU-worked

image_id=projects/ubuntu-os-cloud-devel/global/images/daily-ubuntu-1804-bionic-v20210504
2021-05-18 01:23:32 WARNING   google.auth._default:_default.py:352 No project ID could be determined. Consider running `gcloud config set project` or setting the GOOGLE_CLOUD_PROJECT environment variable
2021-05-18 01:23:42 INFO      pycloudlib.instance:instance.py:165 executing: sh -c whoami
2021-05-18 01:24:14 INFO      pycloudlib.instance:instance.py:343 [Errno None] Unable to connect to port 22 on 34.94.54.202
Retrying SSH connection to ubuntu@34.94.54.202:22 (568s left)
2021-05-18 01:24:15 INFO      paramiko.transport:transport.py:1819 Connected (version 2.0, client OpenSSH_7.6p1)
2021-05-18 01:24:15 INFO      paramiko.transport:transport.py:1819 Authentication (publickey) successful!
2021-05-18 01:24:20 INFO      pycloudlib.instance:instance.py:165 executing: cloud-init status --wait --long
Launched instance: GceInstance(instance_id=9202198169101707773)
2021-05-18 01:24:31 INFO      integration_testing:clouds.py:173 Launched instance: GceInstance(instance_id=9202198169101707773)
2021-05-18 01:24:31 INFO      pycloudlib.instance:instance.py:165 executing: sudo -- sh -c 'cloud-init --version'
cloud-init version: /usr/bin/cloud-init 21.1-19-gbad84ad4-0ubuntu1~18.04.2
2021-05-18 01:24:32 INFO      integration_testing:clouds.py:179 cloud-init version: /usr/bin/cloud-init 21.1-19-gbad84ad4-0ubuntu1~18.04.2
2021-05-18 01:24:32 INFO      pycloudlib.instance:instance.py:165 executing: sudo -- sh -c 'grep serial /etc/cloud/build.info'
image serial: 20210504
2021-05-18 01:24:32 INFO      integration_testing:clouds.py:183 image serial: 20210504
2021-05-18 01:24:32 INFO      pycloudlib.instance:instance.py:165 executing: sudo -- sh -c hostname
2021-05-18 01:24:33 INFO      pycloudlib.instance:instance.py:165 executing: sudo -- sh -c 'dpkg-query --show cloud-init'
2021-05-18 01:24:33 INFO      pycloudlib.instance:instance.py:165 executing: sudo -- sh -c 'cat /run/cloud-init/result.json'
2021-05-18 01:24:33 INFO      pycloudlib.instance:instance.py:165 executing: sudo -- sh -c 'cloud-init init'
2021-05-18 01:24:34 INFO      pycloudlib.instance:instance.py:165 executing: sudo -- sh -c 'grep Trace /var/log/cloud-init.log'
2021-05-18 01:24:34 INFO      pycloudlib.instance:instance.py:165 executing: sudo -- sh -c cloud-id
2021-05-18 01:24:35 INFO      pycloudlib.instance:instance.py:165 executing: sudo -- sh -c 'cat /etc/netplan/50-cloud-init.yaml'
2021-05-18 01:24:35 INFO      pycloudlib.instance:instance.py:165 executing: sudo -- sh -c systemd-analyze
2021-05-18 01:24:35 INFO      pycloudlib.instance:instance.py:165 executing: sudo -- sh -c 'systemd-analyze blame'
2021-05-18 01:24:36 INFO      pycloudlib.instance:instance.py:165 executing: sudo -- sh -c 'cloud-init analyze show'
2021-05-18 01:24:36 INFO      pycloudlib.instance:instance.py:165 executing: sudo -- sh -c 'cloud-init analyze blame'
Installing proposed image
2021-05-18 01:24:37 INFO      integration_testing:instances.py:144 Installing proposed image
2021-05-18 01:24:37 INFO      pycloudlib.instance:instance.py:165 executing: sudo -- sh -c 'echo deb "http://archive.ubuntu.com/ubuntu $(lsb_release -sc)-proposed main" | tee /etc/apt/sources.list.d/proposed.list
apt-get update -q
apt-get install -qy cloud-init'
2021-05-18 01:24:57 INFO      pycloudlib.instance:instance.py:165 executing: sudo -- sh -c 'cloud-init -v'
Installed cloud-init version: 21.2-3-g899bfaa9-0ubuntu2~18.04.1
2021-05-18 01:24:58 INFO      integration_testing:instances.py:136 Installed cloud-init version: 21.2-3-g899bfaa9-0ubuntu2~18.04.1
2021-05-18 01:24:58 INFO      pycloudlib.instance:instance.py:165 executing: sh -c 'sudo cloud-init clean --logs'
2021-05-18 01:24:58 INFO      pycloudlib.instance:instance.py:165 executing: sh -c 'sudo rm -rf /var/log/syslog'
2021-05-18 01:24:59 INFO      pycloudlib.instance:instance.py:165 executing: sudo -- sh -c 'hostname something-else'
Restarting instance and waiting for boot
2021-05-18 01:24:59 INFO      integration_testing:instances.py:65 Restarting instance and waiting for boot
2021-05-18 01:25:58 INFO      pycloudlib.instance:instance.py:165 executing: sh -c whoami
2021-05-18 01:26:13 INFO      pycloudlib.instance:instance.py:343 [Errno None] Unable to connect to port 22 on 35.236.95.174
Retrying SSH connection to ubuntu@35.236.95.174:22 (584s left)
2021-05-18 01:26:14 INFO      pycloudlib.instance:instance.py:343 [Errno None] Unable to connect to port 22 on 35.236.95.174
Retrying SSH connection to ubuntu@35.236.95.174:22 (583s left)
2021-05-18 01:26:15 INFO      pycloudlib.instance:instance.py:343 [Errno None] Unable to connect to port 22 on 35.236.95.174
Retrying SSH connection to ubuntu@35.236.95.174:22 (582s left)
2021-05-18 01:26:16 INFO      pycloudlib.instance:instance.py:343 [Errno None] Unable to connect to port 22 on 35.236.95.174
Retrying SSH connection to ubuntu@35.236.95.174:22 (581s left)
2021-05-18 01:26:17 INFO      paramiko.transport:transport.py:1819 Connected (version 2.0, client OpenSSH_7.6p1)
2021-05-18 01:26:18 INFO      paramiko.transport:transport.py:1819 Authentication (publickey) successful!
2021-05-18 01:26:21 INFO      pycloudlib.instance:instance.py:165 executing: cloud-init status --wait --long
2021-05-18 01:26:24 INFO      pycloudlib.instance:instance.py:165 executing: sudo -- sh -c 'cloud-init status --wait --long'
2021-05-18 01:26:24 INFO      pycloudlib.instance:instance.py:165 executing: sudo -- sh -c 'cloud-init status --wait --long'
2021-05-18 01:26:25 INFO      pycloudlib.instance:instance.py:165 executing: sudo -- sh -c hostname
2021-05-18 01:26:25 INFO      pycloudlib.instance:instance.py:165 executing: sudo -- sh -c 'dpkg-query --show cloud-init'
2021-05-18 01:26:26 INFO      pycloudlib.instance:instance.py:165 executing: sudo -- sh -c 'cat /run/cloud-init/result.json'
2021-05-18 01:26:26 INFO      pycloudlib.instance:instance.py:165 executing: sudo -- sh -c 'cloud-init init'
2021-05-18 01:26:27 INFO      pycloudlib.instance:instance.py:165 executing: sudo -- sh -c 'grep Trace /var/log/cloud-init.log'
2021-05-18 01:26:27 INFO      pycloudlib.instance:instance.py:165 executing: sudo -- sh -c cloud-id
2021-05-18 01:26:28 INFO      pycloudlib.instance:instance.py:165 executing: sudo -- sh -c 'cat /etc/netplan/50-cloud-init.yaml'
2021-05-18 01:26:28 INFO      pycloudlib.instance:instance.py:165 executing: sudo -- sh -c systemd-analyze
2021-05-18 01:26:28 INFO      pycloudlib.instance:instance.py:165 executing: sudo -- sh -c 'systemd-analyze blame'
2021-05-18 01:26:28 INFO      pycloudlib.instance:instance.py:165 executing: sudo -- sh -c 'cloud-init analyze show'
2021-05-18 01:26:29 INFO      pycloudlib.instance:instance.py:165 executing: sudo -- sh -c 'cloud-init analyze blame'
Wrote upgrade test logs to /home/james/tmp_home/cloud_init_test_logs/test_upgrade_gce_bionic_before_210517201834.log and /home/james/tmp_home/cloud_init_test_logs/test_upgrade_gce_bionic_after_210517201834.log
2021-05-18 01:27:16 INFO      integration_testing:test_upgrade.py:102 Wrote upgrade test logs to /home/james/tmp_home/cloud_init_test_logs/test_upgrade_gce_bionic_before_210517201834.log and /home/james/tmp_home/cloud_init_test_logs/test_upgrade_gce_bionic_after_210517201834.log
PASSED


==== Focal ====
-------------------------------- live log setup --------------------------------
2021-05-18 10:34:28 INFO      integration_testing:clouds.py:88 Detected image: image_id=focal os=ubuntu release=focal
Detected image: image_id=focal os=ubuntu release=focal
-------------------------------- live log call ---------------------------------
2021-05-18 10:34:28 INFO      integration_testing:clouds.py:88 Detected image: image_id=focal os=ubuntu release=focal
Launching instance with launch_kwargs:
user_data=#cloud-config
hostname: SRU-worked

image_id=projects/ubuntu-os-cloud-devel/global/images/daily-ubuntu-2004-focal-v20210513a
2021-05-18 10:34:28 INFO      integration_testing:clouds.py:168 Launching instance with launch_kwargs:
user_data=#cloud-config
hostname: SRU-worked

image_id=projects/ubuntu-os-cloud-devel/global/images/daily-ubuntu-2004-focal-v20210513a
2021-05-18 10:34:31 WARNING   google.auth._default:_default.py:352 No project ID could be determined. Consider running `gcloud config set project` or setting the GOOGLE_CLOUD_PROJECT environment variable
2021-05-18 10:34:39 INFO      pycloudlib.instance:instance.py:165 executing: sh -c whoami
2021-05-18 10:35:11 INFO      pycloudlib.instance:instance.py:343 [Errno None] Unable to connect to port 22 on 34.94.54.202
Retrying SSH connection to ubuntu@34.94.54.202:22 (568s left)
2021-05-18 10:35:12 INFO      paramiko.transport:transport.py:1819 Connected (version 2.0, client OpenSSH_8.2p1)
2021-05-18 10:35:12 INFO      paramiko.transport:transport.py:1819 Authentication (publickey) successful!
2021-05-18 10:35:16 INFO      pycloudlib.instance:instance.py:165 executing: cloud-init status --wait --long
Launched instance: GceInstance(instance_id=9132062607288444634)
2021-05-18 10:35:20 INFO      integration_testing:clouds.py:173 Launched instance: GceInstance(instance_id=9132062607288444634)
2021-05-18 10:35:20 INFO      pycloudlib.instance:instance.py:165 executing: sudo -- sh -c 'cloud-init --version'
cloud-init version: /usr/bin/cloud-init 21.1-19-gbad84ad4-0ubuntu1~20.04.2
2021-05-18 10:35:21 INFO      integration_testing:clouds.py:179 cloud-init version: /usr/bin/cloud-init 21.1-19-gbad84ad4-0ubuntu1~20.04.2
2021-05-18 10:35:21 INFO      pycloudlib.instance:instance.py:165 executing: sudo -- sh -c 'grep serial /etc/cloud/build.info'
image serial: 20210513.1
2021-05-18 10:35:21 INFO      integration_testing:clouds.py:183 image serial: 20210513.1
2021-05-18 10:35:21 INFO      pycloudlib.instance:instance.py:165 executing: sudo -- sh -c hostname
2021-05-18 10:35:22 INFO      pycloudlib.instance:instance.py:165 executing: sudo -- sh -c 'dpkg-query --show cloud-init'
2021-05-18 10:35:22 INFO      pycloudlib.instance:instance.py:165 executing: sudo -- sh -c 'cat /run/cloud-init/result.json'
2021-05-18 10:35:22 INFO      pycloudlib.instance:instance.py:165 executing: sudo -- sh -c 'cloud-init init'
2021-05-18 10:35:23 INFO      pycloudlib.instance:instance.py:165 executing: sudo -- sh -c 'grep Trace /var/log/cloud-init.log'
2021-05-18 10:35:23 INFO      pycloudlib.instance:instance.py:165 executing: sudo -- sh -c cloud-id
2021-05-18 10:35:24 INFO      pycloudlib.instance:instance.py:165 executing: sudo -- sh -c 'cat /etc/netplan/50-cloud-init.yaml'
2021-05-18 10:35:24 INFO      pycloudlib.instance:instance.py:165 executing: sudo -- sh -c systemd-analyze
2021-05-18 10:35:24 INFO      pycloudlib.instance:instance.py:165 executing: sudo -- sh -c 'systemd-analyze blame'
2021-05-18 10:35:25 INFO      pycloudlib.instance:instance.py:165 executing: sudo -- sh -c 'cloud-init analyze show'
2021-05-18 10:35:26 INFO      pycloudlib.instance:instance.py:165 executing: sudo -- sh -c 'cloud-init analyze blame'
Installing proposed image
2021-05-18 10:35:27 INFO      integration_testing:instances.py:144 Installing proposed image
2021-05-18 10:35:27 INFO      pycloudlib.instance:instance.py:165 executing: sudo -- sh -c 'echo deb "http://archive.ubuntu.com/ubuntu $(lsb_release -sc)-proposed main" | tee /etc/apt/sources.list.d/proposed.list
apt-get update -q
apt-get install -qy cloud-init'
2021-05-18 10:35:44 INFO      pycloudlib.instance:instance.py:165 executing: sudo -- sh -c 'cloud-init -v'
Installed cloud-init version: 21.2-3-g899bfaa9-0ubuntu2~20.04.1
2021-05-18 10:35:45 INFO      integration_testing:instances.py:136 Installed cloud-init version: 21.2-3-g899bfaa9-0ubuntu2~20.04.1
2021-05-18 10:35:45 INFO      pycloudlib.instance:instance.py:165 executing: sh -c 'sudo cloud-init clean --logs'
2021-05-18 10:35:46 INFO      pycloudlib.instance:instance.py:165 executing: sh -c 'sudo rm -rf /var/log/syslog'
2021-05-18 10:35:46 INFO      pycloudlib.instance:instance.py:165 executing: sudo -- sh -c 'hostname something-else'
Restarting instance and waiting for boot
2021-05-18 10:35:46 INFO      integration_testing:instances.py:65 Restarting instance and waiting for boot
2021-05-18 10:36:14 INFO      pycloudlib.instance:instance.py:165 executing: sh -c whoami
2021-05-18 10:36:29 INFO      pycloudlib.instance:instance.py:343 [Errno None] Unable to connect to port 22 on 35.236.95.174
Retrying SSH connection to ubuntu@35.236.95.174:22 (584s left)
2021-05-18 10:36:30 INFO      pycloudlib.instance:instance.py:343 [Errno None] Unable to connect to port 22 on 35.236.95.174
Retrying SSH connection to ubuntu@35.236.95.174:22 (583s left)
2021-05-18 10:36:32 INFO      pycloudlib.instance:instance.py:343 [Errno None] Unable to connect to port 22 on 35.236.95.174
Retrying SSH connection to ubuntu@35.236.95.174:22 (582s left)
2021-05-18 10:36:33 INFO      pycloudlib.instance:instance.py:343 [Errno None] Unable to connect to port 22 on 35.236.95.174
Retrying SSH connection to ubuntu@35.236.95.174:22 (581s left)
2021-05-18 10:36:34 INFO      pycloudlib.instance:instance.py:343 [Errno None] Unable to connect to port 22 on 35.236.95.174
Retrying SSH connection to ubuntu@35.236.95.174:22 (580s left)
2021-05-18 10:36:35 INFO      paramiko.transport:transport.py:1819 Connected (version 2.0, client OpenSSH_8.2p1)
2021-05-18 10:36:36 INFO      paramiko.transport:transport.py:1819 Authentication (publickey) successful!
2021-05-18 10:36:38 INFO      pycloudlib.instance:instance.py:165 executing: cloud-init status --wait --long
2021-05-18 10:36:41 INFO      pycloudlib.instance:instance.py:165 executing: sudo -- sh -c 'cloud-init status --wait --long'
2021-05-18 10:36:42 INFO      pycloudlib.instance:instance.py:165 executing: sudo -- sh -c 'cloud-init status --wait --long'
2021-05-18 10:36:42 INFO      pycloudlib.instance:instance.py:165 executing: sudo -- sh -c hostname
2021-05-18 10:36:42 INFO      pycloudlib.instance:instance.py:165 executing: sudo -- sh -c 'dpkg-query --show cloud-init'
2021-05-18 10:36:43 INFO      pycloudlib.instance:instance.py:165 executing: sudo -- sh -c 'cat /run/cloud-init/result.json'
2021-05-18 10:36:43 INFO      pycloudlib.instance:instance.py:165 executing: sudo -- sh -c 'cloud-init init'
2021-05-18 10:36:44 INFO      pycloudlib.instance:instance.py:165 executing: sudo -- sh -c 'grep Trace /var/log/cloud-init.log'
2021-05-18 10:36:44 INFO      pycloudlib.instance:instance.py:165 executing: sudo -- sh -c cloud-id
2021-05-18 10:36:45 INFO      pycloudlib.instance:instance.py:165 executing: sudo -- sh -c 'cat /etc/netplan/50-cloud-init.yaml'
2021-05-18 10:36:45 INFO      pycloudlib.instance:instance.py:165 executing: sudo -- sh -c systemd-analyze
2021-05-18 10:36:45 INFO      pycloudlib.instance:instance.py:165 executing: sudo -- sh -c 'systemd-analyze blame'
2021-05-18 10:36:46 INFO      pycloudlib.instance:instance.py:165 executing: sudo -- sh -c 'cloud-init analyze show'
2021-05-18 10:36:47 INFO      pycloudlib.instance:instance.py:165 executing: sudo -- sh -c 'cloud-init analyze blame'
Wrote upgrade test logs to /home/james/tmp_home/cloud_init_test_logs/test_upgrade_gce_focal_before_210518053034.log and /home/james/tmp_home/cloud_init_test_logs/test_upgrade_gce_focal_after_210518053034.log
2021-05-18 10:37:33 INFO      integration_testing:test_upgrade.py:102 Wrote upgrade test logs to /home/james/tmp_home/cloud_init_test_logs/test_upgrade_gce_focal_before_210518053034.log and /home/james/tmp_home/cloud_init_test_logs/test_upgrade_gce_focal_after_210518053034.log
PASSED


==== Groovy ====
-------------------------------- live log setup --------------------------------
2021-05-19 05:51:55 INFO      integration_testing:clouds.py:88 Detected image: image_id=groovy os=ubuntu release=groovy
Detected image: image_id=groovy os=ubuntu release=groovy
-------------------------------- live log call ---------------------------------
2021-05-19 05:51:55 INFO      integration_testing:clouds.py:88 Detected image: image_id=groovy os=ubuntu release=groovy
Launching instance with launch_kwargs:
image_id=projects/ubuntu-os-cloud-devel/global/images/daily-ubuntu-2010-groovy-v20210514
user_data=#cloud-config
hostname: SRU-worked

2021-05-19 05:51:55 INFO      integration_testing:clouds.py:168 Launching instance with launch_kwargs:
image_id=projects/ubuntu-os-cloud-devel/global/images/daily-ubuntu-2010-groovy-v20210514
user_data=#cloud-config
hostname: SRU-worked

2021-05-19 05:51:57 WARNING   google.auth._default:_default.py:352 No project ID could be determined. Consider running `gcloud config set project` or setting the GOOGLE_CLOUD_PROJECT environment variable
2021-05-19 05:52:06 INFO      pycloudlib.instance:instance.py:165 executing: sh -c whoami
2021-05-19 05:52:37 INFO      pycloudlib.instance:instance.py:343 [Errno None] Unable to connect to port 22 on 35.236.95.174
Retrying SSH connection to ubuntu@35.236.95.174:22 (568s left)
2021-05-19 05:52:38 INFO      pycloudlib.instance:instance.py:343 [Errno None] Unable to connect to port 22 on 35.236.95.174
Retrying SSH connection to ubuntu@35.236.95.174:22 (567s left)
2021-05-19 05:52:40 INFO      pycloudlib.instance:instance.py:343 [Errno None] Unable to connect to port 22 on 35.236.95.174
Retrying SSH connection to ubuntu@35.236.95.174:22 (566s left)
2021-05-19 05:52:41 INFO      pycloudlib.instance:instance.py:343 [Errno None] Unable to connect to port 22 on 35.236.95.174
Retrying SSH connection to ubuntu@35.236.95.174:22 (565s left)
2021-05-19 05:52:42 INFO      pycloudlib.instance:instance.py:343 [Errno None] Unable to connect to port 22 on 35.236.95.174
Retrying SSH connection to ubuntu@35.236.95.174:22 (564s left)
2021-05-19 05:52:43 INFO      pycloudlib.instance:instance.py:343 [Errno None] Unable to connect to port 22 on 35.236.95.174
Retrying SSH connection to ubuntu@35.236.95.174:22 (563s left)
2021-05-19 05:52:44 INFO      paramiko.transport:transport.py:1819 Connected (version 2.0, client OpenSSH_8.3p1)
2021-05-19 05:52:44 INFO      paramiko.transport:transport.py:1819 Authentication (publickey) successful!
2021-05-19 05:52:46 INFO      pycloudlib.instance:instance.py:165 executing: cloud-init status --wait --long
Launched instance: GceInstance(instance_id=8038405393598716308)
2021-05-19 05:52:48 INFO      integration_testing:clouds.py:173 Launched instance: GceInstance(instance_id=8038405393598716308)
2021-05-19 05:52:48 INFO      pycloudlib.instance:instance.py:165 executing: sudo -- sh -c 'cloud-init --version'
cloud-init version: /usr/bin/cloud-init 21.1-19-gbad84ad4-0ubuntu1~20.10.2
2021-05-19 05:52:49 INFO      integration_testing:clouds.py:179 cloud-init version: /usr/bin/cloud-init 21.1-19-gbad84ad4-0ubuntu1~20.10.2
2021-05-19 05:52:49 INFO      pycloudlib.instance:instance.py:165 executing: sudo -- sh -c 'grep serial /etc/cloud/build.info'
image serial: 20210514
2021-05-19 05:52:49 INFO      integration_testing:clouds.py:183 image serial: 20210514
2021-05-19 05:52:49 INFO      pycloudlib.instance:instance.py:165 executing: sudo -- sh -c hostname
2021-05-19 05:52:50 INFO      pycloudlib.instance:instance.py:165 executing: sudo -- sh -c 'dpkg-query --show cloud-init'
2021-05-19 05:52:50 INFO      pycloudlib.instance:instance.py:165 executing: sudo -- sh -c 'cat /run/cloud-init/result.json'
2021-05-19 05:52:50 INFO      pycloudlib.instance:instance.py:165 executing: sudo -- sh -c 'cloud-init init'
2021-05-19 05:52:51 INFO      pycloudlib.instance:instance.py:165 executing: sudo -- sh -c 'grep Trace /var/log/cloud-init.log'
2021-05-19 05:52:51 INFO      pycloudlib.instance:instance.py:165 executing: sudo -- sh -c cloud-id
2021-05-19 05:52:52 INFO      pycloudlib.instance:instance.py:165 executing: sudo -- sh -c 'cat /etc/netplan/50-cloud-init.yaml'
2021-05-19 05:52:52 INFO      pycloudlib.instance:instance.py:165 executing: sudo -- sh -c systemd-analyze
2021-05-19 05:52:52 INFO      pycloudlib.instance:instance.py:165 executing: sudo -- sh -c 'systemd-analyze blame'
2021-05-19 05:52:53 INFO      pycloudlib.instance:instance.py:165 executing: sudo -- sh -c 'cloud-init analyze show'
2021-05-19 05:52:54 INFO      pycloudlib.instance:instance.py:165 executing: sudo -- sh -c 'cloud-init analyze blame'
Installing proposed image
2021-05-19 05:52:54 INFO      integration_testing:instances.py:144 Installing proposed image
2021-05-19 05:52:54 INFO      pycloudlib.instance:instance.py:165 executing: sudo -- sh -c 'echo deb "http://archive.ubuntu.com/ubuntu $(lsb_release -sc)-proposed main" | tee /etc/apt/sources.list.d/proposed.list
apt-get update -q
apt-get install -qy cloud-init'
2021-05-19 05:53:11 INFO      pycloudlib.instance:instance.py:165 executing: sudo -- sh -c 'cloud-init -v'
Installed cloud-init version: 21.2-3-g899bfaa9-0ubuntu2~20.10.1
2021-05-19 05:53:12 INFO      integration_testing:instances.py:136 Installed cloud-init version: 21.2-3-g899bfaa9-0ubuntu2~20.10.1
2021-05-19 05:53:12 INFO      pycloudlib.instance:instance.py:165 executing: sh -c 'sudo cloud-init clean --logs'
2021-05-19 05:53:12 INFO      pycloudlib.instance:instance.py:165 executing: sh -c 'sudo rm -rf /var/log/syslog'
2021-05-19 05:53:13 INFO      pycloudlib.instance:instance.py:165 executing: sudo -- sh -c 'hostname something-else'
Restarting instance and waiting for boot
2021-05-19 05:53:13 INFO      integration_testing:instances.py:65 Restarting instance and waiting for boot
2021-05-19 05:53:40 INFO      pycloudlib.instance:instance.py:165 executing: sh -c whoami
2021-05-19 05:53:55 INFO      pycloudlib.instance:instance.py:343 [Errno None] Unable to connect to port 22 on 34.94.54.202
Retrying SSH connection to ubuntu@34.94.54.202:22 (584s left)
2021-05-19 05:53:57 INFO      pycloudlib.instance:instance.py:343 [Errno None] Unable to connect to port 22 on 34.94.54.202
Retrying SSH connection to ubuntu@34.94.54.202:22 (583s left)
2021-05-19 05:53:58 INFO      pycloudlib.instance:instance.py:343 [Errno None] Unable to connect to port 22 on 34.94.54.202
Retrying SSH connection to ubuntu@34.94.54.202:22 (582s left)
2021-05-19 05:53:59 INFO      pycloudlib.instance:instance.py:343 [Errno None] Unable to connect to port 22 on 34.94.54.202
Retrying SSH connection to ubuntu@34.94.54.202:22 (581s left)
2021-05-19 05:54:00 INFO      paramiko.transport:transport.py:1819 Connected (version 2.0, client OpenSSH_8.3p1)
2021-05-19 05:54:01 INFO      paramiko.transport:transport.py:1819 Authentication (publickey) successful!
2021-05-19 05:54:03 INFO      pycloudlib.instance:instance.py:165 executing: cloud-init status --wait --long
2021-05-19 05:54:08 INFO      pycloudlib.instance:instance.py:165 executing: sudo -- sh -c 'cloud-init status --wait --long'
2021-05-19 05:54:09 INFO      pycloudlib.instance:instance.py:165 executing: sudo -- sh -c 'cloud-init status --wait --long'
2021-05-19 05:54:09 INFO      pycloudlib.instance:instance.py:165 executing: sudo -- sh -c hostname
2021-05-19 05:54:10 INFO      pycloudlib.instance:instance.py:165 executing: sudo -- sh -c 'dpkg-query --show cloud-init'
2021-05-19 05:54:10 INFO      pycloudlib.instance:instance.py:165 executing: sudo -- sh -c 'cat /run/cloud-init/result.json'
2021-05-19 05:54:10 INFO      pycloudlib.instance:instance.py:165 executing: sudo -- sh -c 'cloud-init init'
2021-05-19 05:54:11 INFO      pycloudlib.instance:instance.py:165 executing: sudo -- sh -c 'grep Trace /var/log/cloud-init.log'
2021-05-19 05:54:11 INFO      pycloudlib.instance:instance.py:165 executing: sudo -- sh -c cloud-id
2021-05-19 05:54:12 INFO      pycloudlib.instance:instance.py:165 executing: sudo -- sh -c 'cat /etc/netplan/50-cloud-init.yaml'
2021-05-19 05:54:12 INFO      pycloudlib.instance:instance.py:165 executing: sudo -- sh -c systemd-analyze
2021-05-19 05:54:12 INFO      pycloudlib.instance:instance.py:165 executing: sudo -- sh -c 'systemd-analyze blame'
2021-05-19 05:54:13 INFO      pycloudlib.instance:instance.py:165 executing: sudo -- sh -c 'cloud-init analyze show'
2021-05-19 05:54:14 INFO      pycloudlib.instance:instance.py:165 executing: sudo -- sh -c 'cloud-init analyze blame'
Wrote upgrade test logs to /home/james/tmp_home/cloud_init_test_logs/test_upgrade_gce_groovy_before_210519004630.log and /home/james/tmp_home/cloud_init_test_logs/test_upgrade_gce_groovy_after_210519004630.log
2021-05-19 05:55:00 INFO      integration_testing:test_upgrade.py:102 Wrote upgrade test logs to /home/james/tmp_home/cloud_init_test_logs/test_upgrade_gce_groovy_before_210519004630.log and /home/james/tmp_home/cloud_init_test_logs/test_upgrade_gce_groovy_after_210519004630.log
PASSED


==== Hirsute ====
-------------------------------- live log setup --------------------------------
2021-05-19 11:30:49 INFO      integration_testing:clouds.py:88 Detected image: image_id=hirsute os=ubuntu release=hirsute
Detected image: image_id=hirsute os=ubuntu release=hirsute
-------------------------------- live log call ---------------------------------
2021-05-19 11:30:49 INFO      integration_testing:clouds.py:88 Detected image: image_id=hirsute os=ubuntu release=hirsute
Launching instance with launch_kwargs:
user_data=#cloud-config
hostname: SRU-worked

image_id=projects/ubuntu-os-cloud-devel/global/images/daily-ubuntu-2104-hirsute-v20210514
2021-05-19 11:30:49 INFO      integration_testing:clouds.py:168 Launching instance with launch_kwargs:
user_data=#cloud-config
hostname: SRU-worked

image_id=projects/ubuntu-os-cloud-devel/global/images/daily-ubuntu-2104-hirsute-v20210514
2021-05-19 11:30:52 WARNING   google.auth._default:_default.py:352 No project ID could be determined. Consider running `gcloud config set project` or setting the GOOGLE_CLOUD_PROJECT environment variable
2021-05-19 11:31:01 INFO      pycloudlib.instance:instance.py:165 executing: sh -c whoami
2021-05-19 11:31:16 INFO      pycloudlib.instance:instance.py:343 [Errno None] Unable to connect to port 22 on 34.94.54.202
Retrying SSH connection to ubuntu@34.94.54.202:22 (584s left)
2021-05-19 11:31:17 INFO      pycloudlib.instance:instance.py:343 [Errno None] Unable to connect to port 22 on 34.94.54.202
Retrying SSH connection to ubuntu@34.94.54.202:22 (583s left)
2021-05-19 11:31:18 INFO      pycloudlib.instance:instance.py:343 [Errno None] Unable to connect to port 22 on 34.94.54.202
Retrying SSH connection to ubuntu@34.94.54.202:22 (582s left)
2021-05-19 11:31:19 INFO      pycloudlib.instance:instance.py:343 [Errno None] Unable to connect to port 22 on 34.94.54.202
Retrying SSH connection to ubuntu@34.94.54.202:22 (581s left)
2021-05-19 11:31:20 INFO      pycloudlib.instance:instance.py:343 [Errno None] Unable to connect to port 22 on 34.94.54.202
Retrying SSH connection to ubuntu@34.94.54.202:22 (580s left)
2021-05-19 11:31:21 INFO      pycloudlib.instance:instance.py:343 [Errno None] Unable to connect to port 22 on 34.94.54.202
Retrying SSH connection to ubuntu@34.94.54.202:22 (579s left)
2021-05-19 11:31:22 INFO      pycloudlib.instance:instance.py:343 [Errno None] Unable to connect to port 22 on 34.94.54.202
Retrying SSH connection to ubuntu@34.94.54.202:22 (578s left)
2021-05-19 11:31:24 INFO      pycloudlib.instance:instance.py:343 [Errno None] Unable to connect to port 22 on 34.94.54.202
Retrying SSH connection to ubuntu@34.94.54.202:22 (576s left)
2021-05-19 11:31:25 INFO      pycloudlib.instance:instance.py:343 [Errno None] Unable to connect to port 22 on 34.94.54.202
Retrying SSH connection to ubuntu@34.94.54.202:22 (575s left)
2021-05-19 11:31:26 INFO      paramiko.transport:transport.py:1819 Connected (version 2.0, client OpenSSH_8.4p1)
2021-05-19 11:31:26 INFO      paramiko.transport:transport.py:1819 Authentication (publickey) successful!
2021-05-19 11:31:30 INFO      pycloudlib.instance:instance.py:165 executing: cloud-init status --wait --long
Launched instance: GceInstance(instance_id=1757151426985412614)
2021-05-19 11:31:32 INFO      integration_testing:clouds.py:173 Launched instance: GceInstance(instance_id=1757151426985412614)
2021-05-19 11:31:32 INFO      pycloudlib.instance:instance.py:165 executing: sudo -- sh -c 'cloud-init --version'
cloud-init version: /usr/bin/cloud-init 21.1-19-gbad84ad4-0ubuntu3
2021-05-19 11:31:33 INFO      integration_testing:clouds.py:179 cloud-init version: /usr/bin/cloud-init 21.1-19-gbad84ad4-0ubuntu3
2021-05-19 11:31:33 INFO      pycloudlib.instance:instance.py:165 executing: sudo -- sh -c 'grep serial /etc/cloud/build.info'
image serial: 20210514
2021-05-19 11:31:33 INFO      integration_testing:clouds.py:183 image serial: 20210514
2021-05-19 11:31:33 INFO      pycloudlib.instance:instance.py:165 executing: sudo -- sh -c hostname
2021-05-19 11:31:33 INFO      pycloudlib.instance:instance.py:165 executing: sudo -- sh -c 'dpkg-query --show cloud-init'
2021-05-19 11:31:34 INFO      pycloudlib.instance:instance.py:165 executing: sudo -- sh -c 'cat /run/cloud-init/result.json'
2021-05-19 11:31:34 INFO      pycloudlib.instance:instance.py:165 executing: sudo -- sh -c 'cloud-init init'
2021-05-19 11:31:35 INFO      pycloudlib.instance:instance.py:165 executing: sudo -- sh -c 'grep Trace /var/log/cloud-init.log'
2021-05-19 11:31:35 INFO      pycloudlib.instance:instance.py:165 executing: sudo -- sh -c cloud-id
2021-05-19 11:31:35 INFO      pycloudlib.instance:instance.py:165 executing: sudo -- sh -c 'cat /etc/netplan/50-cloud-init.yaml'
2021-05-19 11:31:36 INFO      pycloudlib.instance:instance.py:165 executing: sudo -- sh -c systemd-analyze
2021-05-19 11:31:36 INFO      pycloudlib.instance:instance.py:165 executing: sudo -- sh -c 'systemd-analyze blame'
2021-05-19 11:31:37 INFO      pycloudlib.instance:instance.py:165 executing: sudo -- sh -c 'cloud-init analyze show'
2021-05-19 11:31:37 INFO      pycloudlib.instance:instance.py:165 executing: sudo -- sh -c 'cloud-init analyze blame'
Installing proposed image
2021-05-19 11:31:38 INFO      integration_testing:instances.py:144 Installing proposed image
2021-05-19 11:31:38 INFO      pycloudlib.instance:instance.py:165 executing: sudo -- sh -c 'echo deb "http://archive.ubuntu.com/ubuntu $(lsb_release -sc)-proposed main" | tee /etc/apt/sources.list.d/proposed.list
apt-get update -q
apt-get install -qy cloud-init'
2021-05-19 11:31:54 INFO      pycloudlib.instance:instance.py:165 executing: sudo -- sh -c 'cloud-init -v'
Installed cloud-init version: 21.2-3-g899bfaa9-0ubuntu2~21.04.1
2021-05-19 11:31:55 INFO      integration_testing:instances.py:136 Installed cloud-init version: 21.2-3-g899bfaa9-0ubuntu2~21.04.1
2021-05-19 11:31:55 INFO      pycloudlib.instance:instance.py:165 executing: sh -c 'sudo cloud-init clean --logs'
2021-05-19 11:31:55 INFO      pycloudlib.instance:instance.py:165 executing: sh -c 'sudo rm -rf /var/log/syslog'
2021-05-19 11:31:55 INFO      pycloudlib.instance:instance.py:165 executing: sudo -- sh -c 'hostname something-else'
Restarting instance and waiting for boot
2021-05-19 11:31:56 INFO      integration_testing:instances.py:65 Restarting instance and waiting for boot
2021-05-19 11:32:24 INFO      pycloudlib.instance:instance.py:165 executing: sh -c whoami
2021-05-19 11:32:39 INFO      pycloudlib.instance:instance.py:343 [Errno None] Unable to connect to port 22 on 35.236.95.174
Retrying SSH connection to ubuntu@35.236.95.174:22 (584s left)
2021-05-19 11:32:40 INFO      pycloudlib.instance:instance.py:343 [Errno None] Unable to connect to port 22 on 35.236.95.174
Retrying SSH connection to ubuntu@35.236.95.174:22 (583s left)
2021-05-19 11:32:41 INFO      pycloudlib.instance:instance.py:343 [Errno None] Unable to connect to port 22 on 35.236.95.174
Retrying SSH connection to ubuntu@35.236.95.174:22 (582s left)
2021-05-19 11:32:42 INFO      pycloudlib.instance:instance.py:343 [Errno None] Unable to connect to port 22 on 35.236.95.174
Retrying SSH connection to ubuntu@35.236.95.174:22 (581s left)
2021-05-19 11:32:43 INFO      paramiko.transport:transport.py:1819 Connected (version 2.0, client OpenSSH_8.4p1)
2021-05-19 11:32:44 INFO      paramiko.transport:transport.py:1819 Authentication (publickey) successful!
2021-05-19 11:32:47 INFO      pycloudlib.instance:instance.py:165 executing: cloud-init status --wait --long
2021-05-19 11:32:51 INFO      pycloudlib.instance:instance.py:165 executing: sudo -- sh -c 'cloud-init status --wait --long'
2021-05-19 11:32:52 INFO      pycloudlib.instance:instance.py:165 executing: sudo -- sh -c 'cloud-init status --wait --long'
2021-05-19 11:32:53 INFO      pycloudlib.instance:instance.py:165 executing: sudo -- sh -c hostname
2021-05-19 11:32:53 INFO      pycloudlib.instance:instance.py:165 executing: sudo -- sh -c 'dpkg-query --show cloud-init'
2021-05-19 11:32:53 INFO      pycloudlib.instance:instance.py:165 executing: sudo -- sh -c 'cat /run/cloud-init/result.json'
2021-05-19 11:32:53 INFO      pycloudlib.instance:instance.py:165 executing: sudo -- sh -c 'cloud-init init'
2021-05-19 11:32:54 INFO      pycloudlib.instance:instance.py:165 executing: sudo -- sh -c 'grep Trace /var/log/cloud-init.log'
2021-05-19 11:32:54 INFO      pycloudlib.instance:instance.py:165 executing: sudo -- sh -c cloud-id
2021-05-19 11:32:55 INFO      pycloudlib.instance:instance.py:165 executing: sudo -- sh -c 'cat /etc/netplan/50-cloud-init.yaml'
2021-05-19 11:32:55 INFO      pycloudlib.instance:instance.py:165 executing: sudo -- sh -c systemd-analyze
2021-05-19 11:32:56 INFO      pycloudlib.instance:instance.py:165 executing: sudo -- sh -c 'systemd-analyze blame'
2021-05-19 11:32:57 INFO      pycloudlib.instance:instance.py:165 executing: sudo -- sh -c 'cloud-init analyze show'
2021-05-19 11:32:57 INFO      pycloudlib.instance:instance.py:165 executing: sudo -- sh -c 'cloud-init analyze blame'
Wrote upgrade test logs to /home/james/tmp_home/cloud_init_test_logs/test_upgrade_gce_hirsute_before_210519062649.log and /home/james/tmp_home/cloud_init_test_logs/test_upgrade_gce_hirsute_after_210519062649.log
2021-05-19 11:33:45 INFO      integration_testing:test_upgrade.py:102 Wrote upgrade test logs to /home/james/tmp_home/cloud_init_test_logs/test_upgrade_gce_hirsute_before_210519062649.log and /home/james/tmp_home/cloud_init_test_logs/test_upgrade_gce_hirsute_after_210519062649.log
PASSED
