Upstream test at:
https://github.com/canonical/cloud-init/blob/master/tests/integration_tests/test_upgrade.py

Logs from individual before/after runs in openstack-sru-21.2-3 subdirectory

==== Bionic ====
-------------------------------- live log setup --------------------------------
2021-05-18 16:44:40 INFO      integration_testing:clouds.py:88 Detected image: image_id=de0f35a8-311d-4dc0-be40-1b75c8ff47fa os=ubuntu release=bionic
Detected image: image_id=de0f35a8-311d-4dc0-be40-1b75c8ff47fa os=ubuntu release=bionic
-------------------------------- live log call ---------------------------------
2021-05-18 16:44:40 INFO      integration_testing:clouds.py:88 Detected image: image_id=de0f35a8-311d-4dc0-be40-1b75c8ff47fa os=ubuntu release=bionic
Launching instance with launch_kwargs:
user_data=#cloud-config
hostname: SRU-worked

image_id=de0f35a8-311d-4dc0-be40-1b75c8ff47fa
2021-05-18 16:44:40 INFO      integration_testing:clouds.py:168 Launching instance with launch_kwargs:
user_data=#cloud-config
hostname: SRU-worked

image_id=de0f35a8-311d-4dc0-be40-1b75c8ff47fa
2021-05-18 16:44:55 INFO      paramiko.transport.sftp:sftp.py:158 [chan 8] sftp session closed.
2021-05-18 16:44:55 INFO      pycloudlib.instance:instance.py:165 executing: sh -c whoami
2021-05-18 16:44:58 INFO      pycloudlib.instance:instance.py:343 [Errno None] Unable to connect to port 22 on 10.245.167.180
Retrying SSH connection to ubuntu@10.245.167.180:22 (596s left)
2021-05-18 16:45:03 INFO      pycloudlib.instance:instance.py:343 [Errno None] Unable to connect to port 22 on 10.245.167.180
Retrying SSH connection to ubuntu@10.245.167.180:22 (592s left)
2021-05-18 16:45:07 INFO      pycloudlib.instance:instance.py:343 [Errno None] Unable to connect to port 22 on 10.245.167.180
Retrying SSH connection to ubuntu@10.245.167.180:22 (588s left)
2021-05-18 16:45:11 INFO      pycloudlib.instance:instance.py:343 [Errno None] Unable to connect to port 22 on 10.245.167.180
Retrying SSH connection to ubuntu@10.245.167.180:22 (584s left)
2021-05-18 16:45:12 INFO      pycloudlib.instance:instance.py:343 [Errno None] Unable to connect to port 22 on 10.245.167.180
Retrying SSH connection to ubuntu@10.245.167.180:22 (583s left)
2021-05-18 16:45:13 INFO      pycloudlib.instance:instance.py:343 [Errno None] Unable to connect to port 22 on 10.245.167.180
Retrying SSH connection to ubuntu@10.245.167.180:22 (582s left)
2021-05-18 16:45:14 INFO      pycloudlib.instance:instance.py:343 [Errno None] Unable to connect to port 22 on 10.245.167.180
Retrying SSH connection to ubuntu@10.245.167.180:22 (581s left)
2021-05-18 16:45:15 INFO      pycloudlib.instance:instance.py:343 [Errno None] Unable to connect to port 22 on 10.245.167.180
Retrying SSH connection to ubuntu@10.245.167.180:22 (580s left)
2021-05-18 16:45:17 INFO      pycloudlib.instance:instance.py:343 [Errno None] Unable to connect to port 22 on 10.245.167.180
Retrying SSH connection to ubuntu@10.245.167.180:22 (578s left)
2021-05-18 16:45:18 INFO      pycloudlib.instance:instance.py:343 [Errno None] Unable to connect to port 22 on 10.245.167.180
Retrying SSH connection to ubuntu@10.245.167.180:22 (577s left)
2021-05-18 16:45:19 INFO      pycloudlib.instance:instance.py:343 [Errno None] Unable to connect to port 22 on 10.245.167.180
Retrying SSH connection to ubuntu@10.245.167.180:22 (576s left)
2021-05-18 16:45:20 INFO      pycloudlib.instance:instance.py:343 [Errno None] Unable to connect to port 22 on 10.245.167.180
Retrying SSH connection to ubuntu@10.245.167.180:22 (575s left)
2021-05-18 16:45:21 INFO      paramiko.transport:transport.py:1819 Connected (version 2.0, client OpenSSH_7.6p1)
2021-05-18 16:45:22 INFO      paramiko.transport:transport.py:1819 Authentication (publickey) successful!
2021-05-18 16:45:24 INFO      pycloudlib.instance:instance.py:165 executing: cloud-init status --wait --long
Launched instance: OpenstackInstance(instance_id=45dab4ce-f509-44c8-bcf9-9428538b9cec)
2021-05-18 16:45:25 INFO      integration_testing:clouds.py:173 Launched instance: OpenstackInstance(instance_id=45dab4ce-f509-44c8-bcf9-9428538b9cec)
2021-05-18 16:45:25 INFO      pycloudlib.instance:instance.py:165 executing: sudo -- sh -c 'cloud-init --version'
cloud-init version: /usr/bin/cloud-init 20.4.1-0ubuntu1~18.04.1
2021-05-18 16:45:26 INFO      integration_testing:clouds.py:179 cloud-init version: /usr/bin/cloud-init 20.4.1-0ubuntu1~18.04.1
2021-05-18 16:45:26 INFO      pycloudlib.instance:instance.py:165 executing: sudo -- sh -c 'grep serial /etc/cloud/build.info'
image serial: 20210325
2021-05-18 16:45:26 INFO      integration_testing:clouds.py:183 image serial: 20210325
2021-05-18 16:45:26 INFO      pycloudlib.instance:instance.py:165 executing: sudo -- sh -c hostname
2021-05-18 16:45:27 INFO      pycloudlib.instance:instance.py:165 executing: sudo -- sh -c 'dpkg-query --show cloud-init'
2021-05-18 16:45:27 INFO      pycloudlib.instance:instance.py:165 executing: sudo -- sh -c 'cat /run/cloud-init/result.json'
2021-05-18 16:45:27 INFO      pycloudlib.instance:instance.py:165 executing: sudo -- sh -c 'cloud-init init'
2021-05-18 16:45:28 INFO      pycloudlib.instance:instance.py:165 executing: sudo -- sh -c 'grep Trace /var/log/cloud-init.log'
2021-05-18 16:45:28 INFO      pycloudlib.instance:instance.py:165 executing: sudo -- sh -c cloud-id
2021-05-18 16:45:29 INFO      pycloudlib.instance:instance.py:165 executing: sudo -- sh -c 'cat /etc/netplan/50-cloud-init.yaml'
2021-05-18 16:45:29 INFO      pycloudlib.instance:instance.py:165 executing: sudo -- sh -c systemd-analyze
2021-05-18 16:45:29 INFO      pycloudlib.instance:instance.py:165 executing: sudo -- sh -c 'systemd-analyze blame'
2021-05-18 16:45:29 INFO      pycloudlib.instance:instance.py:165 executing: sudo -- sh -c 'cloud-init analyze show'
2021-05-18 16:45:30 INFO      pycloudlib.instance:instance.py:165 executing: sudo -- sh -c 'cloud-init analyze blame'
Installing proposed image
2021-05-18 16:45:31 INFO      integration_testing:instances.py:144 Installing proposed image
2021-05-18 16:45:31 INFO      pycloudlib.instance:instance.py:165 executing: sudo -- sh -c 'echo deb "http://archive.ubuntu.com/ubuntu $(lsb_release -sc)-proposed main" | tee /etc/apt/sources.list.d/proposed.list
apt-get update -q
apt-get install -qy cloud-init'
2021-05-18 16:45:46 INFO      pycloudlib.instance:instance.py:165 executing: sudo -- sh -c 'cloud-init -v'
Installed cloud-init version: 21.2-3-g899bfaa9-0ubuntu2~18.04.1
2021-05-18 16:45:47 INFO      integration_testing:instances.py:136 Installed cloud-init version: 21.2-3-g899bfaa9-0ubuntu2~18.04.1
2021-05-18 16:45:47 INFO      pycloudlib.instance:instance.py:165 executing: sh -c 'sudo cloud-init clean --logs'
2021-05-18 16:45:48 INFO      pycloudlib.instance:instance.py:165 executing: sh -c 'sudo rm -rf /var/log/syslog'
2021-05-18 16:45:48 INFO      pycloudlib.instance:instance.py:165 executing: sudo -- sh -c 'hostname something-else'
Restarting instance and waiting for boot
2021-05-18 16:45:48 INFO      integration_testing:instances.py:65 Restarting instance and waiting for boot
2021-05-18 16:45:57 INFO      pycloudlib.instance:instance.py:165 executing: sh -c whoami
2021-05-18 16:46:29 INFO      paramiko.transport:transport.py:1819 Connected (version 2.0, client OpenSSH_7.6p1)
2021-05-18 16:46:29 INFO      paramiko.transport:transport.py:1819 Authentication (publickey) successful!
2021-05-18 16:46:30 INFO      pycloudlib.instance:instance.py:165 executing: cloud-init status --wait --long
2021-05-18 16:46:31 INFO      pycloudlib.instance:instance.py:165 executing: sudo -- sh -c 'cloud-init status --wait --long'
2021-05-18 16:46:32 INFO      pycloudlib.instance:instance.py:165 executing: sudo -- sh -c 'cloud-init status --wait --long'
2021-05-18 16:46:32 INFO      pycloudlib.instance:instance.py:165 executing: sudo -- sh -c hostname
2021-05-18 16:46:32 INFO      pycloudlib.instance:instance.py:165 executing: sudo -- sh -c 'dpkg-query --show cloud-init'
2021-05-18 16:46:32 INFO      pycloudlib.instance:instance.py:165 executing: sudo -- sh -c 'cat /run/cloud-init/result.json'
2021-05-18 16:46:33 INFO      pycloudlib.instance:instance.py:165 executing: sudo -- sh -c 'cloud-init init'
2021-05-18 16:46:34 INFO      pycloudlib.instance:instance.py:165 executing: sudo -- sh -c 'grep Trace /var/log/cloud-init.log'
2021-05-18 16:46:34 INFO      pycloudlib.instance:instance.py:165 executing: sudo -- sh -c cloud-id
2021-05-18 16:46:34 INFO      pycloudlib.instance:instance.py:165 executing: sudo -- sh -c 'cat /etc/netplan/50-cloud-init.yaml'
2021-05-18 16:46:34 INFO      pycloudlib.instance:instance.py:165 executing: sudo -- sh -c systemd-analyze
2021-05-18 16:46:35 INFO      pycloudlib.instance:instance.py:165 executing: sudo -- sh -c 'systemd-analyze blame'
2021-05-18 16:46:35 INFO      pycloudlib.instance:instance.py:165 executing: sudo -- sh -c 'cloud-init analyze show'
2021-05-18 16:46:35 INFO      pycloudlib.instance:instance.py:165 executing: sudo -- sh -c 'cloud-init analyze blame'
Wrote upgrade test logs to /home/james/tmp_home/cloud_init_test_logs/test_upgrade_openstack_bionic_before_210518114053.log and /home/james/tmp_home/cloud_init_test_logs/test_upgrade_openstack_bionic_after_210518114053.log
2021-05-18 16:46:38 INFO      integration_testing:test_upgrade.py:102 Wrote upgrade test logs to /home/james/tmp_home/cloud_init_test_logs/test_upgrade_openstack_bionic_before_210518114053.log and /home/james/tmp_home/cloud_init_test_logs/test_upgrade_openstack_bionic_after_210518114053.log
PASSED


==== Focal ====
-------------------------------- live log setup --------------------------------
2021-05-18 17:50:54 INFO      integration_testing:clouds.py:88 Detected image: image_id=8d11d48e-f026-4116-86ea-82f78c02b391 os=ubuntu release=focal
Detected image: image_id=8d11d48e-f026-4116-86ea-82f78c02b391 os=ubuntu release=focal
-------------------------------- live log call ---------------------------------
2021-05-18 17:50:54 INFO      integration_testing:clouds.py:88 Detected image: image_id=8d11d48e-f026-4116-86ea-82f78c02b391 os=ubuntu release=focal
Launching instance with launch_kwargs:
user_data=#cloud-config
hostname: SRU-worked

image_id=8d11d48e-f026-4116-86ea-82f78c02b391
2021-05-18 17:50:54 INFO      integration_testing:clouds.py:168 Launching instance with launch_kwargs:
user_data=#cloud-config
hostname: SRU-worked

image_id=8d11d48e-f026-4116-86ea-82f78c02b391
2021-05-18 17:51:08 INFO      pycloudlib.instance:instance.py:165 executing: sh -c whoami
2021-05-18 17:51:11 INFO      pycloudlib.instance:instance.py:343 [Errno None] Unable to connect to port 22 on 10.245.165.14
Retrying SSH connection to ubuntu@10.245.165.14:22 (596s left)
2021-05-18 17:51:15 INFO      pycloudlib.instance:instance.py:343 [Errno None] Unable to connect to port 22 on 10.245.165.14
Retrying SSH connection to ubuntu@10.245.165.14:22 (592s left)
2021-05-18 17:51:17 INFO      pycloudlib.instance:instance.py:343 [Errno None] Unable to connect to port 22 on 10.245.165.14
Retrying SSH connection to ubuntu@10.245.165.14:22 (591s left)
2021-05-18 17:51:18 INFO      pycloudlib.instance:instance.py:343 [Errno None] Unable to connect to port 22 on 10.245.165.14
Retrying SSH connection to ubuntu@10.245.165.14:22 (590s left)
2021-05-18 17:51:19 INFO      pycloudlib.instance:instance.py:343 [Errno None] Unable to connect to port 22 on 10.245.165.14
Retrying SSH connection to ubuntu@10.245.165.14:22 (589s left)
2021-05-18 17:51:20 INFO      pycloudlib.instance:instance.py:343 [Errno None] Unable to connect to port 22 on 10.245.165.14
Retrying SSH connection to ubuntu@10.245.165.14:22 (588s left)
2021-05-18 17:51:21 INFO      pycloudlib.instance:instance.py:343 [Errno None] Unable to connect to port 22 on 10.245.165.14
Retrying SSH connection to ubuntu@10.245.165.14:22 (587s left)
2021-05-18 17:51:22 INFO      pycloudlib.instance:instance.py:343 [Errno None] Unable to connect to port 22 on 10.245.165.14
Retrying SSH connection to ubuntu@10.245.165.14:22 (586s left)
2021-05-18 17:51:23 INFO      pycloudlib.instance:instance.py:343 [Errno None] Unable to connect to port 22 on 10.245.165.14
Retrying SSH connection to ubuntu@10.245.165.14:22 (585s left)
2021-05-18 17:51:24 INFO      pycloudlib.instance:instance.py:343 [Errno None] Unable to connect to port 22 on 10.245.165.14
Retrying SSH connection to ubuntu@10.245.165.14:22 (584s left)
2021-05-18 17:51:25 INFO      pycloudlib.instance:instance.py:343 [Errno None] Unable to connect to port 22 on 10.245.165.14
Retrying SSH connection to ubuntu@10.245.165.14:22 (583s left)
2021-05-18 17:51:26 INFO      pycloudlib.instance:instance.py:343 [Errno None] Unable to connect to port 22 on 10.245.165.14
Retrying SSH connection to ubuntu@10.245.165.14:22 (582s left)
2021-05-18 17:51:27 INFO      pycloudlib.instance:instance.py:343 [Errno None] Unable to connect to port 22 on 10.245.165.14
Retrying SSH connection to ubuntu@10.245.165.14:22 (581s left)
2021-05-18 17:51:28 INFO      pycloudlib.instance:instance.py:343 [Errno None] Unable to connect to port 22 on 10.245.165.14
Retrying SSH connection to ubuntu@10.245.165.14:22 (580s left)
2021-05-18 17:51:29 INFO      pycloudlib.instance:instance.py:343 [Errno None] Unable to connect to port 22 on 10.245.165.14
Retrying SSH connection to ubuntu@10.245.165.14:22 (579s left)
2021-05-18 17:51:30 INFO      paramiko.transport:transport.py:1819 Connected (version 2.0, client OpenSSH_8.2p1)
2021-05-18 17:51:31 INFO      paramiko.transport:transport.py:1819 Authentication (publickey) successful!
2021-05-18 17:51:33 INFO      pycloudlib.instance:instance.py:165 executing: cloud-init status --wait --long
Launched instance: OpenstackInstance(instance_id=80d6dc1f-5c24-482c-ad64-506a8ffd3e3d)
2021-05-18 17:51:38 INFO      integration_testing:clouds.py:173 Launched instance: OpenstackInstance(instance_id=80d6dc1f-5c24-482c-ad64-506a8ffd3e3d)
2021-05-18 17:51:38 INFO      pycloudlib.instance:instance.py:165 executing: sudo -- sh -c 'cloud-init --version'
cloud-init version: /usr/bin/cloud-init 20.4.1-0ubuntu1~20.04.1
2021-05-18 17:51:39 INFO      integration_testing:clouds.py:179 cloud-init version: /usr/bin/cloud-init 20.4.1-0ubuntu1~20.04.1
2021-05-18 17:51:39 INFO      pycloudlib.instance:instance.py:165 executing: sudo -- sh -c 'grep serial /etc/cloud/build.info'
image serial: 20210325
2021-05-18 17:51:39 INFO      integration_testing:clouds.py:183 image serial: 20210325
2021-05-18 17:51:39 INFO      pycloudlib.instance:instance.py:165 executing: sudo -- sh -c hostname
2021-05-18 17:51:39 INFO      pycloudlib.instance:instance.py:165 executing: sudo -- sh -c 'dpkg-query --show cloud-init'
2021-05-18 17:51:39 INFO      pycloudlib.instance:instance.py:165 executing: sudo -- sh -c 'cat /run/cloud-init/result.json'
2021-05-18 17:51:40 INFO      pycloudlib.instance:instance.py:165 executing: sudo -- sh -c 'cloud-init init'
2021-05-18 17:51:41 INFO      pycloudlib.instance:instance.py:165 executing: sudo -- sh -c 'grep Trace /var/log/cloud-init.log'
2021-05-18 17:51:41 INFO      pycloudlib.instance:instance.py:165 executing: sudo -- sh -c cloud-id
2021-05-18 17:51:41 INFO      pycloudlib.instance:instance.py:165 executing: sudo -- sh -c 'cat /etc/netplan/50-cloud-init.yaml'
2021-05-18 17:51:41 INFO      pycloudlib.instance:instance.py:165 executing: sudo -- sh -c systemd-analyze
2021-05-18 17:51:42 INFO      pycloudlib.instance:instance.py:165 executing: sudo -- sh -c 'systemd-analyze blame'
2021-05-18 17:51:42 INFO      pycloudlib.instance:instance.py:165 executing: sudo -- sh -c 'cloud-init analyze show'
2021-05-18 17:51:43 INFO      pycloudlib.instance:instance.py:165 executing: sudo -- sh -c 'cloud-init analyze blame'
Installing proposed image
2021-05-18 17:51:44 INFO      integration_testing:instances.py:144 Installing proposed image
2021-05-18 17:51:44 INFO      pycloudlib.instance:instance.py:165 executing: sudo -- sh -c 'echo deb "http://archive.ubuntu.com/ubuntu $(lsb_release -sc)-proposed main" | tee /etc/apt/sources.list.d/proposed.list
apt-get update -q
apt-get install -qy cloud-init'
2021-05-18 17:52:09 INFO      pycloudlib.instance:instance.py:165 executing: sudo -- sh -c 'cloud-init -v'
Installed cloud-init version: 21.2-3-g899bfaa9-0ubuntu2~20.04.1
2021-05-18 17:52:10 INFO      integration_testing:instances.py:136 Installed cloud-init version: 21.2-3-g899bfaa9-0ubuntu2~20.04.1
2021-05-18 17:52:10 INFO      pycloudlib.instance:instance.py:165 executing: sh -c 'sudo cloud-init clean --logs'
2021-05-18 17:52:10 INFO      pycloudlib.instance:instance.py:165 executing: sh -c 'sudo rm -rf /var/log/syslog'
2021-05-18 17:52:10 INFO      pycloudlib.instance:instance.py:165 executing: sudo -- sh -c 'hostname something-else'
Restarting instance and waiting for boot
2021-05-18 17:52:11 INFO      integration_testing:instances.py:65 Restarting instance and waiting for boot
2021-05-18 17:52:24 INFO      pycloudlib.instance:instance.py:165 executing: sh -c whoami
2021-05-18 17:52:40 INFO      pycloudlib.instance:instance.py:343 [Errno None] Unable to connect to port 22 on 10.245.165.14
Retrying SSH connection to ubuntu@10.245.165.14:22 (584s left)
2021-05-18 17:52:41 INFO      pycloudlib.instance:instance.py:343 [Errno None] Unable to connect to port 22 on 10.245.165.14
Retrying SSH connection to ubuntu@10.245.165.14:22 (583s left)
2021-05-18 17:52:42 INFO      paramiko.transport:transport.py:1819 Connected (version 2.0, client OpenSSH_8.2p1)
2021-05-18 17:52:42 INFO      paramiko.transport:transport.py:1819 Authentication (publickey) successful!
2021-05-18 17:52:45 INFO      pycloudlib.instance:instance.py:165 executing: cloud-init status --wait --long
2021-05-18 17:52:48 INFO      pycloudlib.instance:instance.py:165 executing: sudo -- sh -c 'cloud-init status --wait --long'
2021-05-18 17:52:49 INFO      pycloudlib.instance:instance.py:165 executing: sudo -- sh -c 'cloud-init status --wait --long'
2021-05-18 17:52:50 INFO      pycloudlib.instance:instance.py:165 executing: sudo -- sh -c hostname
2021-05-18 17:52:50 INFO      pycloudlib.instance:instance.py:165 executing: sudo -- sh -c 'dpkg-query --show cloud-init'
2021-05-18 17:52:50 INFO      pycloudlib.instance:instance.py:165 executing: sudo -- sh -c 'cat /run/cloud-init/result.json'
2021-05-18 17:52:50 INFO      pycloudlib.instance:instance.py:165 executing: sudo -- sh -c 'cloud-init init'
2021-05-18 17:52:51 INFO      pycloudlib.instance:instance.py:165 executing: sudo -- sh -c 'grep Trace /var/log/cloud-init.log'
2021-05-18 17:52:52 INFO      pycloudlib.instance:instance.py:165 executing: sudo -- sh -c cloud-id
2021-05-18 17:52:52 INFO      pycloudlib.instance:instance.py:165 executing: sudo -- sh -c 'cat /etc/netplan/50-cloud-init.yaml'
2021-05-18 17:52:52 INFO      pycloudlib.instance:instance.py:165 executing: sudo -- sh -c systemd-analyze
2021-05-18 17:52:53 INFO      pycloudlib.instance:instance.py:165 executing: sudo -- sh -c 'systemd-analyze blame'
2021-05-18 17:52:54 INFO      pycloudlib.instance:instance.py:165 executing: sudo -- sh -c 'cloud-init analyze show'
2021-05-18 17:52:54 INFO      pycloudlib.instance:instance.py:165 executing: sudo -- sh -c 'cloud-init analyze blame'
Wrote upgrade test logs to /home/james/tmp_home/cloud_init_test_logs/test_upgrade_openstack_focal_before_210518124640.log and /home/james/tmp_home/cloud_init_test_logs/test_upgrade_openstack_focal_after_210518124640.log
2021-05-18 17:53:00 INFO      integration_testing:test_upgrade.py:102 Wrote upgrade test logs to /home/james/tmp_home/cloud_init_test_logs/test_upgrade_openstack_focal_before_210518124640.log and /home/james/tmp_home/cloud_init_test_logs/test_upgrade_openstack_focal_after_210518124640.log
PASSED


==== Groovy ====
-------------------------------- live log setup --------------------------------
2021-05-18 18:35:11 INFO      integration_testing:clouds.py:88 Detected image: image_id=ce833b3e-922d-4cfd-9cdc-a1f5b04297a4 os=ubuntu release=groovy
Detected image: image_id=ce833b3e-922d-4cfd-9cdc-a1f5b04297a4 os=ubuntu release=groovy
-------------------------------- live log call ---------------------------------
2021-05-18 18:35:11 INFO      integration_testing:clouds.py:88 Detected image: image_id=ce833b3e-922d-4cfd-9cdc-a1f5b04297a4 os=ubuntu release=groovy
Launching instance with launch_kwargs:
user_data=#cloud-config
hostname: SRU-worked

image_id=ce833b3e-922d-4cfd-9cdc-a1f5b04297a4
2021-05-18 18:35:11 INFO      integration_testing:clouds.py:168 Launching instance with launch_kwargs:
user_data=#cloud-config
hostname: SRU-worked

image_id=ce833b3e-922d-4cfd-9cdc-a1f5b04297a4
2021-05-18 18:35:22 INFO      pycloudlib.instance:instance.py:165 executing: sh -c whoami
2021-05-18 18:35:27 INFO      pycloudlib.instance:instance.py:343 [Errno None] Unable to connect to port 22 on 10.245.166.100
Retrying SSH connection to ubuntu@10.245.166.100:22 (595s left)
2021-05-18 18:35:29 INFO      pycloudlib.instance:instance.py:343 [Errno None] Unable to connect to port 22 on 10.245.166.100
Retrying SSH connection to ubuntu@10.245.166.100:22 (592s left)
2021-05-18 18:35:30 INFO      pycloudlib.instance:instance.py:343 [Errno None] Unable to connect to port 22 on 10.245.166.100
Retrying SSH connection to ubuntu@10.245.166.100:22 (591s left)
2021-05-18 18:35:31 INFO      pycloudlib.instance:instance.py:343 [Errno None] Unable to connect to port 22 on 10.245.166.100
Retrying SSH connection to ubuntu@10.245.166.100:22 (590s left)
2021-05-18 18:35:32 INFO      pycloudlib.instance:instance.py:343 [Errno None] Unable to connect to port 22 on 10.245.166.100
Retrying SSH connection to ubuntu@10.245.166.100:22 (589s left)
2021-05-18 18:35:34 INFO      pycloudlib.instance:instance.py:343 [Errno None] Unable to connect to port 22 on 10.245.166.100
Retrying SSH connection to ubuntu@10.245.166.100:22 (588s left)
2021-05-18 18:35:36 INFO      pycloudlib.instance:instance.py:343 [Errno None] Unable to connect to port 22 on 10.245.166.100
Retrying SSH connection to ubuntu@10.245.166.100:22 (586s left)
2021-05-18 18:35:37 INFO      pycloudlib.instance:instance.py:343 [Errno None] Unable to connect to port 22 on 10.245.166.100
Retrying SSH connection to ubuntu@10.245.166.100:22 (585s left)
2021-05-18 18:35:38 INFO      pycloudlib.instance:instance.py:343 [Errno None] Unable to connect to port 22 on 10.245.166.100
Retrying SSH connection to ubuntu@10.245.166.100:22 (584s left)
2021-05-18 18:35:39 INFO      pycloudlib.instance:instance.py:343 [Errno None] Unable to connect to port 22 on 10.245.166.100
Retrying SSH connection to ubuntu@10.245.166.100:22 (583s left)
2021-05-18 18:35:40 INFO      pycloudlib.instance:instance.py:343 [Errno None] Unable to connect to port 22 on 10.245.166.100
Retrying SSH connection to ubuntu@10.245.166.100:22 (582s left)
2021-05-18 18:35:41 INFO      paramiko.transport:transport.py:1819 Connected (version 2.0, client OpenSSH_8.3p1)
2021-05-18 18:35:41 INFO      paramiko.transport:transport.py:1819 Authentication (publickey) successful!
2021-05-18 18:35:43 INFO      pycloudlib.instance:instance.py:165 executing: cloud-init status --wait --long
Launched instance: OpenstackInstance(instance_id=9665bed6-f560-446e-bc26-7bc343b044ef)
2021-05-18 18:35:48 INFO      integration_testing:clouds.py:173 Launched instance: OpenstackInstance(instance_id=9665bed6-f560-446e-bc26-7bc343b044ef)
2021-05-18 18:35:48 INFO      pycloudlib.instance:instance.py:165 executing: sudo -- sh -c 'cloud-init --version'
cloud-init version: /usr/bin/cloud-init 20.4.1-0ubuntu1~20.10.1
2021-05-18 18:35:48 INFO      integration_testing:clouds.py:179 cloud-init version: /usr/bin/cloud-init 20.4.1-0ubuntu1~20.10.1
2021-05-18 18:35:48 INFO      pycloudlib.instance:instance.py:165 executing: sudo -- sh -c 'grep serial /etc/cloud/build.info'
image serial: 20210325
2021-05-18 18:35:49 INFO      integration_testing:clouds.py:183 image serial: 20210325
2021-05-18 18:35:49 INFO      pycloudlib.instance:instance.py:165 executing: sudo -- sh -c hostname
2021-05-18 18:35:49 INFO      pycloudlib.instance:instance.py:165 executing: sudo -- sh -c 'dpkg-query --show cloud-init'
2021-05-18 18:35:49 INFO      pycloudlib.instance:instance.py:165 executing: sudo -- sh -c 'cat /run/cloud-init/result.json'
2021-05-18 18:35:49 INFO      pycloudlib.instance:instance.py:165 executing: sudo -- sh -c 'cloud-init init'
2021-05-18 18:35:50 INFO      pycloudlib.instance:instance.py:165 executing: sudo -- sh -c 'grep Trace /var/log/cloud-init.log'
2021-05-18 18:35:50 INFO      pycloudlib.instance:instance.py:165 executing: sudo -- sh -c cloud-id
2021-05-18 18:35:50 INFO      pycloudlib.instance:instance.py:165 executing: sudo -- sh -c 'cat /etc/netplan/50-cloud-init.yaml'
2021-05-18 18:35:51 INFO      pycloudlib.instance:instance.py:165 executing: sudo -- sh -c systemd-analyze
2021-05-18 18:35:51 INFO      pycloudlib.instance:instance.py:165 executing: sudo -- sh -c 'systemd-analyze blame'
2021-05-18 18:35:52 INFO      pycloudlib.instance:instance.py:165 executing: sudo -- sh -c 'cloud-init analyze show'
2021-05-18 18:35:52 INFO      pycloudlib.instance:instance.py:165 executing: sudo -- sh -c 'cloud-init analyze blame'
Installing proposed image
2021-05-18 18:35:53 INFO      integration_testing:instances.py:144 Installing proposed image
2021-05-18 18:35:53 INFO      pycloudlib.instance:instance.py:165 executing: sudo -- sh -c 'echo deb "http://archive.ubuntu.com/ubuntu $(lsb_release -sc)-proposed main" | tee /etc/apt/sources.list.d/proposed.list
apt-get update -q
apt-get install -qy cloud-init'
2021-05-18 18:36:14 INFO      pycloudlib.instance:instance.py:165 executing: sudo -- sh -c 'cloud-init -v'
Installed cloud-init version: 21.2-3-g899bfaa9-0ubuntu2~20.10.1
2021-05-18 18:36:15 INFO      integration_testing:instances.py:136 Installed cloud-init version: 21.2-3-g899bfaa9-0ubuntu2~20.10.1
2021-05-18 18:36:15 INFO      pycloudlib.instance:instance.py:165 executing: sh -c 'sudo cloud-init clean --logs'
2021-05-18 18:36:16 INFO      pycloudlib.instance:instance.py:165 executing: sh -c 'sudo rm -rf /var/log/syslog'
2021-05-18 18:36:16 INFO      pycloudlib.instance:instance.py:165 executing: sudo -- sh -c 'hostname something-else'
Restarting instance and waiting for boot
2021-05-18 18:36:16 INFO      integration_testing:instances.py:65 Restarting instance and waiting for boot
2021-05-18 18:36:26 INFO      pycloudlib.instance:instance.py:165 executing: sh -c whoami
2021-05-18 18:36:29 INFO      pycloudlib.instance:instance.py:343 [Errno None] Unable to connect to port 22 on 10.245.166.100
Retrying SSH connection to ubuntu@10.245.166.100:22 (596s left)
2021-05-18 18:36:32 INFO      pycloudlib.instance:instance.py:343 [Errno None] Unable to connect to port 22 on 10.245.166.100
Retrying SSH connection to ubuntu@10.245.166.100:22 (594s left)
2021-05-18 18:36:33 INFO      pycloudlib.instance:instance.py:343 [Errno None] Unable to connect to port 22 on 10.245.166.100
Retrying SSH connection to ubuntu@10.245.166.100:22 (593s left)
2021-05-18 18:36:34 INFO      pycloudlib.instance:instance.py:343 [Errno None] Unable to connect to port 22 on 10.245.166.100
Retrying SSH connection to ubuntu@10.245.166.100:22 (592s left)
2021-05-18 18:36:35 INFO      pycloudlib.instance:instance.py:343 [Errno None] Unable to connect to port 22 on 10.245.166.100
Retrying SSH connection to ubuntu@10.245.166.100:22 (591s left)
2021-05-18 18:36:36 INFO      pycloudlib.instance:instance.py:343 [Errno None] Unable to connect to port 22 on 10.245.166.100
Retrying SSH connection to ubuntu@10.245.166.100:22 (590s left)
2021-05-18 18:36:37 INFO      pycloudlib.instance:instance.py:343 [Errno None] Unable to connect to port 22 on 10.245.166.100
Retrying SSH connection to ubuntu@10.245.166.100:22 (589s left)
2021-05-18 18:36:38 INFO      pycloudlib.instance:instance.py:343 [Errno None] Unable to connect to port 22 on 10.245.166.100
Retrying SSH connection to ubuntu@10.245.166.100:22 (587s left)
2021-05-18 18:36:39 INFO      pycloudlib.instance:instance.py:343 [Errno None] Unable to connect to port 22 on 10.245.166.100
Retrying SSH connection to ubuntu@10.245.166.100:22 (586s left)
2021-05-18 18:36:40 INFO      pycloudlib.instance:instance.py:343 [Errno None] Unable to connect to port 22 on 10.245.166.100
Retrying SSH connection to ubuntu@10.245.166.100:22 (585s left)
2021-05-18 18:36:41 INFO      pycloudlib.instance:instance.py:343 [Errno None] Unable to connect to port 22 on 10.245.166.100
Retrying SSH connection to ubuntu@10.245.166.100:22 (584s left)
2021-05-18 18:36:42 INFO      paramiko.transport:transport.py:1819 Connected (version 2.0, client OpenSSH_8.3p1)
2021-05-18 18:36:43 INFO      paramiko.transport:transport.py:1819 Authentication (publickey) successful!
2021-05-18 18:36:46 INFO      pycloudlib.instance:instance.py:165 executing: cloud-init status --wait --long
2021-05-18 18:36:50 INFO      pycloudlib.instance:instance.py:165 executing: sudo -- sh -c 'cloud-init status --wait --long'
2021-05-18 18:36:50 INFO      pycloudlib.instance:instance.py:165 executing: sudo -- sh -c 'cloud-init status --wait --long'
2021-05-18 18:36:51 INFO      pycloudlib.instance:instance.py:165 executing: sudo -- sh -c hostname
2021-05-18 18:36:51 INFO      pycloudlib.instance:instance.py:165 executing: sudo -- sh -c 'dpkg-query --show cloud-init'
2021-05-18 18:36:51 INFO      pycloudlib.instance:instance.py:165 executing: sudo -- sh -c 'cat /run/cloud-init/result.json'
2021-05-18 18:36:51 INFO      pycloudlib.instance:instance.py:165 executing: sudo -- sh -c 'cloud-init init'
2021-05-18 18:36:52 INFO      pycloudlib.instance:instance.py:165 executing: sudo -- sh -c 'grep Trace /var/log/cloud-init.log'
2021-05-18 18:36:52 INFO      pycloudlib.instance:instance.py:165 executing: sudo -- sh -c cloud-id
2021-05-18 18:36:53 INFO      pycloudlib.instance:instance.py:165 executing: sudo -- sh -c 'cat /etc/netplan/50-cloud-init.yaml'
2021-05-18 18:36:53 INFO      pycloudlib.instance:instance.py:165 executing: sudo -- sh -c systemd-analyze
2021-05-18 18:36:53 INFO      pycloudlib.instance:instance.py:165 executing: sudo -- sh -c 'systemd-analyze blame'
2021-05-18 18:36:54 INFO      pycloudlib.instance:instance.py:165 executing: sudo -- sh -c 'cloud-init analyze show'
2021-05-18 18:36:55 INFO      pycloudlib.instance:instance.py:165 executing: sudo -- sh -c 'cloud-init analyze blame'
Wrote upgrade test logs to /home/james/tmp_home/cloud_init_test_logs/test_upgrade_openstack_groovy_before_210518133024.log and /home/james/tmp_home/cloud_init_test_logs/test_upgrade_openstack_groovy_after_210518133024.log
2021-05-18 18:37:00 INFO      integration_testing:test_upgrade.py:102 Wrote upgrade test logs to /home/james/tmp_home/cloud_init_test_logs/test_upgrade_openstack_groovy_before_210518133024.log and /home/james/tmp_home/cloud_init_test_logs/test_upgrade_openstack_groovy_after_210518133024.log
PASSED


==== Hirsute ====
-------------------------------- live log setup --------------------------------
2021-05-18 19:21:49 INFO      integration_testing:clouds.py:88 Detected image: image_id=8b7e753a-7da2-4a29-833d-f763a3a09aa9 os=ubuntu release=hirsute
Detected image: image_id=8b7e753a-7da2-4a29-833d-f763a3a09aa9 os=ubuntu release=hirsute
-------------------------------- live log call ---------------------------------
2021-05-18 19:21:49 INFO      integration_testing:clouds.py:88 Detected image: image_id=8b7e753a-7da2-4a29-833d-f763a3a09aa9 os=ubuntu release=hirsute
Launching instance with launch_kwargs:
image_id=8b7e753a-7da2-4a29-833d-f763a3a09aa9
user_data=#cloud-config
hostname: SRU-worked

2021-05-18 19:21:49 INFO      integration_testing:clouds.py:168 Launching instance with launch_kwargs:
image_id=8b7e753a-7da2-4a29-833d-f763a3a09aa9
user_data=#cloud-config
hostname: SRU-worked

2021-05-18 19:22:02 INFO      pycloudlib.instance:instance.py:165 executing: sh -c whoami
2021-05-18 19:22:07 INFO      pycloudlib.instance:instance.py:343 [Errno None] Unable to connect to port 22 on 10.245.166.243
Retrying SSH connection to ubuntu@10.245.166.243:22 (595s left)
2021-05-18 19:22:10 INFO      pycloudlib.instance:instance.py:343 [Errno None] Unable to connect to port 22 on 10.245.166.243
Retrying SSH connection to ubuntu@10.245.166.243:22 (592s left)
2021-05-18 19:22:11 INFO      pycloudlib.instance:instance.py:343 [Errno None] Unable to connect to port 22 on 10.245.166.243
Retrying SSH connection to ubuntu@10.245.166.243:22 (591s left)
2021-05-18 19:22:12 INFO      pycloudlib.instance:instance.py:343 [Errno None] Unable to connect to port 22 on 10.245.166.243
Retrying SSH connection to ubuntu@10.245.166.243:22 (590s left)
2021-05-18 19:22:13 INFO      pycloudlib.instance:instance.py:343 [Errno None] Unable to connect to port 22 on 10.245.166.243
Retrying SSH connection to ubuntu@10.245.166.243:22 (589s left)
2021-05-18 19:22:14 INFO      pycloudlib.instance:instance.py:343 [Errno None] Unable to connect to port 22 on 10.245.166.243
Retrying SSH connection to ubuntu@10.245.166.243:22 (588s left)
2021-05-18 19:22:16 INFO      pycloudlib.instance:instance.py:343 [Errno None] Unable to connect to port 22 on 10.245.166.243
Retrying SSH connection to ubuntu@10.245.166.243:22 (586s left)
2021-05-18 19:22:17 INFO      pycloudlib.instance:instance.py:343 [Errno None] Unable to connect to port 22 on 10.245.166.243
Retrying SSH connection to ubuntu@10.245.166.243:22 (585s left)
2021-05-18 19:22:19 INFO      pycloudlib.instance:instance.py:343 [Errno None] Unable to connect to port 22 on 10.245.166.243
Retrying SSH connection to ubuntu@10.245.166.243:22 (583s left)
2021-05-18 19:22:20 INFO      paramiko.transport:transport.py:1819 Connected (version 2.0, client OpenSSH_8.4p1)
2021-05-18 19:22:20 INFO      paramiko.transport:transport.py:1819 Authentication (publickey) successful!
2021-05-18 19:23:07 INFO      pycloudlib.instance:instance.py:165 executing: cloud-init status --wait --long
Launched instance: OpenstackInstance(instance_id=89015cfb-166a-4eb2-a72e-433b70cc29f4)
2021-05-18 19:23:11 INFO      integration_testing:clouds.py:173 Launched instance: OpenstackInstance(instance_id=89015cfb-166a-4eb2-a72e-433b70cc29f4)
2021-05-18 19:23:11 INFO      pycloudlib.instance:instance.py:165 executing: sudo -- sh -c 'cloud-init --version'
cloud-init version: /usr/bin/cloud-init 21.1-19-gbad84ad4-0ubuntu2
2021-05-18 19:23:11 INFO      integration_testing:clouds.py:179 cloud-init version: /usr/bin/cloud-init 21.1-19-gbad84ad4-0ubuntu2
2021-05-18 19:23:11 INFO      pycloudlib.instance:instance.py:165 executing: sudo -- sh -c 'grep serial /etc/cloud/build.info'
image serial: 20210409
2021-05-18 19:23:11 INFO      integration_testing:clouds.py:183 image serial: 20210409
2021-05-18 19:23:11 INFO      pycloudlib.instance:instance.py:165 executing: sudo -- sh -c hostname
2021-05-18 19:23:12 INFO      pycloudlib.instance:instance.py:165 executing: sudo -- sh -c 'dpkg-query --show cloud-init'
2021-05-18 19:23:12 INFO      pycloudlib.instance:instance.py:165 executing: sudo -- sh -c 'cat /run/cloud-init/result.json'
2021-05-18 19:23:13 INFO      pycloudlib.instance:instance.py:165 executing: sudo -- sh -c 'cloud-init init'
2021-05-18 19:23:14 INFO      pycloudlib.instance:instance.py:165 executing: sudo -- sh -c 'grep Trace /var/log/cloud-init.log'
2021-05-18 19:23:14 INFO      pycloudlib.instance:instance.py:165 executing: sudo -- sh -c cloud-id
2021-05-18 19:23:14 INFO      pycloudlib.instance:instance.py:165 executing: sudo -- sh -c 'cat /etc/netplan/50-cloud-init.yaml'
2021-05-18 19:23:14 INFO      pycloudlib.instance:instance.py:165 executing: sudo -- sh -c systemd-analyze
2021-05-18 19:23:14 INFO      pycloudlib.instance:instance.py:165 executing: sudo -- sh -c 'systemd-analyze blame'
2021-05-18 19:23:15 INFO      pycloudlib.instance:instance.py:165 executing: sudo -- sh -c 'cloud-init analyze show'
2021-05-18 19:23:16 INFO      pycloudlib.instance:instance.py:165 executing: sudo -- sh -c 'cloud-init analyze blame'
Installing proposed image
2021-05-18 19:23:16 INFO      integration_testing:instances.py:144 Installing proposed image
2021-05-18 19:23:16 INFO      pycloudlib.instance:instance.py:165 executing: sudo -- sh -c 'echo deb "http://archive.ubuntu.com/ubuntu $(lsb_release -sc)-proposed main" | tee /etc/apt/sources.list.d/proposed.list
apt-get update -q
apt-get install -qy cloud-init'
2021-05-18 19:24:13 INFO      pycloudlib.instance:instance.py:165 executing: sudo -- sh -c 'cloud-init -v'
Installed cloud-init version: 21.2-3-g899bfaa9-0ubuntu2~21.04.1
2021-05-18 19:24:14 INFO      integration_testing:instances.py:136 Installed cloud-init version: 21.2-3-g899bfaa9-0ubuntu2~21.04.1
2021-05-18 19:24:14 INFO      pycloudlib.instance:instance.py:165 executing: sh -c 'sudo cloud-init clean --logs'
2021-05-18 19:24:14 INFO      pycloudlib.instance:instance.py:165 executing: sh -c 'sudo rm -rf /var/log/syslog'
2021-05-18 19:24:15 INFO      pycloudlib.instance:instance.py:165 executing: sudo -- sh -c 'hostname something-else'
Restarting instance and waiting for boot
2021-05-18 19:24:15 INFO      integration_testing:instances.py:65 Restarting instance and waiting for boot
2021-05-18 19:24:54 INFO      pycloudlib.instance:instance.py:165 executing: sh -c whoami
2021-05-18 19:25:09 INFO      pycloudlib.instance:instance.py:343 [Errno None] Unable to connect to port 22 on 10.245.166.243
Retrying SSH connection to ubuntu@10.245.166.243:22 (584s left)
2021-05-18 19:25:10 INFO      paramiko.transport:transport.py:1819 Connected (version 2.0, client OpenSSH_8.4p1)
2021-05-18 19:25:11 INFO      paramiko.transport:transport.py:1819 Authentication (publickey) successful!
2021-05-18 19:25:12 INFO      pycloudlib.instance:instance.py:165 executing: cloud-init status --wait --long
2021-05-18 19:25:13 INFO      pycloudlib.instance:instance.py:165 executing: sudo -- sh -c 'cloud-init status --wait --long'
2021-05-18 19:25:14 INFO      pycloudlib.instance:instance.py:165 executing: sudo -- sh -c 'cloud-init status --wait --long'
2021-05-18 19:25:15 INFO      pycloudlib.instance:instance.py:165 executing: sudo -- sh -c hostname
2021-05-18 19:25:15 INFO      pycloudlib.instance:instance.py:165 executing: sudo -- sh -c 'dpkg-query --show cloud-init'
2021-05-18 19:25:15 INFO      pycloudlib.instance:instance.py:165 executing: sudo -- sh -c 'cat /run/cloud-init/result.json'
2021-05-18 19:25:15 INFO      pycloudlib.instance:instance.py:165 executing: sudo -- sh -c 'cloud-init init'
2021-05-18 19:25:16 INFO      pycloudlib.instance:instance.py:165 executing: sudo -- sh -c 'grep Trace /var/log/cloud-init.log'
2021-05-18 19:25:16 INFO      pycloudlib.instance:instance.py:165 executing: sudo -- sh -c cloud-id
2021-05-18 19:25:16 INFO      pycloudlib.instance:instance.py:165 executing: sudo -- sh -c 'cat /etc/netplan/50-cloud-init.yaml'
2021-05-18 19:25:17 INFO      pycloudlib.instance:instance.py:165 executing: sudo -- sh -c systemd-analyze
2021-05-18 19:25:17 INFO      pycloudlib.instance:instance.py:165 executing: sudo -- sh -c 'systemd-analyze blame'
2021-05-18 19:25:18 INFO      pycloudlib.instance:instance.py:165 executing: sudo -- sh -c 'cloud-init analyze show'
2021-05-18 19:25:18 INFO      pycloudlib.instance:instance.py:165 executing: sudo -- sh -c 'cloud-init analyze blame'
Wrote upgrade test logs to /home/james/tmp_home/cloud_init_test_logs/test_upgrade_openstack_hirsute_before_210518141738.log and /home/james/tmp_home/cloud_init_test_logs/test_upgrade_openstack_hirsute_after_210518141738.log
2021-05-18 19:25:24 INFO      integration_testing:test_upgrade.py:102 Wrote upgrade test logs to /home/james/tmp_home/cloud_init_test_logs/test_upgrade_openstack_hirsute_before_210518141738.log and /home/james/tmp_home/cloud_init_test_logs/test_upgrade_openstack_hirsute_after_210518141738.log
PASSED
