Upstream test at:
https://github.com/canonical/cloud-init/blob/master/tests/integration_tests/test_upgrade.py

Logs from individual before/after runs in oracle-sru-21.2-3 subdirectory

==== Bionic ====
-------------------------------- live log setup --------------------------------
2021-05-18 02:52:56 INFO      integration_testing:clouds.py:88 Detected image: image_id=bionic os=ubuntu release=bionic
Detected image: image_id=bionic os=ubuntu release=bionic
-------------------------------- live log call ---------------------------------
2021-05-18 02:52:56 INFO      integration_testing:clouds.py:88 Detected image: image_id=bionic os=ubuntu release=bionic
Launching instance with launch_kwargs:
image_id=ocid1.image.oc1.phx.aaaaaaaay55y367c7ycfctr4xzzt7pri7s5zebkx6eowp3rs44pz4njqot2a
user_data=#cloud-config
hostname: SRU-worked

2021-05-18 02:52:56 INFO      integration_testing:clouds.py:168 Launching instance with launch_kwargs:
image_id=ocid1.image.oc1.phx.aaaaaaaay55y367c7ycfctr4xzzt7pri7s5zebkx6eowp3rs44pz4njqot2a
user_data=#cloud-config
hostname: SRU-worked

2021-05-18 02:53:47 INFO      pycloudlib.instance:instance.py:165 executing: sh -c whoami
2021-05-18 02:54:03 INFO      pycloudlib.instance:instance.py:343 [Errno None] Unable to connect to port 22 on 129.146.176.243
Retrying SSH connection to ubuntu@129.146.176.243:22 (583s left)
2021-05-18 02:54:04 INFO      pycloudlib.instance:instance.py:343 [Errno None] Unable to connect to port 22 on 129.146.176.243
Retrying SSH connection to ubuntu@129.146.176.243:22 (582s left)
2021-05-18 02:54:05 INFO      pycloudlib.instance:instance.py:343 [Errno None] Unable to connect to port 22 on 129.146.176.243
Retrying SSH connection to ubuntu@129.146.176.243:22 (581s left)
2021-05-18 02:54:07 INFO      pycloudlib.instance:instance.py:343 [Errno None] Unable to connect to port 22 on 129.146.176.243
Retrying SSH connection to ubuntu@129.146.176.243:22 (580s left)
2021-05-18 02:54:08 INFO      pycloudlib.instance:instance.py:343 [Errno None] Unable to connect to port 22 on 129.146.176.243
Retrying SSH connection to ubuntu@129.146.176.243:22 (579s left)
2021-05-18 02:54:09 INFO      paramiko.transport:transport.py:1819 Connected (version 2.0, client OpenSSH_7.6p1)
2021-05-18 02:54:09 INFO      paramiko.transport:transport.py:1819 Authentication (publickey) successful!
2021-05-18 02:54:12 INFO      pycloudlib.instance:instance.py:165 executing: cloud-init status --wait --long
Launched instance: OciInstance(instance_id=ocid1.instance.oc1.phx.anyhqljrniwq6sycm4n4fcergm4v75xrnkk7qvlagwzvnatluempnhfygveq, compartment_id=ocid1.compartment.oc1..aaaaaaaanz4b63fdemmuag77dg2pi22xfyhrpq46hcgdd3dozkvqfzwwjwxa)
2021-05-18 02:54:26 INFO      integration_testing:clouds.py:173 Launched instance: OciInstance(instance_id=ocid1.instance.oc1.phx.anyhqljrniwq6sycm4n4fcergm4v75xrnkk7qvlagwzvnatluempnhfygveq, compartment_id=ocid1.compartment.oc1..aaaaaaaanz4b63fdemmuag77dg2pi22xfyhrpq46hcgdd3dozkvqfzwwjwxa)
2021-05-18 02:54:26 INFO      pycloudlib.instance:instance.py:165 executing: sudo -- sh -c 'cloud-init --version'
cloud-init version: /usr/bin/cloud-init 21.1-19-gbad84ad4-0ubuntu1~18.04.1
2021-05-18 02:54:27 INFO      integration_testing:clouds.py:179 cloud-init version: /usr/bin/cloud-init 21.1-19-gbad84ad4-0ubuntu1~18.04.1
2021-05-18 02:54:27 INFO      pycloudlib.instance:instance.py:165 executing: sudo -- sh -c 'grep serial /etc/cloud/build.info'
image serial: 20210415
2021-05-18 02:54:27 INFO      integration_testing:clouds.py:183 image serial: 20210415
2021-05-18 02:54:27 INFO      pycloudlib.instance:instance.py:165 executing: sudo -- sh -c hostname
2021-05-18 02:54:27 INFO      pycloudlib.instance:instance.py:165 executing: sudo -- sh -c 'dpkg-query --show cloud-init'
2021-05-18 02:54:27 INFO      pycloudlib.instance:instance.py:165 executing: sudo -- sh -c 'cat /run/cloud-init/result.json'
2021-05-18 02:54:28 INFO      pycloudlib.instance:instance.py:165 executing: sudo -- sh -c 'cloud-init init'
2021-05-18 02:54:28 INFO      pycloudlib.instance:instance.py:165 executing: sudo -- sh -c 'grep Trace /var/log/cloud-init.log'
2021-05-18 02:54:29 INFO      pycloudlib.instance:instance.py:165 executing: sudo -- sh -c cloud-id
2021-05-18 02:54:29 INFO      pycloudlib.instance:instance.py:165 executing: sudo -- sh -c 'cat /etc/netplan/50-cloud-init.yaml'
2021-05-18 02:54:30 INFO      pycloudlib.instance:instance.py:165 executing: sudo -- sh -c systemd-analyze
2021-05-18 02:54:30 INFO      pycloudlib.instance:instance.py:165 executing: sudo -- sh -c 'systemd-analyze blame'
2021-05-18 02:54:30 INFO      pycloudlib.instance:instance.py:165 executing: sudo -- sh -c 'cloud-init analyze show'
2021-05-18 02:54:31 INFO      pycloudlib.instance:instance.py:165 executing: sudo -- sh -c 'cloud-init analyze blame'
Installing proposed image
2021-05-18 02:54:32 INFO      integration_testing:instances.py:144 Installing proposed image
2021-05-18 02:54:32 INFO      pycloudlib.instance:instance.py:165 executing: sudo -- sh -c 'echo deb "http://archive.ubuntu.com/ubuntu $(lsb_release -sc)-proposed main" | tee /etc/apt/sources.list.d/proposed.list
apt-get update -q
apt-get install -qy cloud-init'
2021-05-18 02:54:49 INFO      pycloudlib.instance:instance.py:165 executing: sudo -- sh -c 'cloud-init -v'
Installed cloud-init version: 21.2-3-g899bfaa9-0ubuntu2~18.04.1
2021-05-18 02:54:49 INFO      integration_testing:instances.py:136 Installed cloud-init version: 21.2-3-g899bfaa9-0ubuntu2~18.04.1
2021-05-18 02:54:49 INFO      pycloudlib.instance:instance.py:165 executing: sh -c 'sudo cloud-init clean --logs'
2021-05-18 02:54:50 INFO      pycloudlib.instance:instance.py:165 executing: sh -c 'sudo rm -rf /var/log/syslog'
2021-05-18 02:54:50 INFO      pycloudlib.instance:instance.py:165 executing: sudo -- sh -c 'hostname something-else'
Restarting instance and waiting for boot
2021-05-18 02:54:51 INFO      integration_testing:instances.py:65 Restarting instance and waiting for boot
2021-05-18 02:54:59 INFO      pycloudlib.instance:instance.py:165 executing: sh -c whoami
2021-05-18 02:55:18 ERROR     paramiko.transport:transport.py:1819 Socket exception: Connection reset by peer (104)
2021-05-18 02:55:18 INFO      pycloudlib.instance:instance.py:343 [Errno None] Unable to connect to port 22 on 129.146.176.243
Retrying SSH connection to ubuntu@129.146.176.243:22 (599s left)
2021-05-18 02:55:19 INFO      pycloudlib.instance:instance.py:343 [Errno None] Unable to connect to port 22 on 129.146.176.243
Retrying SSH connection to ubuntu@129.146.176.243:22 (598s left)
2021-05-18 02:55:20 INFO      pycloudlib.instance:instance.py:343 [Errno None] Unable to connect to port 22 on 129.146.176.243
Retrying SSH connection to ubuntu@129.146.176.243:22 (597s left)
2021-05-18 02:55:21 INFO      pycloudlib.instance:instance.py:343 [Errno None] Unable to connect to port 22 on 129.146.176.243
Retrying SSH connection to ubuntu@129.146.176.243:22 (596s left)
2021-05-18 02:55:23 INFO      paramiko.transport:transport.py:1819 Connected (version 2.0, client OpenSSH_7.6p1)
2021-05-18 02:55:23 INFO      paramiko.transport:transport.py:1819 Authentication (publickey) successful!
2021-05-18 02:55:26 INFO      pycloudlib.instance:instance.py:165 executing: cloud-init status --wait --long
2021-05-18 02:55:29 INFO      pycloudlib.instance:instance.py:165 executing: sudo -- sh -c 'cloud-init status --wait --long'
2021-05-18 02:55:30 INFO      pycloudlib.instance:instance.py:165 executing: sudo -- sh -c 'cloud-init status --wait --long'
2021-05-18 02:55:30 INFO      pycloudlib.instance:instance.py:165 executing: sudo -- sh -c hostname
2021-05-18 02:55:31 INFO      pycloudlib.instance:instance.py:165 executing: sudo -- sh -c 'dpkg-query --show cloud-init'
2021-05-18 02:55:31 INFO      pycloudlib.instance:instance.py:165 executing: sudo -- sh -c 'cat /run/cloud-init/result.json'
2021-05-18 02:55:31 INFO      pycloudlib.instance:instance.py:165 executing: sudo -- sh -c 'cloud-init init'
2021-05-18 02:55:32 INFO      pycloudlib.instance:instance.py:165 executing: sudo -- sh -c 'grep Trace /var/log/cloud-init.log'
2021-05-18 02:55:32 INFO      pycloudlib.instance:instance.py:165 executing: sudo -- sh -c cloud-id
2021-05-18 02:55:33 INFO      pycloudlib.instance:instance.py:165 executing: sudo -- sh -c 'cat /etc/netplan/50-cloud-init.yaml'
2021-05-18 02:55:33 INFO      pycloudlib.instance:instance.py:165 executing: sudo -- sh -c systemd-analyze
2021-05-18 02:55:33 INFO      pycloudlib.instance:instance.py:165 executing: sudo -- sh -c 'systemd-analyze blame'
2021-05-18 02:55:34 INFO      pycloudlib.instance:instance.py:165 executing: sudo -- sh -c 'cloud-init analyze show'
2021-05-18 02:55:34 INFO      pycloudlib.instance:instance.py:165 executing: sudo -- sh -c 'cloud-init analyze blame'
Wrote upgrade test logs to /home/james/tmp_home/cloud_init_test_logs/test_upgrade_oci_bionic_before_210517214415.log and /home/james/tmp_home/cloud_init_test_logs/test_upgrade_oci_bionic_after_210517214415.log
2021-05-18 02:57:11 INFO      integration_testing:test_upgrade.py:102 Wrote upgrade test logs to /home/james/tmp_home/cloud_init_test_logs/test_upgrade_oci_bionic_before_210517214415.log and /home/james/tmp_home/cloud_init_test_logs/test_upgrade_oci_bionic_after_210517214415.log
PASSED


==== Focal ====
-------------------------------- live log setup --------------------------------
2021-05-18 22:07:54 INFO      integration_testing:clouds.py:88 Detected image: image_id=focal os=ubuntu release=focal
Detected image: image_id=focal os=ubuntu release=focal
-------------------------------- live log call ---------------------------------
2021-05-18 22:07:54 INFO      integration_testing:clouds.py:88 Detected image: image_id=focal os=ubuntu release=focal
Launching instance with launch_kwargs:
image_id=ocid1.image.oc1.phx.aaaaaaaa7bgsdz7waro6nlsbv4xksxs5lw43ibiotpcl3jrhryehtzf7m3rq
user_data=#cloud-config
hostname: SRU-worked

2021-05-18 22:07:54 INFO      integration_testing:clouds.py:168 Launching instance with launch_kwargs:
image_id=ocid1.image.oc1.phx.aaaaaaaa7bgsdz7waro6nlsbv4xksxs5lw43ibiotpcl3jrhryehtzf7m3rq
user_data=#cloud-config
hostname: SRU-worked

2021-05-18 22:08:38 INFO      pycloudlib.instance:instance.py:165 executing: sh -c whoami
2021-05-18 22:08:55 INFO      paramiko.transport:transport.py:1819 Connected (version 2.0, client OpenSSH_8.2p1)
2021-05-18 22:08:56 INFO      paramiko.transport:transport.py:1819 Authentication (publickey) successful!
2021-05-18 22:09:43 INFO      pycloudlib.instance:instance.py:165 executing: cloud-init status --wait --long
Launched instance: OciInstance(instance_id=ocid1.instance.oc1.phx.anyhqljrniwq6syclmgrx3q5nvuat2yw2qphm2ziytigj5lg4tm74emszxia, compartment_id=ocid1.compartment.oc1..aaaaaaaanz4b63fdemmuag77dg2pi22xfyhrpq46hcgdd3dozkvqfzwwjwxa)
2021-05-18 22:09:50 INFO      integration_testing:clouds.py:173 Launched instance: OciInstance(instance_id=ocid1.instance.oc1.phx.anyhqljrniwq6syclmgrx3q5nvuat2yw2qphm2ziytigj5lg4tm74emszxia, compartment_id=ocid1.compartment.oc1..aaaaaaaanz4b63fdemmuag77dg2pi22xfyhrpq46hcgdd3dozkvqfzwwjwxa)
2021-05-18 22:09:50 INFO      pycloudlib.instance:instance.py:165 executing: sudo -- sh -c 'cloud-init --version'
cloud-init version: /usr/bin/cloud-init 21.1-19-gbad84ad4-0ubuntu1~20.04.1
2021-05-18 22:09:50 INFO      integration_testing:clouds.py:179 cloud-init version: /usr/bin/cloud-init 21.1-19-gbad84ad4-0ubuntu1~20.04.1
2021-05-18 22:09:50 INFO      pycloudlib.instance:instance.py:165 executing: sudo -- sh -c 'grep serial /etc/cloud/build.info'
image serial: 20210415
2021-05-18 22:09:51 INFO      integration_testing:clouds.py:183 image serial: 20210415
2021-05-18 22:09:51 INFO      pycloudlib.instance:instance.py:165 executing: sudo -- sh -c hostname
2021-05-18 22:09:51 INFO      pycloudlib.instance:instance.py:165 executing: sudo -- sh -c 'dpkg-query --show cloud-init'
2021-05-18 22:09:51 INFO      pycloudlib.instance:instance.py:165 executing: sudo -- sh -c 'cat /run/cloud-init/result.json'
2021-05-18 22:09:51 INFO      pycloudlib.instance:instance.py:165 executing: sudo -- sh -c 'cloud-init init'
2021-05-18 22:09:52 INFO      pycloudlib.instance:instance.py:165 executing: sudo -- sh -c 'grep Trace /var/log/cloud-init.log'
2021-05-18 22:09:52 INFO      pycloudlib.instance:instance.py:165 executing: sudo -- sh -c cloud-id
2021-05-18 22:09:53 INFO      pycloudlib.instance:instance.py:165 executing: sudo -- sh -c 'cat /etc/netplan/50-cloud-init.yaml'
2021-05-18 22:09:53 INFO      pycloudlib.instance:instance.py:165 executing: sudo -- sh -c systemd-analyze
2021-05-18 22:09:54 INFO      pycloudlib.instance:instance.py:165 executing: sudo -- sh -c 'systemd-analyze blame'
2021-05-18 22:09:55 INFO      pycloudlib.instance:instance.py:165 executing: sudo -- sh -c 'cloud-init analyze show'
2021-05-18 22:09:55 INFO      pycloudlib.instance:instance.py:165 executing: sudo -- sh -c 'cloud-init analyze blame'
Installing proposed image
2021-05-18 22:09:56 INFO      integration_testing:instances.py:144 Installing proposed image
2021-05-18 22:09:56 INFO      pycloudlib.instance:instance.py:165 executing: sudo -- sh -c 'echo deb "http://archive.ubuntu.com/ubuntu $(lsb_release -sc)-proposed main" | tee /etc/apt/sources.list.d/proposed.list
apt-get update -q
apt-get install -qy cloud-init'
2021-05-18 22:10:16 INFO      pycloudlib.instance:instance.py:165 executing: sudo -- sh -c 'cloud-init -v'
Installed cloud-init version: 21.2-3-g899bfaa9-0ubuntu2~20.04.1
2021-05-18 22:10:17 INFO      integration_testing:instances.py:136 Installed cloud-init version: 21.2-3-g899bfaa9-0ubuntu2~20.04.1
2021-05-18 22:10:17 INFO      pycloudlib.instance:instance.py:165 executing: sh -c 'sudo cloud-init clean --logs'
2021-05-18 22:10:17 INFO      pycloudlib.instance:instance.py:165 executing: sh -c 'sudo rm -rf /var/log/syslog'
2021-05-18 22:10:18 INFO      pycloudlib.instance:instance.py:165 executing: sudo -- sh -c 'hostname something-else'
Restarting instance and waiting for boot
2021-05-18 22:10:18 INFO      integration_testing:instances.py:65 Restarting instance and waiting for boot
2021-05-18 22:10:29 INFO      pycloudlib.instance:instance.py:165 executing: sh -c whoami
2021-05-18 22:10:48 ERROR     paramiko.transport:transport.py:1819 Socket exception: Connection reset by peer (104)
2021-05-18 22:10:48 INFO      paramiko.transport:transport.py:1819 Connected (version 2.0, client OpenSSH_8.2p1)
2021-05-18 22:10:48 INFO      paramiko.transport:transport.py:1819 Authentication (publickey) successful!
2021-05-18 22:10:50 INFO      pycloudlib.instance:instance.py:165 executing: cloud-init status --wait --long
2021-05-18 22:10:53 INFO      pycloudlib.instance:instance.py:165 executing: sudo -- sh -c 'cloud-init status --wait --long'
2021-05-18 22:10:54 INFO      pycloudlib.instance:instance.py:165 executing: sudo -- sh -c 'cloud-init status --wait --long'
2021-05-18 22:10:54 INFO      pycloudlib.instance:instance.py:165 executing: sudo -- sh -c hostname
2021-05-18 22:10:55 INFO      pycloudlib.instance:instance.py:165 executing: sudo -- sh -c 'dpkg-query --show cloud-init'
2021-05-18 22:10:55 INFO      pycloudlib.instance:instance.py:165 executing: sudo -- sh -c 'cat /run/cloud-init/result.json'
2021-05-18 22:10:55 INFO      pycloudlib.instance:instance.py:165 executing: sudo -- sh -c 'cloud-init init'
2021-05-18 22:10:56 INFO      pycloudlib.instance:instance.py:165 executing: sudo -- sh -c 'grep Trace /var/log/cloud-init.log'
2021-05-18 22:10:56 INFO      pycloudlib.instance:instance.py:165 executing: sudo -- sh -c cloud-id
2021-05-18 22:10:57 INFO      pycloudlib.instance:instance.py:165 executing: sudo -- sh -c 'cat /etc/netplan/50-cloud-init.yaml'
2021-05-18 22:10:57 INFO      pycloudlib.instance:instance.py:165 executing: sudo -- sh -c systemd-analyze
2021-05-18 22:10:57 INFO      pycloudlib.instance:instance.py:165 executing: sudo -- sh -c 'systemd-analyze blame'
2021-05-18 22:10:58 INFO      pycloudlib.instance:instance.py:165 executing: sudo -- sh -c 'cloud-init analyze show'
2021-05-18 22:10:59 INFO      pycloudlib.instance:instance.py:165 executing: sudo -- sh -c 'cloud-init analyze blame'
Wrote upgrade test logs to /home/james/tmp_home/cloud_init_test_logs/test_upgrade_oci_focal_before_210518170005.log and /home/james/tmp_home/cloud_init_test_logs/test_upgrade_oci_focal_after_210518170005.log
2021-05-18 22:13:02 INFO      integration_testing:test_upgrade.py:102 Wrote upgrade test logs to /home/james/tmp_home/cloud_init_test_logs/test_upgrade_oci_focal_before_210518170005.log and /home/james/tmp_home/cloud_init_test_logs/test_upgrade_oci_focal_after_210518170005.log
PASSED


==== Groovy ====
n/a, Oracle only provides LTS images

==== Hirsute ====
n/a, Oracle only provides LTS images
